09시 34분 / [오류] Traceback (most recent call last):
  File "C:\Users\82105\AppData\Local\Programs\Python\Python39\lib\site-packages\discord\ext\commands\core.py", line 85, in wrapped
    ret = await coro(*args, **kwargs)
  File "c:\Users\82105\Desktop\Project\Discord\DiscordBot_Gwen\cogs\SearchCommand.py", line 101, in 챔피언
    Background.paste(getImg(chamPro, 1000,1000).filter(ImageFilter.BLUR(5)), (50, -100))
TypeError: BLUR() takes no arguments

The above exception was the direct cause of the following exception:

Traceback (most recent call last):
  File "c:\Users\82105\Desktop\Project\Discord\DiscordBot_Gwen\utils\logger.py", line 22, in err
    raise error
  File "C:\Users\82105\AppData\Local\Programs\Python\Python39\lib\site-packages\discord\ext\commands\bot.py", line 939, in invoke
    await ctx.command.invoke(ctx)
  File "C:\Users\82105\AppData\Local\Programs\Python\Python39\lib\site-packages\discord\ext\commands\core.py", line 863, in invoke
    await injected(*ctx.args, **ctx.kwargs)
  File "C:\Users\82105\AppData\Local\Programs\Python\Python39\lib\site-packages\discord\ext\commands\core.py", line 94, in wrapped
    raise CommandInvokeError(exc) from exc
discord.ext.commands.errors.CommandInvokeError: Command raised an exception: TypeError: BLUR() takes no arguments



09시 36분 / [오류] Traceback (most recent call last):
  File "C:\Users\82105\AppData\Local\Programs\Python\Python39\lib\site-packages\discord\ext\commands\core.py", line 85, in wrapped
    ret = await coro(*args, **kwargs)
  File "c:\Users\82105\Desktop\Project\Discord\DiscordBot_Gwen\cogs\SearchCommand.py", line 101, in 챔피언
    Background.paste(getImg(chamPro, 1000,1000).filter(ImageFilter.GaussianBlur(10)), (-50, -200))
  File "C:\Users\82105\AppData\Local\Programs\Python\Python39\lib\site-packages\PIL\Image.py", line 1243, in filter
    return self._new(filter.filter(self.im))
  File "C:\Users\82105\AppData\Local\Programs\Python\Python39\lib\site-packages\PIL\ImageFilter.py", line 165, in filter
    return image.gaussian_blur(self.radius)
ValueError: image has wrong mode

The above exception was the direct cause of the following exception:

Traceback (most recent call last):
  File "c:\Users\82105\Desktop\Project\Discord\DiscordBot_Gwen\utils\logger.py", line 22, in err
    raise error
  File "C:\Users\82105\AppData\Local\Programs\Python\Python39\lib\site-packages\discord\ext\commands\bot.py", line 939, in invoke
    await ctx.command.invoke(ctx)
  File "C:\Users\82105\AppData\Local\Programs\Python\Python39\lib\site-packages\discord\ext\commands\core.py", line 863, in invoke
    await injected(*ctx.args, **ctx.kwargs)
  File "C:\Users\82105\AppData\Local\Programs\Python\Python39\lib\site-packages\discord\ext\commands\core.py", line 94, in wrapped
    raise CommandInvokeError(exc) from exc
discord.ext.commands.errors.CommandInvokeError: Command raised an exception: ValueError: image has wrong mode



09시 36분 / [오류] Traceback (most recent call last):
  File "C:\Users\82105\AppData\Local\Programs\Python\Python39\lib\site-packages\discord\ext\commands\core.py", line 85, in wrapped
    ret = await coro(*args, **kwargs)
  File "c:\Users\82105\Desktop\Project\Discord\DiscordBot_Gwen\cogs\SearchCommand.py", line 101, in 챔피언
    Background.paste(getImg(chamPro, 1000,1000).filter(ImageFilter.GaussianBlur(10)), (-50, -200))
  File "C:\Users\82105\AppData\Local\Programs\Python\Python39\lib\site-packages\PIL\Image.py", line 1243, in filter
    return self._new(filter.filter(self.im))
  File "C:\Users\82105\AppData\Local\Programs\Python\Python39\lib\site-packages\PIL\ImageFilter.py", line 165, in filter
    return image.gaussian_blur(self.radius)
ValueError: image has wrong mode

The above exception was the direct cause of the following exception:

Traceback (most recent call last):
  File "c:\Users\82105\Desktop\Project\Discord\DiscordBot_Gwen\utils\logger.py", line 22, in err
    raise error
  File "C:\Users\82105\AppData\Local\Programs\Python\Python39\lib\site-packages\discord\ext\commands\bot.py", line 939, in invoke
    await ctx.command.invoke(ctx)
  File "C:\Users\82105\AppData\Local\Programs\Python\Python39\lib\site-packages\discord\ext\commands\core.py", line 863, in invoke
    await injected(*ctx.args, **ctx.kwargs)
  File "C:\Users\82105\AppData\Local\Programs\Python\Python39\lib\site-packages\discord\ext\commands\core.py", line 94, in wrapped
    raise CommandInvokeError(exc) from exc
discord.ext.commands.errors.CommandInvokeError: Command raised an exception: ValueError: image has wrong mode



09시 36분 / [오류] Traceback (most recent call last):
  File "C:\Users\82105\AppData\Local\Programs\Python\Python39\lib\site-packages\discord\ext\commands\core.py", line 85, in wrapped
    ret = await coro(*args, **kwargs)
  File "c:\Users\82105\Desktop\Project\Discord\DiscordBot_Gwen\cogs\SearchCommand.py", line 101, in 챔피언
    Background.paste(getImg(chamPro, 1000,1000).filter(ImageFilter.GaussianBlur(10)), (-50, -200))
  File "C:\Users\82105\AppData\Local\Programs\Python\Python39\lib\site-packages\PIL\Image.py", line 1243, in filter
    return self._new(filter.filter(self.im))
  File "C:\Users\82105\AppData\Local\Programs\Python\Python39\lib\site-packages\PIL\ImageFilter.py", line 165, in filter
    return image.gaussian_blur(self.radius)
ValueError: image has wrong mode

The above exception was the direct cause of the following exception:

Traceback (most recent call last):
  File "c:\Users\82105\Desktop\Project\Discord\DiscordBot_Gwen\utils\logger.py", line 22, in err
    raise error
  File "C:\Users\82105\AppData\Local\Programs\Python\Python39\lib\site-packages\discord\ext\commands\bot.py", line 939, in invoke
    await ctx.command.invoke(ctx)
  File "C:\Users\82105\AppData\Local\Programs\Python\Python39\lib\site-packages\discord\ext\commands\core.py", line 863, in invoke
    await injected(*ctx.args, **ctx.kwargs)
  File "C:\Users\82105\AppData\Local\Programs\Python\Python39\lib\site-packages\discord\ext\commands\core.py", line 94, in wrapped
    raise CommandInvokeError(exc) from exc
discord.ext.commands.errors.CommandInvokeError: Command raised an exception: ValueError: image has wrong mode



09시 36분 / [오류] Traceback (most recent call last):
  File "C:\Users\82105\AppData\Local\Programs\Python\Python39\lib\site-packages\discord\ext\commands\core.py", line 85, in wrapped
    ret = await coro(*args, **kwargs)
  File "c:\Users\82105\Desktop\Project\Discord\DiscordBot_Gwen\cogs\SearchCommand.py", line 101, in 챔피언
    Background.paste(getImg(chamPro, 1000,1000).filter(ImageFilter.GaussianBlur(10)), (-50, -200))
  File "C:\Users\82105\AppData\Local\Programs\Python\Python39\lib\site-packages\PIL\Image.py", line 1243, in filter
    return self._new(filter.filter(self.im))
  File "C:\Users\82105\AppData\Local\Programs\Python\Python39\lib\site-packages\PIL\ImageFilter.py", line 165, in filter
    return image.gaussian_blur(self.radius)
ValueError: image has wrong mode

The above exception was the direct cause of the following exception:

Traceback (most recent call last):
  File "c:\Users\82105\Desktop\Project\Discord\DiscordBot_Gwen\utils\logger.py", line 22, in err
    raise error
  File "C:\Users\82105\AppData\Local\Programs\Python\Python39\lib\site-packages\discord\ext\commands\bot.py", line 939, in invoke
    await ctx.command.invoke(ctx)
  File "C:\Users\82105\AppData\Local\Programs\Python\Python39\lib\site-packages\discord\ext\commands\core.py", line 863, in invoke
    await injected(*ctx.args, **ctx.kwargs)
  File "C:\Users\82105\AppData\Local\Programs\Python\Python39\lib\site-packages\discord\ext\commands\core.py", line 94, in wrapped
    raise CommandInvokeError(exc) from exc
discord.ext.commands.errors.CommandInvokeError: Command raised an exception: ValueError: image has wrong mode



09시 51분 / [오류] Traceback (most recent call last):
  File "C:\Users\82105\AppData\Local\Programs\Python\Python39\lib\site-packages\discord\ext\commands\core.py", line 85, in wrapped
    ret = await coro(*args, **kwargs)
  File "c:\Users\82105\Desktop\Project\Discord\DiscordBot_Gwen\cogs\SearchCommand.py", line 101, in 챔피언
    Background.paste(getImg(chamPro, 1000,1000).convert('L').filter(ImageFilter.DETAIL(10)), (-50, -200))
TypeError: DETAIL() takes no arguments

The above exception was the direct cause of the following exception:

Traceback (most recent call last):
  File "c:\Users\82105\Desktop\Project\Discord\DiscordBot_Gwen\utils\logger.py", line 22, in err
    raise error
  File "C:\Users\82105\AppData\Local\Programs\Python\Python39\lib\site-packages\discord\ext\commands\bot.py", line 939, in invoke
    await ctx.command.invoke(ctx)
  File "C:\Users\82105\AppData\Local\Programs\Python\Python39\lib\site-packages\discord\ext\commands\core.py", line 863, in invoke
    await injected(*ctx.args, **ctx.kwargs)
  File "C:\Users\82105\AppData\Local\Programs\Python\Python39\lib\site-packages\discord\ext\commands\core.py", line 94, in wrapped
    raise CommandInvokeError(exc) from exc
discord.ext.commands.errors.CommandInvokeError: Command raised an exception: TypeError: DETAIL() takes no arguments



09시 52분 / [오류] Traceback (most recent call last):
  File "C:\Users\82105\AppData\Local\Programs\Python\Python39\lib\site-packages\discord\ext\commands\core.py", line 85, in wrapped
    ret = await coro(*args, **kwargs)
  File "c:\Users\82105\Desktop\Project\Discord\DiscordBot_Gwen\cogs\SearchCommand.py", line 101, in 챔피언
    Background.paste(getImg(chamPro, 1000,1000).filter(ImageFilter.DETAIL), (-50, -200))
  File "C:\Users\82105\AppData\Local\Programs\Python\Python39\lib\site-packages\PIL\Image.py", line 1243, in filter
    return self._new(filter.filter(self.im))
  File "C:\Users\82105\AppData\Local\Programs\Python\Python39\lib\site-packages\PIL\ImageFilter.py", line 31, in filter
    raise ValueError("cannot filter palette images")
ValueError: cannot filter palette images

The above exception was the direct cause of the following exception:

Traceback (most recent call last):
  File "c:\Users\82105\Desktop\Project\Discord\DiscordBot_Gwen\utils\logger.py", line 22, in err
    raise error
  File "C:\Users\82105\AppData\Local\Programs\Python\Python39\lib\site-packages\discord\ext\commands\bot.py", line 939, in invoke
    await ctx.command.invoke(ctx)
  File "C:\Users\82105\AppData\Local\Programs\Python\Python39\lib\site-packages\discord\ext\commands\core.py", line 863, in invoke
    await injected(*ctx.args, **ctx.kwargs)
  File "C:\Users\82105\AppData\Local\Programs\Python\Python39\lib\site-packages\discord\ext\commands\core.py", line 94, in wrapped
    raise CommandInvokeError(exc) from exc
discord.ext.commands.errors.CommandInvokeError: Command raised an exception: ValueError: cannot filter palette images



10시 44분 / [오류] Traceback (most recent call last):
  File "C:\Users\82105\AppData\Local\Programs\Python\Python39\lib\site-packages\discord\ext\commands\bot.py", line 606, in _load_from_module_spec
    spec.loader.exec_module(lib)
  File "<frozen importlib._bootstrap_external>", line 846, in exec_module
  File "<frozen importlib._bootstrap_external>", line 983, in get_code
  File "<frozen importlib._bootstrap_external>", line 913, in source_to_code
  File "<frozen importlib._bootstrap>", line 228, in _call_with_frames_removed
  File "c:\Users\82105\Desktop\Project\Discord\DiscordBot_Gwen\cogs\SearchCommand.py", line 116
    draw.text("원하는 글자위치 x좌표","원하는 글자위치 y좌표"),keyword,fill="white",font=selectedFont,align='center') # fill= 속성은 무슨 색으로 채울지 설정,font=는 자신이 설정한 폰트 설정
    ^
SyntaxError: cannot assign to function call

The above exception was the direct cause of the following exception:

Traceback (most recent call last):
  File "C:\Users\82105\AppData\Local\Programs\Python\Python39\lib\site-packages\discord\ext\commands\core.py", line 85, in wrapped
    ret = await coro(*args, **kwargs)
  File "c:\Users\82105\Desktop\Project\Discord\DiscordBot_Gwen\cogs\AdminCommand.py", line 26, in restart
    self.bot.reload_extension(f"cogs.{i}")
  File "C:\Users\82105\AppData\Local\Programs\Python\Python39\lib\site-packages\discord\ext\commands\bot.py", line 772, in reload_extension
    self.load_extension(name)
  File "C:\Users\82105\AppData\Local\Programs\Python\Python39\lib\site-packages\discord\ext\commands\bot.py", line 678, in load_extension
    self._load_from_module_spec(spec, name)
  File "C:\Users\82105\AppData\Local\Programs\Python\Python39\lib\site-packages\discord\ext\commands\bot.py", line 609, in _load_from_module_spec
    raise errors.ExtensionFailed(key, e) from e
discord.ext.commands.errors.ExtensionFailed: Extension 'cogs.SearchCommand' raised an error: SyntaxError: cannot assign to function call (SearchCommand.py, line 116)

The above exception was the direct cause of the following exception:

Traceback (most recent call last):
  File "c:\Users\82105\Desktop\Project\Discord\DiscordBot_Gwen\utils\logger.py", line 22, in err
    raise error
  File "C:\Users\82105\AppData\Local\Programs\Python\Python39\lib\site-packages\discord\ext\commands\bot.py", line 939, in invoke
    await ctx.command.invoke(ctx)
  File "C:\Users\82105\AppData\Local\Programs\Python\Python39\lib\site-packages\discord\ext\commands\core.py", line 863, in invoke
    await injected(*ctx.args, **ctx.kwargs)
  File "C:\Users\82105\AppData\Local\Programs\Python\Python39\lib\site-packages\discord\ext\commands\core.py", line 94, in wrapped
    raise CommandInvokeError(exc) from exc
discord.ext.commands.errors.CommandInvokeError: Command raised an exception: ExtensionFailed: Extension 'cogs.SearchCommand' raised an error: SyntaxError: cannot assign to function call (SearchCommand.py, line 116)



10시 45분 / [오류] Traceback (most recent call last):
  File "C:\Users\82105\AppData\Local\Programs\Python\Python39\lib\site-packages\discord\ext\commands\bot.py", line 606, in _load_from_module_spec
    spec.loader.exec_module(lib)
  File "<frozen importlib._bootstrap_external>", line 846, in exec_module
  File "<frozen importlib._bootstrap_external>", line 983, in get_code
  File "<frozen importlib._bootstrap_external>", line 913, in source_to_code
  File "<frozen importlib._bootstrap>", line 228, in _call_with_frames_removed
  File "c:\Users\82105\Desktop\Project\Discord\DiscordBot_Gwen\cogs\SearchCommand.py", line 116
    draw.text("원하는 글자위치 x좌표","원하는 글자위치 y좌표"),keyword,fill="white",font=selectedFont,align='center') # fill= 속성은 무슨 색으로 채울지 설정,font=는 자신이 설정한 폰트 설정
    ^
SyntaxError: cannot assign to function call

The above exception was the direct cause of the following exception:

Traceback (most recent call last):
  File "C:\Users\82105\AppData\Local\Programs\Python\Python39\lib\site-packages\discord\ext\commands\core.py", line 85, in wrapped
    ret = await coro(*args, **kwargs)
  File "c:\Users\82105\Desktop\Project\Discord\DiscordBot_Gwen\cogs\AdminCommand.py", line 26, in restart
    self.bot.reload_extension(f"cogs.{i}")
  File "C:\Users\82105\AppData\Local\Programs\Python\Python39\lib\site-packages\discord\ext\commands\bot.py", line 772, in reload_extension
    self.load_extension(name)
  File "C:\Users\82105\AppData\Local\Programs\Python\Python39\lib\site-packages\discord\ext\commands\bot.py", line 678, in load_extension
    self._load_from_module_spec(spec, name)
  File "C:\Users\82105\AppData\Local\Programs\Python\Python39\lib\site-packages\discord\ext\commands\bot.py", line 609, in _load_from_module_spec
    raise errors.ExtensionFailed(key, e) from e
discord.ext.commands.errors.ExtensionFailed: Extension 'cogs.SearchCommand' raised an error: SyntaxError: cannot assign to function call (SearchCommand.py, line 116)

The above exception was the direct cause of the following exception:

Traceback (most recent call last):
  File "c:\Users\82105\Desktop\Project\Discord\DiscordBot_Gwen\utils\logger.py", line 22, in err
    raise error
  File "C:\Users\82105\AppData\Local\Programs\Python\Python39\lib\site-packages\discord\ext\commands\bot.py", line 939, in invoke
    await ctx.command.invoke(ctx)
  File "C:\Users\82105\AppData\Local\Programs\Python\Python39\lib\site-packages\discord\ext\commands\core.py", line 863, in invoke
    await injected(*ctx.args, **ctx.kwargs)
  File "C:\Users\82105\AppData\Local\Programs\Python\Python39\lib\site-packages\discord\ext\commands\core.py", line 94, in wrapped
    raise CommandInvokeError(exc) from exc
discord.ext.commands.errors.CommandInvokeError: Command raised an exception: ExtensionFailed: Extension 'cogs.SearchCommand' raised an error: SyntaxError: cannot assign to function call (SearchCommand.py, line 116)



10시 48분 / [오류] Traceback (most recent call last):
  File "C:\Users\82105\AppData\Local\Programs\Python\Python39\lib\site-packages\discord\ext\commands\core.py", line 85, in wrapped
    ret = await coro(*args, **kwargs)
  File "c:\Users\82105\Desktop\Project\Discord\DiscordBot_Gwen\cogs\SearchCommand.py", line 115, in 챔피언
    selectedFont =ImageFont.truetype(os.path.join('cogs/Cafe24SsurroundAir.ttf','Cafe24SsurroundAir.ttf'), 50) #폰트경로과 사이즈를 설정해줍니다.
  File "C:\Users\82105\AppData\Local\Programs\Python\Python39\lib\site-packages\PIL\ImageFont.py", line 855, in truetype
    return freetype(font)
  File "C:\Users\82105\AppData\Local\Programs\Python\Python39\lib\site-packages\PIL\ImageFont.py", line 852, in freetype
    return FreeTypeFont(font, size, index, encoding, layout_engine)
  File "C:\Users\82105\AppData\Local\Programs\Python\Python39\lib\site-packages\PIL\ImageFont.py", line 211, in __init__
    self.font = core.getfont(
OSError: cannot open resource

The above exception was the direct cause of the following exception:

Traceback (most recent call last):
  File "c:\Users\82105\Desktop\Project\Discord\DiscordBot_Gwen\utils\logger.py", line 22, in err
    raise error
  File "C:\Users\82105\AppData\Local\Programs\Python\Python39\lib\site-packages\discord\ext\commands\bot.py", line 939, in invoke
    await ctx.command.invoke(ctx)
  File "C:\Users\82105\AppData\Local\Programs\Python\Python39\lib\site-packages\discord\ext\commands\core.py", line 863, in invoke
    await injected(*ctx.args, **ctx.kwargs)
  File "C:\Users\82105\AppData\Local\Programs\Python\Python39\lib\site-packages\discord\ext\commands\core.py", line 94, in wrapped
    raise CommandInvokeError(exc) from exc
discord.ext.commands.errors.CommandInvokeError: Command raised an exception: OSError: cannot open resource



10시 49분 / [오류] Traceback (most recent call last):
  File "C:\Users\82105\AppData\Local\Programs\Python\Python39\lib\site-packages\discord\ext\commands\core.py", line 85, in wrapped
    ret = await coro(*args, **kwargs)
  File "c:\Users\82105\Desktop\Project\Discord\DiscordBot_Gwen\cogs\SearchCommand.py", line 116, in 챔피언
    selectedFont = ImageFont.truetype("Cafe24SsurroundAir.ttf", 50, encoding="UTF-8")
  File "C:\Users\82105\AppData\Local\Programs\Python\Python39\lib\site-packages\PIL\ImageFont.py", line 855, in truetype
    return freetype(font)
  File "C:\Users\82105\AppData\Local\Programs\Python\Python39\lib\site-packages\PIL\ImageFont.py", line 852, in freetype
    return FreeTypeFont(font, size, index, encoding, layout_engine)
  File "C:\Users\82105\AppData\Local\Programs\Python\Python39\lib\site-packages\PIL\ImageFont.py", line 211, in __init__
    self.font = core.getfont(
OSError: cannot open resource

The above exception was the direct cause of the following exception:

Traceback (most recent call last):
  File "c:\Users\82105\Desktop\Project\Discord\DiscordBot_Gwen\utils\logger.py", line 22, in err
    raise error
  File "C:\Users\82105\AppData\Local\Programs\Python\Python39\lib\site-packages\discord\ext\commands\bot.py", line 939, in invoke
    await ctx.command.invoke(ctx)
  File "C:\Users\82105\AppData\Local\Programs\Python\Python39\lib\site-packages\discord\ext\commands\core.py", line 863, in invoke
    await injected(*ctx.args, **ctx.kwargs)
  File "C:\Users\82105\AppData\Local\Programs\Python\Python39\lib\site-packages\discord\ext\commands\core.py", line 94, in wrapped
    raise CommandInvokeError(exc) from exc
discord.ext.commands.errors.CommandInvokeError: Command raised an exception: OSError: cannot open resource



11시 18분 / [오류] Traceback (most recent call last):
  File "C:\Users\82105\AppData\Local\Programs\Python\Python39\lib\site-packages\discord\ext\commands\core.py", line 85, in wrapped
    ret = await coro(*args, **kwargs)
  File "c:\Users\82105\Desktop\Project\Discord\DiscordBot_Gwen\cogs\SearchCommand.py", line 103, in 챔피언
    Background.paste(getImg(chamPro, 1000,1000).convert('RGB').filter(ImageFilter.GaussianBlur(30)), (-50, -200))
AttributeError: 'list' object has no attribute 'paste'

The above exception was the direct cause of the following exception:

Traceback (most recent call last):
  File "c:\Users\82105\Desktop\Project\Discord\DiscordBot_Gwen\utils\logger.py", line 22, in err
    raise error
  File "C:\Users\82105\AppData\Local\Programs\Python\Python39\lib\site-packages\discord\ext\commands\bot.py", line 939, in invoke
    await ctx.command.invoke(ctx)
  File "C:\Users\82105\AppData\Local\Programs\Python\Python39\lib\site-packages\discord\ext\commands\core.py", line 863, in invoke
    await injected(*ctx.args, **ctx.kwargs)
  File "C:\Users\82105\AppData\Local\Programs\Python\Python39\lib\site-packages\discord\ext\commands\core.py", line 94, in wrapped
    raise CommandInvokeError(exc) from exc
discord.ext.commands.errors.CommandInvokeError: Command raised an exception: AttributeError: 'list' object has no attribute 'paste'



11시 18분 / [오류] Traceback (most recent call last):
  File "C:\Users\82105\AppData\Local\Programs\Python\Python39\lib\site-packages\discord\ext\commands\core.py", line 85, in wrapped
    ret = await coro(*args, **kwargs)
  File "c:\Users\82105\Desktop\Project\Discord\DiscordBot_Gwen\cogs\SearchCommand.py", line 118, in 챔피언
    getText(Background[0], "asdfasdfasdf", 500, 500, fontsize = 100, fonttype = 'arial.ttf')
TypeError: 'Image' object is not subscriptable

The above exception was the direct cause of the following exception:

Traceback (most recent call last):
  File "c:\Users\82105\Desktop\Project\Discord\DiscordBot_Gwen\utils\logger.py", line 22, in err
    raise error
  File "C:\Users\82105\AppData\Local\Programs\Python\Python39\lib\site-packages\discord\ext\commands\bot.py", line 939, in invoke
    await ctx.command.invoke(ctx)
  File "C:\Users\82105\AppData\Local\Programs\Python\Python39\lib\site-packages\discord\ext\commands\core.py", line 863, in invoke
    await injected(*ctx.args, **ctx.kwargs)
  File "C:\Users\82105\AppData\Local\Programs\Python\Python39\lib\site-packages\discord\ext\commands\core.py", line 94, in wrapped
    raise CommandInvokeError(exc) from exc
discord.ext.commands.errors.CommandInvokeError: Command raised an exception: TypeError: 'Image' object is not subscriptable



11시 20분 / [오류] Traceback (most recent call last):
  File "C:\Users\82105\AppData\Local\Programs\Python\Python39\lib\site-packages\discord\ext\commands\core.py", line 85, in wrapped
    ret = await coro(*args, **kwargs)
  File "c:\Users\82105\Desktop\Project\Discord\DiscordBot_Gwen\cogs\SearchCommand.py", line 118, in 챔피언
    Background = getText(Background, "asdfasdfasdf", 500, 500, fontsize = 100, fonttype = 'Cafe24SsurroundAir.ttf')
  File "c:\Users\82105\Desktop\Project\Discord\DiscordBot_Gwen\cogs\SearchCommand.py", line 166, in getText
    selectedFont = ImageFont.truetype(fonttype, fontsize, encoding="UTF-8")
  File "C:\Users\82105\AppData\Local\Programs\Python\Python39\lib\site-packages\PIL\ImageFont.py", line 855, in truetype
    return freetype(font)
  File "C:\Users\82105\AppData\Local\Programs\Python\Python39\lib\site-packages\PIL\ImageFont.py", line 852, in freetype
    return FreeTypeFont(font, size, index, encoding, layout_engine)
  File "C:\Users\82105\AppData\Local\Programs\Python\Python39\lib\site-packages\PIL\ImageFont.py", line 211, in __init__
    self.font = core.getfont(
OSError: cannot open resource

The above exception was the direct cause of the following exception:

Traceback (most recent call last):
  File "c:\Users\82105\Desktop\Project\Discord\DiscordBot_Gwen\utils\logger.py", line 22, in err
    raise error
  File "C:\Users\82105\AppData\Local\Programs\Python\Python39\lib\site-packages\discord\ext\commands\bot.py", line 939, in invoke
    await ctx.command.invoke(ctx)
  File "C:\Users\82105\AppData\Local\Programs\Python\Python39\lib\site-packages\discord\ext\commands\core.py", line 863, in invoke
    await injected(*ctx.args, **ctx.kwargs)
  File "C:\Users\82105\AppData\Local\Programs\Python\Python39\lib\site-packages\discord\ext\commands\core.py", line 94, in wrapped
    raise CommandInvokeError(exc) from exc
discord.ext.commands.errors.CommandInvokeError: Command raised an exception: OSError: cannot open resource



11시 59분 / [오류] Traceback (most recent call last):
  File "C:\Users\82105\AppData\Local\Programs\Python\Python39\lib\site-packages\discord\ext\commands\core.py", line 85, in wrapped
    ret = await coro(*args, **kwargs)
  File "c:\Users\82105\Desktop\Project\Discord\DiscordBot_Gwen\cogs\SearchCommand.py", line 118, in 챔피언
    Background = getText(Background, arg1, 200, 550, fontsize = 100, fonttype = 'font/Cafe24SsurroundAir.ttf')
  File "c:\Users\82105\Desktop\Project\Discord\DiscordBot_Gwen\cogs\SearchCommand.py", line 168, in getText
    w, h = draw.textsize(text)
  File "C:\Users\82105\AppData\Local\Programs\Python\Python39\lib\site-packages\PIL\ImageDraw.py", line 563, in textsize
    return font.getsize(text, direction, features, language, stroke_width)
  File "C:\Users\82105\AppData\Local\Programs\Python\Python39\lib\site-packages\PIL\ImageFont.py", line 129, in getsize
    return self.font.getsize(text)
UnicodeEncodeError: 'latin-1' codec can't encode characters in position 0-2: ordinal not in range(256)

The above exception was the direct cause of the following exception:

Traceback (most recent call last):
  File "c:\Users\82105\Desktop\Project\Discord\DiscordBot_Gwen\utils\logger.py", line 22, in err
    raise error
  File "C:\Users\82105\AppData\Local\Programs\Python\Python39\lib\site-packages\discord\ext\commands\bot.py", line 939, in invoke
    await ctx.command.invoke(ctx)
  File "C:\Users\82105\AppData\Local\Programs\Python\Python39\lib\site-packages\discord\ext\commands\core.py", line 863, in invoke
    await injected(*ctx.args, **ctx.kwargs)
  File "C:\Users\82105\AppData\Local\Programs\Python\Python39\lib\site-packages\discord\ext\commands\core.py", line 94, in wrapped
    raise CommandInvokeError(exc) from exc
discord.ext.commands.errors.CommandInvokeError: Command raised an exception: UnicodeEncodeError: 'latin-1' codec can't encode characters in position 0-2: ordinal not in range(256)



11시 59분 / [오류] Traceback (most recent call last):
  File "C:\Users\82105\AppData\Local\Programs\Python\Python39\lib\site-packages\discord\ext\commands\core.py", line 85, in wrapped
    ret = await coro(*args, **kwargs)
  File "c:\Users\82105\Desktop\Project\Discord\DiscordBot_Gwen\cogs\SearchCommand.py", line 118, in 챔피언
    Background = getText(Background, arg1, 200, 550, fontsize = 100, fonttype = 'font/Cafe24SsurroundAir.ttf')
  File "c:\Users\82105\Desktop\Project\Discord\DiscordBot_Gwen\cogs\SearchCommand.py", line 168, in getText
    w, h = draw.textsize(text)
  File "C:\Users\82105\AppData\Local\Programs\Python\Python39\lib\site-packages\PIL\ImageDraw.py", line 563, in textsize
    return font.getsize(text, direction, features, language, stroke_width)
  File "C:\Users\82105\AppData\Local\Programs\Python\Python39\lib\site-packages\PIL\ImageFont.py", line 129, in getsize
    return self.font.getsize(text)
UnicodeEncodeError: 'latin-1' codec can't encode character '\uc9c4' in position 0: ordinal not in range(256)

The above exception was the direct cause of the following exception:

Traceback (most recent call last):
  File "c:\Users\82105\Desktop\Project\Discord\DiscordBot_Gwen\utils\logger.py", line 22, in err
    raise error
  File "C:\Users\82105\AppData\Local\Programs\Python\Python39\lib\site-packages\discord\ext\commands\bot.py", line 939, in invoke
    await ctx.command.invoke(ctx)
  File "C:\Users\82105\AppData\Local\Programs\Python\Python39\lib\site-packages\discord\ext\commands\core.py", line 863, in invoke
    await injected(*ctx.args, **ctx.kwargs)
  File "C:\Users\82105\AppData\Local\Programs\Python\Python39\lib\site-packages\discord\ext\commands\core.py", line 94, in wrapped
    raise CommandInvokeError(exc) from exc
discord.ext.commands.errors.CommandInvokeError: Command raised an exception: UnicodeEncodeError: 'latin-1' codec can't encode character '\uc9c4' in position 0: ordinal not in range(256)



12시 00분 / [오류] Traceback (most recent call last):
  File "C:\Users\82105\AppData\Local\Programs\Python\Python39\lib\site-packages\discord\ext\commands\core.py", line 85, in wrapped
    ret = await coro(*args, **kwargs)
  File "c:\Users\82105\Desktop\Project\Discord\DiscordBot_Gwen\cogs\SearchCommand.py", line 118, in 챔피언
    Background = getText(Background, arg1, 200, 550, fontsize = 100, fonttype = 'font/Cafe24SsurroundAir.ttf')
  File "c:\Users\82105\Desktop\Project\Discord\DiscordBot_Gwen\cogs\SearchCommand.py", line 168, in getText
    w, h = draw.textsize(text)
  File "C:\Users\82105\AppData\Local\Programs\Python\Python39\lib\site-packages\PIL\ImageDraw.py", line 563, in textsize
    return font.getsize(text, direction, features, language, stroke_width)
  File "C:\Users\82105\AppData\Local\Programs\Python\Python39\lib\site-packages\PIL\ImageFont.py", line 129, in getsize
    return self.font.getsize(text)
UnicodeEncodeError: 'latin-1' codec can't encode characters in position 0-3: ordinal not in range(256)

The above exception was the direct cause of the following exception:

Traceback (most recent call last):
  File "c:\Users\82105\Desktop\Project\Discord\DiscordBot_Gwen\utils\logger.py", line 22, in err
    raise error
  File "C:\Users\82105\AppData\Local\Programs\Python\Python39\lib\site-packages\discord\ext\commands\bot.py", line 939, in invoke
    await ctx.command.invoke(ctx)
  File "C:\Users\82105\AppData\Local\Programs\Python\Python39\lib\site-packages\discord\ext\commands\core.py", line 863, in invoke
    await injected(*ctx.args, **ctx.kwargs)
  File "C:\Users\82105\AppData\Local\Programs\Python\Python39\lib\site-packages\discord\ext\commands\core.py", line 94, in wrapped
    raise CommandInvokeError(exc) from exc
discord.ext.commands.errors.CommandInvokeError: Command raised an exception: UnicodeEncodeError: 'latin-1' codec can't encode characters in position 0-3: ordinal not in range(256)



12시 00분 / [오류] Traceback (most recent call last):
  File "C:\Users\82105\AppData\Local\Programs\Python\Python39\lib\site-packages\discord\ext\commands\core.py", line 85, in wrapped
    ret = await coro(*args, **kwargs)
  File "c:\Users\82105\Desktop\Project\Discord\DiscordBot_Gwen\cogs\SearchCommand.py", line 118, in 챔피언
    Background = getText(Background, arg1, 200, 550, fontsize = 100, fonttype = 'font/Cafe24SsurroundAir.ttf')
  File "c:\Users\82105\Desktop\Project\Discord\DiscordBot_Gwen\cogs\SearchCommand.py", line 168, in getText
    w, h = draw.textsize(text)
  File "C:\Users\82105\AppData\Local\Programs\Python\Python39\lib\site-packages\PIL\ImageDraw.py", line 563, in textsize
    return font.getsize(text, direction, features, language, stroke_width)
  File "C:\Users\82105\AppData\Local\Programs\Python\Python39\lib\site-packages\PIL\ImageFont.py", line 129, in getsize
    return self.font.getsize(text)
UnicodeEncodeError: 'latin-1' codec can't encode characters in position 0-3: ordinal not in range(256)

The above exception was the direct cause of the following exception:

Traceback (most recent call last):
  File "c:\Users\82105\Desktop\Project\Discord\DiscordBot_Gwen\utils\logger.py", line 22, in err
    raise error
  File "C:\Users\82105\AppData\Local\Programs\Python\Python39\lib\site-packages\discord\ext\commands\bot.py", line 939, in invoke
    await ctx.command.invoke(ctx)
  File "C:\Users\82105\AppData\Local\Programs\Python\Python39\lib\site-packages\discord\ext\commands\core.py", line 863, in invoke
    await injected(*ctx.args, **ctx.kwargs)
  File "C:\Users\82105\AppData\Local\Programs\Python\Python39\lib\site-packages\discord\ext\commands\core.py", line 94, in wrapped
    raise CommandInvokeError(exc) from exc
discord.ext.commands.errors.CommandInvokeError: Command raised an exception: UnicodeEncodeError: 'latin-1' codec can't encode characters in position 0-3: ordinal not in range(256)



12시 31분 / [오류] Traceback (most recent call last):
  File "C:\Users\82105\AppData\Local\Programs\Python\Python39\lib\site-packages\discord\ext\commands\core.py", line 85, in wrapped
    ret = await coro(*args, **kwargs)
  File "c:\Users\82105\Desktop\Project\Discord\DiscordBot_Gwen\cogs\SearchCommand.py", line 127, in 챔피언
    await ctx.send(file=out)
  File "C:\Users\82105\AppData\Local\Programs\Python\Python39\lib\site-packages\discord\abc.py", line 1045, in send
    data = await state.http.send_files(channel.id, files=[file], allowed_mentions=allowed_mentions,
  File "C:\Users\82105\AppData\Local\Programs\Python\Python39\lib\site-packages\discord\http.py", line 192, in request
    async with self.__session.request(method, url, **kwargs) as r:
  File "C:\Users\82105\AppData\Local\Programs\Python\Python39\lib\site-packages\aiohttp\client.py", line 1117, in __aenter__
    self._resp = await self._coro
  File "C:\Users\82105\AppData\Local\Programs\Python\Python39\lib\site-packages\aiohttp\client.py", line 544, in _request
    await resp.start(conn)
  File "C:\Users\82105\AppData\Local\Programs\Python\Python39\lib\site-packages\aiohttp\client_reqrep.py", line 890, in start
    message, payload = await self._protocol.read()  # type: ignore
  File "C:\Users\82105\AppData\Local\Programs\Python\Python39\lib\site-packages\aiohttp\streams.py", line 604, in read
    await self._waiter
aiohttp.client_exceptions.ClientOSError: [WinError 64] 지정된 네트워크 이름을 더 이상 사용할 수 없습니다

The above exception was the direct cause of the following exception:

Traceback (most recent call last):
  File "c:\Users\82105\Desktop\Project\Discord\DiscordBot_Gwen\utils\logger.py", line 22, in err
    raise error
  File "C:\Users\82105\AppData\Local\Programs\Python\Python39\lib\site-packages\discord\ext\commands\bot.py", line 939, in invoke
    await ctx.command.invoke(ctx)
  File "C:\Users\82105\AppData\Local\Programs\Python\Python39\lib\site-packages\discord\ext\commands\core.py", line 863, in invoke
    await injected(*ctx.args, **ctx.kwargs)
  File "C:\Users\82105\AppData\Local\Programs\Python\Python39\lib\site-packages\discord\ext\commands\core.py", line 94, in wrapped
    raise CommandInvokeError(exc) from exc
discord.ext.commands.errors.CommandInvokeError: Command raised an exception: ClientOSError: [WinError 64] 지정된 네트워크 이름을 더 이상 사용할 수 없습니다



12시 37분 / [오류] Traceback (most recent call last):
  File "C:\Users\82105\AppData\Local\Programs\Python\Python39\lib\site-packages\urllib3\connectionpool.py", line 699, in urlopen
    httplib_response = self._make_request(
  File "C:\Users\82105\AppData\Local\Programs\Python\Python39\lib\site-packages\urllib3\connectionpool.py", line 382, in _make_request
    self._validate_conn(conn)
  File "C:\Users\82105\AppData\Local\Programs\Python\Python39\lib\site-packages\urllib3\connectionpool.py", line 1010, in _validate_conn
    conn.connect()
  File "C:\Users\82105\AppData\Local\Programs\Python\Python39\lib\site-packages\urllib3\connection.py", line 411, in connect
    self.sock = ssl_wrap_socket(
  File "C:\Users\82105\AppData\Local\Programs\Python\Python39\lib\site-packages\urllib3\util\ssl_.py", line 449, in ssl_wrap_socket
    ssl_sock = _ssl_wrap_socket_impl(
  File "C:\Users\82105\AppData\Local\Programs\Python\Python39\lib\site-packages\urllib3\util\ssl_.py", line 493, in _ssl_wrap_socket_impl
    return ssl_context.wrap_socket(sock, server_hostname=server_hostname)
  File "C:\Users\82105\AppData\Local\Programs\Python\Python39\lib\ssl.py", line 500, in wrap_socket
    return self.sslsocket_class._create(
  File "C:\Users\82105\AppData\Local\Programs\Python\Python39\lib\ssl.py", line 1040, in _create
    self.do_handshake()
  File "C:\Users\82105\AppData\Local\Programs\Python\Python39\lib\ssl.py", line 1309, in do_handshake
    self._sslobj.do_handshake()
ssl.SSLCertVerificationError: [SSL: CERTIFICATE_VERIFY_FAILED] certificate verify failed: self signed certificate (_ssl.c:1129)

During handling of the above exception, another exception occurred:

Traceback (most recent call last):
  File "C:\Users\82105\AppData\Local\Programs\Python\Python39\lib\site-packages\requests\adapters.py", line 439, in send
    resp = conn.urlopen(
  File "C:\Users\82105\AppData\Local\Programs\Python\Python39\lib\site-packages\urllib3\connectionpool.py", line 755, in urlopen
    retries = retries.increment(
  File "C:\Users\82105\AppData\Local\Programs\Python\Python39\lib\site-packages\urllib3\util\retry.py", line 574, in increment
    raise MaxRetryError(_pool, url, error or ResponseError(cause))
urllib3.exceptions.MaxRetryError: HTTPSConnectionPool(host='www.op.gg', port=443): Max retries exceeded with url: /champion/akali (Caused by SSLError(SSLCertVerificationError(1, '[SSL: CERTIFICATE_VERIFY_FAILED] certificate verify failed: self signed certificate (_ssl.c:1129)')))

During handling of the above exception, another exception occurred:

Traceback (most recent call last):
  File "C:\Users\82105\AppData\Local\Programs\Python\Python39\lib\site-packages\discord\ext\commands\core.py", line 85, in wrapped
    ret = await coro(*args, **kwargs)
  File "c:\Users\82105\Desktop\Project\Discord\DiscordBot_Gwen\cogs\SearchCommand.py", line 82, in 챔피언
    res = requests.get(url).text
  File "C:\Users\82105\AppData\Local\Programs\Python\Python39\lib\site-packages\requests\api.py", line 75, in get
    return request('get', url, params=params, **kwargs)
  File "C:\Users\82105\AppData\Local\Programs\Python\Python39\lib\site-packages\requests\api.py", line 61, in request
    return session.request(method=method, url=url, **kwargs)
  File "C:\Users\82105\AppData\Local\Programs\Python\Python39\lib\site-packages\requests\sessions.py", line 542, in request
    resp = self.send(prep, **send_kwargs)
  File "C:\Users\82105\AppData\Local\Programs\Python\Python39\lib\site-packages\requests\sessions.py", line 655, in send
    r = adapter.send(request, **kwargs)
  File "C:\Users\82105\AppData\Local\Programs\Python\Python39\lib\site-packages\requests\adapters.py", line 514, in send
    raise SSLError(e, request=request)
requests.exceptions.SSLError: HTTPSConnectionPool(host='www.op.gg', port=443): Max retries exceeded with url: /champion/akali (Caused by SSLError(SSLCertVerificationError(1, '[SSL: CERTIFICATE_VERIFY_FAILED] certificate verify failed: self signed certificate (_ssl.c:1129)')))

The above exception was the direct cause of the following exception:

Traceback (most recent call last):
  File "c:\Users\82105\Desktop\Project\Discord\DiscordBot_Gwen\utils\logger.py", line 22, in err
    raise error
  File "C:\Users\82105\AppData\Local\Programs\Python\Python39\lib\site-packages\discord\ext\commands\bot.py", line 939, in invoke
    await ctx.command.invoke(ctx)
  File "C:\Users\82105\AppData\Local\Programs\Python\Python39\lib\site-packages\discord\ext\commands\core.py", line 863, in invoke
    await injected(*ctx.args, **ctx.kwargs)
  File "C:\Users\82105\AppData\Local\Programs\Python\Python39\lib\site-packages\discord\ext\commands\core.py", line 94, in wrapped
    raise CommandInvokeError(exc) from exc
discord.ext.commands.errors.CommandInvokeError: Command raised an exception: SSLError: HTTPSConnectionPool(host='www.op.gg', port=443): Max retries exceeded with url: /champion/akali (Caused by SSLError(SSLCertVerificationError(1, '[SSL: CERTIFICATE_VERIFY_FAILED] certificate verify failed: self signed certificate (_ssl.c:1129)')))



12시 37분 / [오류] Traceback (most recent call last):
  File "C:\Users\82105\AppData\Local\Programs\Python\Python39\lib\site-packages\urllib3\connectionpool.py", line 699, in urlopen
    httplib_response = self._make_request(
  File "C:\Users\82105\AppData\Local\Programs\Python\Python39\lib\site-packages\urllib3\connectionpool.py", line 382, in _make_request
    self._validate_conn(conn)
  File "C:\Users\82105\AppData\Local\Programs\Python\Python39\lib\site-packages\urllib3\connectionpool.py", line 1010, in _validate_conn
    conn.connect()
  File "C:\Users\82105\AppData\Local\Programs\Python\Python39\lib\site-packages\urllib3\connection.py", line 411, in connect
    self.sock = ssl_wrap_socket(
  File "C:\Users\82105\AppData\Local\Programs\Python\Python39\lib\site-packages\urllib3\util\ssl_.py", line 449, in ssl_wrap_socket
    ssl_sock = _ssl_wrap_socket_impl(
  File "C:\Users\82105\AppData\Local\Programs\Python\Python39\lib\site-packages\urllib3\util\ssl_.py", line 493, in _ssl_wrap_socket_impl
    return ssl_context.wrap_socket(sock, server_hostname=server_hostname)
  File "C:\Users\82105\AppData\Local\Programs\Python\Python39\lib\ssl.py", line 500, in wrap_socket
    return self.sslsocket_class._create(
  File "C:\Users\82105\AppData\Local\Programs\Python\Python39\lib\ssl.py", line 1040, in _create
    self.do_handshake()
  File "C:\Users\82105\AppData\Local\Programs\Python\Python39\lib\ssl.py", line 1309, in do_handshake
    self._sslobj.do_handshake()
ssl.SSLCertVerificationError: [SSL: CERTIFICATE_VERIFY_FAILED] certificate verify failed: self signed certificate (_ssl.c:1129)

During handling of the above exception, another exception occurred:

Traceback (most recent call last):
  File "C:\Users\82105\AppData\Local\Programs\Python\Python39\lib\site-packages\requests\adapters.py", line 439, in send
    resp = conn.urlopen(
  File "C:\Users\82105\AppData\Local\Programs\Python\Python39\lib\site-packages\urllib3\connectionpool.py", line 755, in urlopen
    retries = retries.increment(
  File "C:\Users\82105\AppData\Local\Programs\Python\Python39\lib\site-packages\urllib3\util\retry.py", line 574, in increment
    raise MaxRetryError(_pool, url, error or ResponseError(cause))
urllib3.exceptions.MaxRetryError: HTTPSConnectionPool(host='www.op.gg', port=443): Max retries exceeded with url: /summoner/userName=%EC%8B%9C%EB%A6%AC%ED%95%98%EB%A3%A8 (Caused by SSLError(SSLCertVerificationError(1, '[SSL: CERTIFICATE_VERIFY_FAILED] certificate verify failed: self signed certificate (_ssl.c:1129)')))

During handling of the above exception, another exception occurred:

Traceback (most recent call last):
  File "C:\Users\82105\AppData\Local\Programs\Python\Python39\lib\site-packages\discord\ext\commands\core.py", line 85, in wrapped
    ret = await coro(*args, **kwargs)
  File "c:\Users\82105\Desktop\Project\Discord\DiscordBot_Gwen\cogs\SearchCommand.py", line 29, in 전적
    res = requests.get(url).text
  File "C:\Users\82105\AppData\Local\Programs\Python\Python39\lib\site-packages\requests\api.py", line 75, in get
    return request('get', url, params=params, **kwargs)
  File "C:\Users\82105\AppData\Local\Programs\Python\Python39\lib\site-packages\requests\api.py", line 61, in request
    return session.request(method=method, url=url, **kwargs)
  File "C:\Users\82105\AppData\Local\Programs\Python\Python39\lib\site-packages\requests\sessions.py", line 542, in request
    resp = self.send(prep, **send_kwargs)
  File "C:\Users\82105\AppData\Local\Programs\Python\Python39\lib\site-packages\requests\sessions.py", line 677, in send
    history = [resp for resp in gen]
  File "C:\Users\82105\AppData\Local\Programs\Python\Python39\lib\site-packages\requests\sessions.py", line 677, in <listcomp>
    history = [resp for resp in gen]
  File "C:\Users\82105\AppData\Local\Programs\Python\Python39\lib\site-packages\requests\sessions.py", line 237, in resolve_redirects
    resp = self.send(
  File "C:\Users\82105\AppData\Local\Programs\Python\Python39\lib\site-packages\requests\sessions.py", line 655, in send
    r = adapter.send(request, **kwargs)
  File "C:\Users\82105\AppData\Local\Programs\Python\Python39\lib\site-packages\requests\adapters.py", line 514, in send
    raise SSLError(e, request=request)
requests.exceptions.SSLError: HTTPSConnectionPool(host='www.op.gg', port=443): Max retries exceeded with url: /summoner/userName=%EC%8B%9C%EB%A6%AC%ED%95%98%EB%A3%A8 (Caused by SSLError(SSLCertVerificationError(1, '[SSL: CERTIFICATE_VERIFY_FAILED] certificate verify failed: self signed certificate (_ssl.c:1129)')))

The above exception was the direct cause of the following exception:

Traceback (most recent call last):
  File "c:\Users\82105\Desktop\Project\Discord\DiscordBot_Gwen\utils\logger.py", line 22, in err
    raise error
  File "C:\Users\82105\AppData\Local\Programs\Python\Python39\lib\site-packages\discord\ext\commands\bot.py", line 939, in invoke
    await ctx.command.invoke(ctx)
  File "C:\Users\82105\AppData\Local\Programs\Python\Python39\lib\site-packages\discord\ext\commands\core.py", line 863, in invoke
    await injected(*ctx.args, **ctx.kwargs)
  File "C:\Users\82105\AppData\Local\Programs\Python\Python39\lib\site-packages\discord\ext\commands\core.py", line 94, in wrapped
    raise CommandInvokeError(exc) from exc
discord.ext.commands.errors.CommandInvokeError: Command raised an exception: SSLError: HTTPSConnectionPool(host='www.op.gg', port=443): Max retries exceeded with url: /summoner/userName=%EC%8B%9C%EB%A6%AC%ED%95%98%EB%A3%A8 (Caused by SSLError(SSLCertVerificationError(1, '[SSL: CERTIFICATE_VERIFY_FAILED] certificate verify failed: self signed certificate (_ssl.c:1129)')))



14시 10분 / [오류] Traceback (most recent call last):
  File "C:\Users\82105\AppData\Local\Programs\Python\Python39\lib\site-packages\discord\ext\commands\core.py", line 85, in wrapped
    ret = await coro(*args, **kwargs)
  File "c:\Users\82105\Desktop\Project\Discord\DiscordBot_Gwen\cogs\SearchCommand.py", line 86, in 챔피언
    winrate = soup.find("div", attrs={"class":"champion-stats-trend-rate"}).get_text()
AttributeError: 'NoneType' object has no attribute 'get_text'

The above exception was the direct cause of the following exception:

Traceback (most recent call last):
  File "c:\Users\82105\Desktop\Project\Discord\DiscordBot_Gwen\utils\logger.py", line 22, in err
    raise error
  File "C:\Users\82105\AppData\Local\Programs\Python\Python39\lib\site-packages\discord\ext\commands\bot.py", line 939, in invoke
    await ctx.command.invoke(ctx)
  File "C:\Users\82105\AppData\Local\Programs\Python\Python39\lib\site-packages\discord\ext\commands\core.py", line 863, in invoke
    await injected(*ctx.args, **ctx.kwargs)
  File "C:\Users\82105\AppData\Local\Programs\Python\Python39\lib\site-packages\discord\ext\commands\core.py", line 94, in wrapped
    raise CommandInvokeError(exc) from exc
discord.ext.commands.errors.CommandInvokeError: Command raised an exception: AttributeError: 'NoneType' object has no attribute 'get_text'



14시 14분 / [오류] Traceback (most recent call last):
  File "C:\Users\82105\AppData\Local\Programs\Python\Python39\lib\site-packages\discord\ext\commands\core.py", line 85, in wrapped
    ret = await coro(*args, **kwargs)
  File "c:\Users\82105\Desktop\Project\Discord\DiscordBot_Gwen\cogs\SearchCommand.py", line 91, in 챔피언
    chamPro = soup.find("div", attrs={"class":"champion-stats-header-info__image"}).find("img").get("src")
AttributeError: 'NoneType' object has no attribute 'find'

The above exception was the direct cause of the following exception:

Traceback (most recent call last):
  File "c:\Users\82105\Desktop\Project\Discord\DiscordBot_Gwen\utils\logger.py", line 22, in err
    raise error
  File "C:\Users\82105\AppData\Local\Programs\Python\Python39\lib\site-packages\discord\ext\commands\bot.py", line 939, in invoke
    await ctx.command.invoke(ctx)
  File "C:\Users\82105\AppData\Local\Programs\Python\Python39\lib\site-packages\discord\ext\commands\core.py", line 863, in invoke
    await injected(*ctx.args, **ctx.kwargs)
  File "C:\Users\82105\AppData\Local\Programs\Python\Python39\lib\site-packages\discord\ext\commands\core.py", line 94, in wrapped
    raise CommandInvokeError(exc) from exc
discord.ext.commands.errors.CommandInvokeError: Command raised an exception: AttributeError: 'NoneType' object has no attribute 'find'



14시 22분 / [오류] Traceback (most recent call last):
  File "C:\Users\82105\AppData\Local\Programs\Python\Python39\lib\site-packages\discord\ext\commands\core.py", line 85, in wrapped
    ret = await coro(*args, **kwargs)
  File "c:\Users\82105\Desktop\Project\Discord\DiscordBot_Gwen\cogs\SearchCommand.py", line 124, in 챔피언
    Background = getText(Background, winrate, 330, 680, fontsize = 50)
UnboundLocalError: local variable 'winrate' referenced before assignment

The above exception was the direct cause of the following exception:

Traceback (most recent call last):
  File "c:\Users\82105\Desktop\Project\Discord\DiscordBot_Gwen\utils\logger.py", line 22, in err
    raise error
  File "C:\Users\82105\AppData\Local\Programs\Python\Python39\lib\site-packages\discord\ext\commands\bot.py", line 939, in invoke
    await ctx.command.invoke(ctx)
  File "C:\Users\82105\AppData\Local\Programs\Python\Python39\lib\site-packages\discord\ext\commands\core.py", line 863, in invoke
    await injected(*ctx.args, **ctx.kwargs)
  File "C:\Users\82105\AppData\Local\Programs\Python\Python39\lib\site-packages\discord\ext\commands\core.py", line 94, in wrapped
    raise CommandInvokeError(exc) from exc
discord.ext.commands.errors.CommandInvokeError: Command raised an exception: UnboundLocalError: local variable 'winrate' referenced before assignment



14시 33분 / [오류] Traceback (most recent call last):
  File "C:\Users\82105\AppData\Local\Programs\Python\Python39\lib\site-packages\discord\ext\commands\core.py", line 85, in wrapped
    ret = await coro(*args, **kwargs)
  File "c:\Users\82105\Desktop\Project\Discord\DiscordBot_Gwen\cogs\SearchCommand.py", line 147, in 챔피언
    await ctx.send(file=out)
  File "C:\Users\82105\AppData\Local\Programs\Python\Python39\lib\site-packages\discord\abc.py", line 1045, in send
    data = await state.http.send_files(channel.id, files=[file], allowed_mentions=allowed_mentions,
  File "C:\Users\82105\AppData\Local\Programs\Python\Python39\lib\site-packages\discord\http.py", line 192, in request
    async with self.__session.request(method, url, **kwargs) as r:
  File "C:\Users\82105\AppData\Local\Programs\Python\Python39\lib\site-packages\aiohttp\client.py", line 1117, in __aenter__
    self._resp = await self._coro
  File "C:\Users\82105\AppData\Local\Programs\Python\Python39\lib\site-packages\aiohttp\client.py", line 544, in _request
    await resp.start(conn)
  File "C:\Users\82105\AppData\Local\Programs\Python\Python39\lib\site-packages\aiohttp\client_reqrep.py", line 890, in start
    message, payload = await self._protocol.read()  # type: ignore
  File "C:\Users\82105\AppData\Local\Programs\Python\Python39\lib\site-packages\aiohttp\streams.py", line 604, in read
    await self._waiter
aiohttp.client_exceptions.ClientOSError: [WinError 64] 지정된 네트워크 이름을 더 이상 사용할 수 없습니다

The above exception was the direct cause of the following exception:

Traceback (most recent call last):
  File "c:\Users\82105\Desktop\Project\Discord\DiscordBot_Gwen\utils\logger.py", line 22, in err
    raise error
  File "C:\Users\82105\AppData\Local\Programs\Python\Python39\lib\site-packages\discord\ext\commands\bot.py", line 939, in invoke
    await ctx.command.invoke(ctx)
  File "C:\Users\82105\AppData\Local\Programs\Python\Python39\lib\site-packages\discord\ext\commands\core.py", line 863, in invoke
    await injected(*ctx.args, **ctx.kwargs)
  File "C:\Users\82105\AppData\Local\Programs\Python\Python39\lib\site-packages\discord\ext\commands\core.py", line 94, in wrapped
    raise CommandInvokeError(exc) from exc
discord.ext.commands.errors.CommandInvokeError: Command raised an exception: ClientOSError: [WinError 64] 지정된 네트워크 이름을 더 이상 사용할 수 없습니다



14시 44분 / [오류] Traceback (most recent call last):
  File "C:\Users\82105\AppData\Local\Programs\Python\Python39\lib\site-packages\discord\ext\commands\core.py", line 85, in wrapped
    ret = await coro(*args, **kwargs)
  File "c:\Users\82105\Desktop\Project\Discord\DiscordBot_Gwen\cogs\SearchCommand.py", line 95, in 챔피언
    for i in 34:
TypeError: 'int' object is not iterable

The above exception was the direct cause of the following exception:

Traceback (most recent call last):
  File "c:\Users\82105\Desktop\Project\Discord\DiscordBot_Gwen\utils\logger.py", line 22, in err
    raise error
  File "C:\Users\82105\AppData\Local\Programs\Python\Python39\lib\site-packages\discord\ext\commands\bot.py", line 939, in invoke
    await ctx.command.invoke(ctx)
  File "C:\Users\82105\AppData\Local\Programs\Python\Python39\lib\site-packages\discord\ext\commands\core.py", line 863, in invoke
    await injected(*ctx.args, **ctx.kwargs)
  File "C:\Users\82105\AppData\Local\Programs\Python\Python39\lib\site-packages\discord\ext\commands\core.py", line 94, in wrapped
    raise CommandInvokeError(exc) from exc
discord.ext.commands.errors.CommandInvokeError: Command raised an exception: TypeError: 'int' object is not iterable



14시 53분 / [오류] Traceback (most recent call last):
  File "C:\Users\82105\AppData\Local\Programs\Python\Python39\lib\site-packages\discord\ext\commands\core.py", line 85, in wrapped
    ret = await coro(*args, **kwargs)
  File "c:\Users\82105\Desktop\Project\Discord\DiscordBot_Gwen\cogs\SearchCommand.py", line 94, in 챔피언
    tier = soup.find("div", attrs={"class":"champion-stats-header-info__tier"}).find("br").get_text()
AttributeError: 'NoneType' object has no attribute 'get_text'

The above exception was the direct cause of the following exception:

Traceback (most recent call last):
  File "c:\Users\82105\Desktop\Project\Discord\DiscordBot_Gwen\utils\logger.py", line 22, in err
    raise error
  File "C:\Users\82105\AppData\Local\Programs\Python\Python39\lib\site-packages\discord\ext\commands\bot.py", line 939, in invoke
    await ctx.command.invoke(ctx)
  File "C:\Users\82105\AppData\Local\Programs\Python\Python39\lib\site-packages\discord\ext\commands\core.py", line 863, in invoke
    await injected(*ctx.args, **ctx.kwargs)
  File "C:\Users\82105\AppData\Local\Programs\Python\Python39\lib\site-packages\discord\ext\commands\core.py", line 94, in wrapped
    raise CommandInvokeError(exc) from exc
discord.ext.commands.errors.CommandInvokeError: Command raised an exception: AttributeError: 'NoneType' object has no attribute 'get_text'



14시 57분 / [오류] Traceback (most recent call last):
  File "C:\Users\82105\AppData\Local\Programs\Python\Python39\lib\site-packages\discord\ext\commands\core.py", line 85, in wrapped
    ret = await coro(*args, **kwargs)
  File "c:\Users\82105\Desktop\Project\Discord\DiscordBot_Gwen\cogs\SearchCommand.py", line 96, in 챔피언
    logger.info(tier[i])
IndexError: string index out of range

The above exception was the direct cause of the following exception:

Traceback (most recent call last):
  File "c:\Users\82105\Desktop\Project\Discord\DiscordBot_Gwen\utils\logger.py", line 22, in err
    raise error
  File "C:\Users\82105\AppData\Local\Programs\Python\Python39\lib\site-packages\discord\ext\commands\bot.py", line 939, in invoke
    await ctx.command.invoke(ctx)
  File "C:\Users\82105\AppData\Local\Programs\Python\Python39\lib\site-packages\discord\ext\commands\core.py", line 863, in invoke
    await injected(*ctx.args, **ctx.kwargs)
  File "C:\Users\82105\AppData\Local\Programs\Python\Python39\lib\site-packages\discord\ext\commands\core.py", line 94, in wrapped
    raise CommandInvokeError(exc) from exc
discord.ext.commands.errors.CommandInvokeError: Command raised an exception: IndexError: string index out of range



15시 02분 / [오류] Traceback (most recent call last):
  File "C:\Users\82105\AppData\Local\Programs\Python\Python39\lib\site-packages\discord\ext\commands\core.py", line 85, in wrapped
    ret = await coro(*args, **kwargs)
  File "c:\Users\82105\Desktop\Project\Discord\DiscordBot_Gwen\cogs\SearchCommand.py", line 96, in 챔피언
    if tier[len(tier)] == '5':
IndexError: string index out of range

The above exception was the direct cause of the following exception:

Traceback (most recent call last):
  File "c:\Users\82105\Desktop\Project\Discord\DiscordBot_Gwen\utils\logger.py", line 22, in err
    raise error
  File "C:\Users\82105\AppData\Local\Programs\Python\Python39\lib\site-packages\discord\ext\commands\bot.py", line 939, in invoke
    await ctx.command.invoke(ctx)
  File "C:\Users\82105\AppData\Local\Programs\Python\Python39\lib\site-packages\discord\ext\commands\core.py", line 863, in invoke
    await injected(*ctx.args, **ctx.kwargs)
  File "C:\Users\82105\AppData\Local\Programs\Python\Python39\lib\site-packages\discord\ext\commands\core.py", line 94, in wrapped
    raise CommandInvokeError(exc) from exc
discord.ext.commands.errors.CommandInvokeError: Command raised an exception: IndexError: string index out of range



15시 04분 / [오류] Traceback (most recent call last):
  File "C:\Users\82105\AppData\Local\Programs\Python\Python39\lib\site-packages\discord\ext\commands\core.py", line 85, in wrapped
    ret = await coro(*args, **kwargs)
  File "c:\Users\82105\Desktop\Project\Discord\DiscordBot_Gwen\cogs\SearchCommand.py", line 96, in 챔피언
    if tier[len(tier) - 1] == '5':
IndexError: string index out of range

The above exception was the direct cause of the following exception:

Traceback (most recent call last):
  File "c:\Users\82105\Desktop\Project\Discord\DiscordBot_Gwen\utils\logger.py", line 22, in err
    raise error
  File "C:\Users\82105\AppData\Local\Programs\Python\Python39\lib\site-packages\discord\ext\commands\bot.py", line 939, in invoke
    await ctx.command.invoke(ctx)
  File "C:\Users\82105\AppData\Local\Programs\Python\Python39\lib\site-packages\discord\ext\commands\core.py", line 863, in invoke
    await injected(*ctx.args, **ctx.kwargs)
  File "C:\Users\82105\AppData\Local\Programs\Python\Python39\lib\site-packages\discord\ext\commands\core.py", line 94, in wrapped
    raise CommandInvokeError(exc) from exc
discord.ext.commands.errors.CommandInvokeError: Command raised an exception: IndexError: string index out of range



15시 06분 / [오류] Traceback (most recent call last):
  File "C:\Users\82105\AppData\Local\Programs\Python\Python39\lib\site-packages\discord\ext\commands\core.py", line 85, in wrapped
    ret = await coro(*args, **kwargs)
  File "c:\Users\82105\Desktop\Project\Discord\DiscordBot_Gwen\cogs\SearchCommand.py", line 99, in 챔피언
    if tier[len(tier) - 1] == '5':
IndexError: string index out of range

The above exception was the direct cause of the following exception:

Traceback (most recent call last):
  File "c:\Users\82105\Desktop\Project\Discord\DiscordBot_Gwen\utils\logger.py", line 22, in err
    raise error
  File "C:\Users\82105\AppData\Local\Programs\Python\Python39\lib\site-packages\discord\ext\commands\bot.py", line 939, in invoke
    await ctx.command.invoke(ctx)
  File "C:\Users\82105\AppData\Local\Programs\Python\Python39\lib\site-packages\discord\ext\commands\core.py", line 863, in invoke
    await injected(*ctx.args, **ctx.kwargs)
  File "C:\Users\82105\AppData\Local\Programs\Python\Python39\lib\site-packages\discord\ext\commands\core.py", line 94, in wrapped
    raise CommandInvokeError(exc) from exc
discord.ext.commands.errors.CommandInvokeError: Command raised an exception: IndexError: string index out of range



15시 06분 / [오류] Traceback (most recent call last):
  File "c:\Users\82105\Desktop\Project\Discord\DiscordBot_Gwen\cogs\SearchCommand.py", line 87, in 챔피언
    winrate = soup.find("div", attrs={"class":"champion-stats-trend-rate"}).get_text()
AttributeError: 'NoneType' object has no attribute 'get_text'

During handling of the above exception, another exception occurred:

Traceback (most recent call last):
  File "C:\Users\82105\AppData\Local\Programs\Python\Python39\lib\site-packages\discord\ext\commands\core.py", line 85, in wrapped
    ret = await coro(*args, **kwargs)
  File "c:\Users\82105\Desktop\Project\Discord\DiscordBot_Gwen\cogs\SearchCommand.py", line 92, in 챔피언
    winrate = soup.find("div", attrs={"class":"champion-stats-trend-rate"}).get_text()
AttributeError: 'NoneType' object has no attribute 'get_text'

The above exception was the direct cause of the following exception:

Traceback (most recent call last):
  File "c:\Users\82105\Desktop\Project\Discord\DiscordBot_Gwen\utils\logger.py", line 22, in err
    raise error
  File "C:\Users\82105\AppData\Local\Programs\Python\Python39\lib\site-packages\discord\ext\commands\bot.py", line 939, in invoke
    await ctx.command.invoke(ctx)
  File "C:\Users\82105\AppData\Local\Programs\Python\Python39\lib\site-packages\discord\ext\commands\core.py", line 863, in invoke
    await injected(*ctx.args, **ctx.kwargs)
  File "C:\Users\82105\AppData\Local\Programs\Python\Python39\lib\site-packages\discord\ext\commands\core.py", line 94, in wrapped
    raise CommandInvokeError(exc) from exc
discord.ext.commands.errors.CommandInvokeError: Command raised an exception: AttributeError: 'NoneType' object has no attribute 'get_text'



15시 08분 / [오류] Traceback (most recent call last):
  File "c:\Users\82105\Desktop\Project\Discord\DiscordBot_Gwen\cogs\SearchCommand.py", line 87, in 챔피언
    winrate = soup.find("div", attrs={"class":"champion-stats-trend-rate"}).get_text()
AttributeError: 'NoneType' object has no attribute 'get_text'

During handling of the above exception, another exception occurred:

Traceback (most recent call last):
  File "C:\Users\82105\AppData\Local\Programs\Python\Python39\lib\site-packages\discord\ext\commands\core.py", line 85, in wrapped
    ret = await coro(*args, **kwargs)
  File "c:\Users\82105\Desktop\Project\Discord\DiscordBot_Gwen\cogs\SearchCommand.py", line 92, in 챔피언
    winrate = soup.find("div", attrs={"class":"champion-stats-trend-rate"}).get_text()
AttributeError: 'NoneType' object has no attribute 'get_text'

The above exception was the direct cause of the following exception:

Traceback (most recent call last):
  File "c:\Users\82105\Desktop\Project\Discord\DiscordBot_Gwen\utils\logger.py", line 22, in err
    raise error
  File "C:\Users\82105\AppData\Local\Programs\Python\Python39\lib\site-packages\discord\ext\commands\bot.py", line 939, in invoke
    await ctx.command.invoke(ctx)
  File "C:\Users\82105\AppData\Local\Programs\Python\Python39\lib\site-packages\discord\ext\commands\core.py", line 863, in invoke
    await injected(*ctx.args, **ctx.kwargs)
  File "C:\Users\82105\AppData\Local\Programs\Python\Python39\lib\site-packages\discord\ext\commands\core.py", line 94, in wrapped
    raise CommandInvokeError(exc) from exc
discord.ext.commands.errors.CommandInvokeError: Command raised an exception: AttributeError: 'NoneType' object has no attribute 'get_text'



20시 26분 / [오류] Traceback (most recent call last):
  File "c:\Users\82105\Desktop\Project\Discord\DiscordBot_Gwen\cogs\SearchCommand.py", line 87, in 챔피언
    rate = soup.find_all("div", attrs={"class":"champion-stats-trend-rate"}, limit=2).get_text()
  File "C:\Users\82105\AppData\Local\Programs\Python\Python39\lib\site-packages\bs4\element.py", line 2253, in __getattr__
    raise AttributeError(
AttributeError: ResultSet object has no attribute 'get_text'. You're probably treating a list of elements like a single element. Did you call find_all() when you meant to call find()?

During handling of the above exception, another exception occurred:

Traceback (most recent call last):
  File "C:\Users\82105\AppData\Local\Programs\Python\Python39\lib\site-packages\discord\ext\commands\core.py", line 85, in wrapped
    ret = await coro(*args, **kwargs)
  File "c:\Users\82105\Desktop\Project\Discord\DiscordBot_Gwen\cogs\SearchCommand.py", line 92, in 챔피언
    rate = soup.find_all("div", attrs={"class":"champion-stats-trend-rate"}, limit=2).get_text()
  File "C:\Users\82105\AppData\Local\Programs\Python\Python39\lib\site-packages\bs4\element.py", line 2253, in __getattr__
    raise AttributeError(
AttributeError: ResultSet object has no attribute 'get_text'. You're probably treating a list of elements like a single element. Did you call find_all() when you meant to call find()?

The above exception was the direct cause of the following exception:

Traceback (most recent call last):
  File "c:\Users\82105\Desktop\Project\Discord\DiscordBot_Gwen\utils\logger.py", line 22, in err
    raise error
  File "C:\Users\82105\AppData\Local\Programs\Python\Python39\lib\site-packages\discord\ext\commands\bot.py", line 939, in invoke
    await ctx.command.invoke(ctx)
  File "C:\Users\82105\AppData\Local\Programs\Python\Python39\lib\site-packages\discord\ext\commands\core.py", line 863, in invoke
    await injected(*ctx.args, **ctx.kwargs)
  File "C:\Users\82105\AppData\Local\Programs\Python\Python39\lib\site-packages\discord\ext\commands\core.py", line 94, in wrapped
    raise CommandInvokeError(exc) from exc
discord.ext.commands.errors.CommandInvokeError: Command raised an exception: AttributeError: ResultSet object has no attribute 'get_text'. You're probably treating a list of elements like a single element. Did you call find_all() when you meant to call find()?



20시 55분 / [오류] Traceback (most recent call last):
  File "C:\Users\82105\AppData\Local\Programs\Python\Python39\lib\site-packages\discord\ext\commands\core.py", line 85, in wrapped
    ret = await coro(*args, **kwargs)
  File "c:\Users\82105\Desktop\Project\Discord\DiscordBot_Gwen\cogs\SearchCommand.py", line 97, in 챔피언
    rate_list.append(most.find('div').get('title'))
AttributeError: 'NoneType' object has no attribute 'get'

The above exception was the direct cause of the following exception:

Traceback (most recent call last):
  File "c:\Users\82105\Desktop\Project\Discord\DiscordBot_Gwen\utils\logger.py", line 22, in err
    raise error
  File "C:\Users\82105\AppData\Local\Programs\Python\Python39\lib\site-packages\discord\ext\commands\bot.py", line 939, in invoke
    await ctx.command.invoke(ctx)
  File "C:\Users\82105\AppData\Local\Programs\Python\Python39\lib\site-packages\discord\ext\commands\core.py", line 863, in invoke
    await injected(*ctx.args, **ctx.kwargs)
  File "C:\Users\82105\AppData\Local\Programs\Python\Python39\lib\site-packages\discord\ext\commands\core.py", line 94, in wrapped
    raise CommandInvokeError(exc) from exc
discord.ext.commands.errors.CommandInvokeError: Command raised an exception: AttributeError: 'NoneType' object has no attribute 'get'



22시 07분 / [오류] Traceback (most recent call last):
  File "C:\Users\82105\AppData\Local\Programs\Python\Python39\lib\site-packages\discord\ext\commands\core.py", line 85, in wrapped
    ret = await coro(*args, **kwargs)
  File "c:\Users\82105\Desktop\Project\Discord\DiscordBot_Gwen\cogs\SearchCommand.py", line 142, in 챔피언
    Background.paste(Image.open('imgs/profile.png'),(300,300))
  File "C:\Users\82105\AppData\Local\Programs\Python\Python39\lib\site-packages\PIL\Image.py", line 2968, in open
    fp = builtins.open(filename, "rb")
FileNotFoundError: [Errno 2] No such file or directory: 'imgs/profile.png'

The above exception was the direct cause of the following exception:

Traceback (most recent call last):
  File "c:\Users\82105\Desktop\Project\Discord\DiscordBot_Gwen\utils\logger.py", line 22, in err
    raise error
  File "C:\Users\82105\AppData\Local\Programs\Python\Python39\lib\site-packages\discord\ext\commands\bot.py", line 939, in invoke
    await ctx.command.invoke(ctx)
  File "C:\Users\82105\AppData\Local\Programs\Python\Python39\lib\site-packages\discord\ext\commands\core.py", line 863, in invoke
    await injected(*ctx.args, **ctx.kwargs)
  File "C:\Users\82105\AppData\Local\Programs\Python\Python39\lib\site-packages\discord\ext\commands\core.py", line 94, in wrapped
    raise CommandInvokeError(exc) from exc
discord.ext.commands.errors.CommandInvokeError: Command raised an exception: FileNotFoundError: [Errno 2] No such file or directory: 'imgs/profile.png'



22시 08분 / [오류] Traceback (most recent call last):
  File "C:\Users\82105\AppData\Local\Programs\Python\Python39\lib\site-packages\discord\ext\commands\core.py", line 85, in wrapped
    ret = await coro(*args, **kwargs)
  File "c:\Users\82105\Desktop\Project\Discord\DiscordBot_Gwen\cogs\SearchCommand.py", line 99, in 챔피언
    tier = soup.find("div", attrs={"class":"champion-stats-header-info__tier"}).get_text().strip()
AttributeError: 'NoneType' object has no attribute 'get_text'

The above exception was the direct cause of the following exception:

Traceback (most recent call last):
  File "c:\Users\82105\Desktop\Project\Discord\DiscordBot_Gwen\utils\logger.py", line 22, in err
    raise error
  File "C:\Users\82105\AppData\Local\Programs\Python\Python39\lib\site-packages\discord\ext\commands\bot.py", line 939, in invoke
    await ctx.command.invoke(ctx)
  File "C:\Users\82105\AppData\Local\Programs\Python\Python39\lib\site-packages\discord\ext\commands\core.py", line 863, in invoke
    await injected(*ctx.args, **ctx.kwargs)
  File "C:\Users\82105\AppData\Local\Programs\Python\Python39\lib\site-packages\discord\ext\commands\core.py", line 94, in wrapped
    raise CommandInvokeError(exc) from exc
discord.ext.commands.errors.CommandInvokeError: Command raised an exception: AttributeError: 'NoneType' object has no attribute 'get_text'



22시 12분 / [오류] Traceback (most recent call last):
  File "C:\Users\82105\AppData\Local\Programs\Python\Python39\lib\site-packages\discord\ext\commands\core.py", line 85, in wrapped
    ret = await coro(*args, **kwargs)
  File "c:\Users\82105\Desktop\Project\Discord\DiscordBot_Gwen\cogs\SearchCommand.py", line 123, in 챔피언
    chamPro = soup.find("div", attrs={"class":"champion-stats-header-info__image"}).find("img").get("src")
AttributeError: 'NoneType' object has no attribute 'find'

The above exception was the direct cause of the following exception:

Traceback (most recent call last):
  File "c:\Users\82105\Desktop\Project\Discord\DiscordBot_Gwen\utils\logger.py", line 22, in err
    raise error
  File "C:\Users\82105\AppData\Local\Programs\Python\Python39\lib\site-packages\discord\ext\commands\bot.py", line 939, in invoke
    await ctx.command.invoke(ctx)
  File "C:\Users\82105\AppData\Local\Programs\Python\Python39\lib\site-packages\discord\ext\commands\core.py", line 863, in invoke
    await injected(*ctx.args, **ctx.kwargs)
  File "C:\Users\82105\AppData\Local\Programs\Python\Python39\lib\site-packages\discord\ext\commands\core.py", line 94, in wrapped
    raise CommandInvokeError(exc) from exc
discord.ext.commands.errors.CommandInvokeError: Command raised an exception: AttributeError: 'NoneType' object has no attribute 'find'



22시 14분 / [오류] Traceback (most recent call last):
  File "C:\Users\82105\AppData\Local\Programs\Python\Python39\lib\site-packages\discord\ext\commands\core.py", line 85, in wrapped
    ret = await coro(*args, **kwargs)
  File "c:\Users\82105\Desktop\Project\Discord\DiscordBot_Gwen\cogs\SearchCommand.py", line 123, in 챔피언
    chamPro = soup.find("div", attrs={"class":"champion-stats-header-info__image"}).find("img").get("src")
AttributeError: 'NoneType' object has no attribute 'find'

The above exception was the direct cause of the following exception:

Traceback (most recent call last):
  File "c:\Users\82105\Desktop\Project\Discord\DiscordBot_Gwen\utils\logger.py", line 22, in err
    raise error
  File "C:\Users\82105\AppData\Local\Programs\Python\Python39\lib\site-packages\discord\ext\commands\bot.py", line 939, in invoke
    await ctx.command.invoke(ctx)
  File "C:\Users\82105\AppData\Local\Programs\Python\Python39\lib\site-packages\discord\ext\commands\core.py", line 863, in invoke
    await injected(*ctx.args, **ctx.kwargs)
  File "C:\Users\82105\AppData\Local\Programs\Python\Python39\lib\site-packages\discord\ext\commands\core.py", line 94, in wrapped
    raise CommandInvokeError(exc) from exc
discord.ext.commands.errors.CommandInvokeError: Command raised an exception: AttributeError: 'NoneType' object has no attribute 'find'



