10시 37분 / [오류] Traceback (most recent call last):
  File "C:\Users\82105\AppData\Local\Programs\Python\Python39\lib\site-packages\discord\ext\commands\core.py", line 85, in wrapped
    ret = await coro(*args, **kwargs)
  File "c:\Users\82105\Desktop\Project\Discord\DiscordBot_Gwen\cogs\SearchCommand.py", line 184, in 챔피언
    luneType = soup.find_all("div", attrs="perk-page__item perk-page__item--mark", limit=2).find("img").get("src")
  File "C:\Users\82105\AppData\Local\Programs\Python\Python39\lib\site-packages\bs4\element.py", line 2253, in __getattr__
    raise AttributeError(
AttributeError: ResultSet object has no attribute 'find'. You're probably treating a list of elements like a single element. Did you call find_all() when you meant to call find()?

The above exception was the direct cause of the following exception:

Traceback (most recent call last):
  File "c:\Users\82105\Desktop\Project\Discord\DiscordBot_Gwen\utils\logger.py", line 22, in err
    raise error
  File "C:\Users\82105\AppData\Local\Programs\Python\Python39\lib\site-packages\discord\ext\commands\bot.py", line 939, in invoke
    await ctx.command.invoke(ctx)
  File "C:\Users\82105\AppData\Local\Programs\Python\Python39\lib\site-packages\discord\ext\commands\core.py", line 863, in invoke
    await injected(*ctx.args, **ctx.kwargs)
  File "C:\Users\82105\AppData\Local\Programs\Python\Python39\lib\site-packages\discord\ext\commands\core.py", line 94, in wrapped
    raise CommandInvokeError(exc) from exc
discord.ext.commands.errors.CommandInvokeError: Command raised an exception: AttributeError: ResultSet object has no attribute 'find'. You're probably treating a list of elements like a single element. Did you call find_all() when you meant to call find()?



11시 54분 / [오류] Traceback (most recent call last):
  File "C:\Users\82105\AppData\Local\Programs\Python\Python39\lib\site-packages\discord\ext\commands\core.py", line 85, in wrapped
    ret = await coro(*args, **kwargs)
  File "c:\Users\82105\Desktop\Project\Discord\DiscordBot_Gwen\cogs\SearchCommand.py", line 232, in 패치
    await ctx.send(embed=embed)
  File "C:\Users\82105\AppData\Local\Programs\Python\Python39\lib\site-packages\discord\abc.py", line 1065, in send
    data = await state.http.send_message(channel.id, content, tts=tts, embed=embed,
  File "C:\Users\82105\AppData\Local\Programs\Python\Python39\lib\site-packages\discord\http.py", line 254, in request
    raise HTTPException(r, data)
discord.errors.HTTPException: 400 Bad Request (error code: 50035): Invalid Form Body
In embed.thumbnail.url: Scheme "http:https" is not supported. Scheme must be one of ('http', 'https').

The above exception was the direct cause of the following exception:

Traceback (most recent call last):
  File "c:\Users\82105\Desktop\Project\Discord\DiscordBot_Gwen\utils\logger.py", line 22, in err
    raise error
  File "C:\Users\82105\AppData\Local\Programs\Python\Python39\lib\site-packages\discord\ext\commands\bot.py", line 939, in invoke
    await ctx.command.invoke(ctx)
  File "C:\Users\82105\AppData\Local\Programs\Python\Python39\lib\site-packages\discord\ext\commands\core.py", line 863, in invoke
    await injected(*ctx.args, **ctx.kwargs)
  File "C:\Users\82105\AppData\Local\Programs\Python\Python39\lib\site-packages\discord\ext\commands\core.py", line 94, in wrapped
    raise CommandInvokeError(exc) from exc
discord.ext.commands.errors.CommandInvokeError: Command raised an exception: HTTPException: 400 Bad Request (error code: 50035): Invalid Form Body
In embed.thumbnail.url: Scheme "http:https" is not supported. Scheme must be one of ('http', 'https').



11시 57분 / [오류] Traceback (most recent call last):
  File "C:\Users\82105\AppData\Local\Programs\Python\Python39\lib\site-packages\discord\ext\commands\core.py", line 85, in wrapped
    ret = await coro(*args, **kwargs)
  File "c:\Users\82105\Desktop\Project\Discord\DiscordBot_Gwen\cogs\SearchCommand.py", line 227, in 패치
    logger.msg(len(patch_list))  # 메시지를 기록
  File "c:\Users\82105\Desktop\Project\Discord\DiscordBot_Gwen\utils\logger.py", line 55, in msg
    if message.content == '':
AttributeError: 'int' object has no attribute 'content'

The above exception was the direct cause of the following exception:

Traceback (most recent call last):
  File "c:\Users\82105\Desktop\Project\Discord\DiscordBot_Gwen\utils\logger.py", line 22, in err
    raise error
  File "C:\Users\82105\AppData\Local\Programs\Python\Python39\lib\site-packages\discord\ext\commands\bot.py", line 939, in invoke
    await ctx.command.invoke(ctx)
  File "C:\Users\82105\AppData\Local\Programs\Python\Python39\lib\site-packages\discord\ext\commands\core.py", line 863, in invoke
    await injected(*ctx.args, **ctx.kwargs)
  File "C:\Users\82105\AppData\Local\Programs\Python\Python39\lib\site-packages\discord\ext\commands\core.py", line 94, in wrapped
    raise CommandInvokeError(exc) from exc
discord.ext.commands.errors.CommandInvokeError: Command raised an exception: AttributeError: 'int' object has no attribute 'content'



11시 58분 / [오류] Traceback (most recent call last):
  File "C:\Users\82105\AppData\Local\Programs\Python\Python39\lib\site-packages\discord\ext\commands\core.py", line 85, in wrapped
    ret = await coro(*args, **kwargs)
  File "c:\Users\82105\Desktop\Project\Discord\DiscordBot_Gwen\cogs\SearchCommand.py", line 227, in 패치
    logger.msg(len(patch_list))  # 메시지를 기록
  File "c:\Users\82105\Desktop\Project\Discord\DiscordBot_Gwen\utils\logger.py", line 55, in msg
    if message.content == '':
AttributeError: 'int' object has no attribute 'content'

The above exception was the direct cause of the following exception:

Traceback (most recent call last):
  File "c:\Users\82105\Desktop\Project\Discord\DiscordBot_Gwen\utils\logger.py", line 22, in err
    raise error
  File "C:\Users\82105\AppData\Local\Programs\Python\Python39\lib\site-packages\discord\ext\commands\bot.py", line 939, in invoke
    await ctx.command.invoke(ctx)
  File "C:\Users\82105\AppData\Local\Programs\Python\Python39\lib\site-packages\discord\ext\commands\core.py", line 863, in invoke
    await injected(*ctx.args, **ctx.kwargs)
  File "C:\Users\82105\AppData\Local\Programs\Python\Python39\lib\site-packages\discord\ext\commands\core.py", line 94, in wrapped
    raise CommandInvokeError(exc) from exc
discord.ext.commands.errors.CommandInvokeError: Command raised an exception: AttributeError: 'int' object has no attribute 'content'



11시 58분 / [오류] Traceback (most recent call last):
  File "C:\Users\82105\AppData\Local\Programs\Python\Python39\lib\site-packages\discord\ext\commands\core.py", line 85, in wrapped
    ret = await coro(*args, **kwargs)
  File "c:\Users\82105\Desktop\Project\Discord\DiscordBot_Gwen\cogs\SearchCommand.py", line 227, in 패치
    logger.msg(len(patch_list))  # 메시지를 기록
  File "c:\Users\82105\Desktop\Project\Discord\DiscordBot_Gwen\utils\logger.py", line 55, in msg
    if message.content == '':
AttributeError: 'int' object has no attribute 'content'

The above exception was the direct cause of the following exception:

Traceback (most recent call last):
  File "c:\Users\82105\Desktop\Project\Discord\DiscordBot_Gwen\utils\logger.py", line 22, in err
    raise error
  File "C:\Users\82105\AppData\Local\Programs\Python\Python39\lib\site-packages\discord\ext\commands\bot.py", line 939, in invoke
    await ctx.command.invoke(ctx)
  File "C:\Users\82105\AppData\Local\Programs\Python\Python39\lib\site-packages\discord\ext\commands\core.py", line 863, in invoke
    await injected(*ctx.args, **ctx.kwargs)
  File "C:\Users\82105\AppData\Local\Programs\Python\Python39\lib\site-packages\discord\ext\commands\core.py", line 94, in wrapped
    raise CommandInvokeError(exc) from exc
discord.ext.commands.errors.CommandInvokeError: Command raised an exception: AttributeError: 'int' object has no attribute 'content'



11시 59분 / [오류] Traceback (most recent call last):
  File "C:\Users\82105\AppData\Local\Programs\Python\Python39\lib\site-packages\discord\ext\commands\core.py", line 85, in wrapped
    ret = await coro(*args, **kwargs)
  File "c:\Users\82105\Desktop\Project\Discord\DiscordBot_Gwen\cogs\SearchCommand.py", line 228, in 패치
    embed.add_field(name=champ_list[i], value=patch_list[i],inline = False)
IndexError: list index out of range

The above exception was the direct cause of the following exception:

Traceback (most recent call last):
  File "c:\Users\82105\Desktop\Project\Discord\DiscordBot_Gwen\utils\logger.py", line 22, in err
    raise error
  File "C:\Users\82105\AppData\Local\Programs\Python\Python39\lib\site-packages\discord\ext\commands\bot.py", line 939, in invoke
    await ctx.command.invoke(ctx)
  File "C:\Users\82105\AppData\Local\Programs\Python\Python39\lib\site-packages\discord\ext\commands\core.py", line 863, in invoke
    await injected(*ctx.args, **ctx.kwargs)
  File "C:\Users\82105\AppData\Local\Programs\Python\Python39\lib\site-packages\discord\ext\commands\core.py", line 94, in wrapped
    raise CommandInvokeError(exc) from exc
discord.ext.commands.errors.CommandInvokeError: Command raised an exception: IndexError: list index out of range



12시 05분 / [오류] Traceback (most recent call last):
  File "C:\Users\82105\AppData\Local\Programs\Python\Python39\lib\site-packages\discord\ext\commands\core.py", line 85, in wrapped
    ret = await coro(*args, **kwargs)
  File "c:\Users\82105\Desktop\Project\Discord\DiscordBot_Gwen\cogs\SearchCommand.py", line 228, in 패치
    embed.add_field(name=champ_list[i],inline = False)
IndexError: list index out of range

The above exception was the direct cause of the following exception:

Traceback (most recent call last):
  File "c:\Users\82105\Desktop\Project\Discord\DiscordBot_Gwen\utils\logger.py", line 22, in err
    raise error
  File "C:\Users\82105\AppData\Local\Programs\Python\Python39\lib\site-packages\discord\ext\commands\bot.py", line 939, in invoke
    await ctx.command.invoke(ctx)
  File "C:\Users\82105\AppData\Local\Programs\Python\Python39\lib\site-packages\discord\ext\commands\core.py", line 863, in invoke
    await injected(*ctx.args, **ctx.kwargs)
  File "C:\Users\82105\AppData\Local\Programs\Python\Python39\lib\site-packages\discord\ext\commands\core.py", line 94, in wrapped
    raise CommandInvokeError(exc) from exc
discord.ext.commands.errors.CommandInvokeError: Command raised an exception: IndexError: list index out of range



12시 06분 / [오류] Traceback (most recent call last):
  File "C:\Users\82105\AppData\Local\Programs\Python\Python39\lib\site-packages\discord\ext\commands\core.py", line 85, in wrapped
    ret = await coro(*args, **kwargs)
  File "c:\Users\82105\Desktop\Project\Discord\DiscordBot_Gwen\cogs\SearchCommand.py", line 228, in 패치
    embed.add_field(name=champ_list[i],inline = False)
IndexError: list index out of range

The above exception was the direct cause of the following exception:

Traceback (most recent call last):
  File "c:\Users\82105\Desktop\Project\Discord\DiscordBot_Gwen\utils\logger.py", line 22, in err
    raise error
  File "C:\Users\82105\AppData\Local\Programs\Python\Python39\lib\site-packages\discord\ext\commands\bot.py", line 939, in invoke
    await ctx.command.invoke(ctx)
  File "C:\Users\82105\AppData\Local\Programs\Python\Python39\lib\site-packages\discord\ext\commands\core.py", line 863, in invoke
    await injected(*ctx.args, **ctx.kwargs)
  File "C:\Users\82105\AppData\Local\Programs\Python\Python39\lib\site-packages\discord\ext\commands\core.py", line 94, in wrapped
    raise CommandInvokeError(exc) from exc
discord.ext.commands.errors.CommandInvokeError: Command raised an exception: IndexError: list index out of range



12시 06분 / [오류] Traceback (most recent call last):
  File "C:\Users\82105\AppData\Local\Programs\Python\Python39\lib\site-packages\discord\ext\commands\core.py", line 85, in wrapped
    ret = await coro(*args, **kwargs)
  File "c:\Users\82105\Desktop\Project\Discord\DiscordBot_Gwen\cogs\SearchCommand.py", line 222, in 패치
    logger.msg(len(champ_list))  # 메시지를 기록
  File "c:\Users\82105\Desktop\Project\Discord\DiscordBot_Gwen\utils\logger.py", line 55, in msg
    if message.content == '':
AttributeError: 'int' object has no attribute 'content'

The above exception was the direct cause of the following exception:

Traceback (most recent call last):
  File "c:\Users\82105\Desktop\Project\Discord\DiscordBot_Gwen\utils\logger.py", line 22, in err
    raise error
  File "C:\Users\82105\AppData\Local\Programs\Python\Python39\lib\site-packages\discord\ext\commands\bot.py", line 939, in invoke
    await ctx.command.invoke(ctx)
  File "C:\Users\82105\AppData\Local\Programs\Python\Python39\lib\site-packages\discord\ext\commands\core.py", line 863, in invoke
    await injected(*ctx.args, **ctx.kwargs)
  File "C:\Users\82105\AppData\Local\Programs\Python\Python39\lib\site-packages\discord\ext\commands\core.py", line 94, in wrapped
    raise CommandInvokeError(exc) from exc
discord.ext.commands.errors.CommandInvokeError: Command raised an exception: AttributeError: 'int' object has no attribute 'content'



12시 17분 / [오류] Traceback (most recent call last):
  File "C:\Users\82105\AppData\Local\Programs\Python\Python39\lib\site-packages\discord\ext\commands\core.py", line 85, in wrapped
    ret = await coro(*args, **kwargs)
  File "c:\Users\82105\Desktop\Project\Discord\DiscordBot_Gwen\cogs\SearchCommand.py", line 218, in 패치
    champ = soup.find("h3", attrs="champion-name").get_text()
AttributeError: 'NoneType' object has no attribute 'get_text'

The above exception was the direct cause of the following exception:

Traceback (most recent call last):
  File "c:\Users\82105\Desktop\Project\Discord\DiscordBot_Gwen\utils\logger.py", line 22, in err
    raise error
  File "C:\Users\82105\AppData\Local\Programs\Python\Python39\lib\site-packages\discord\ext\commands\bot.py", line 939, in invoke
    await ctx.command.invoke(ctx)
  File "C:\Users\82105\AppData\Local\Programs\Python\Python39\lib\site-packages\discord\ext\commands\core.py", line 863, in invoke
    await injected(*ctx.args, **ctx.kwargs)
  File "C:\Users\82105\AppData\Local\Programs\Python\Python39\lib\site-packages\discord\ext\commands\core.py", line 94, in wrapped
    raise CommandInvokeError(exc) from exc
discord.ext.commands.errors.CommandInvokeError: Command raised an exception: AttributeError: 'NoneType' object has no attribute 'get_text'



12시 18분 / [오류] Traceback (most recent call last):
  File "C:\Users\82105\AppData\Local\Programs\Python\Python39\lib\site-packages\discord\ext\commands\core.py", line 85, in wrapped
    ret = await coro(*args, **kwargs)
  File "c:\Users\82105\Desktop\Project\Discord\DiscordBot_Gwen\cogs\SearchCommand.py", line 218, in 패치
    champ = soup.find("h3", attrs="champion-name").get_text().strip()
AttributeError: 'NoneType' object has no attribute 'get_text'

The above exception was the direct cause of the following exception:

Traceback (most recent call last):
  File "c:\Users\82105\Desktop\Project\Discord\DiscordBot_Gwen\utils\logger.py", line 22, in err
    raise error
  File "C:\Users\82105\AppData\Local\Programs\Python\Python39\lib\site-packages\discord\ext\commands\bot.py", line 939, in invoke
    await ctx.command.invoke(ctx)
  File "C:\Users\82105\AppData\Local\Programs\Python\Python39\lib\site-packages\discord\ext\commands\core.py", line 863, in invoke
    await injected(*ctx.args, **ctx.kwargs)
  File "C:\Users\82105\AppData\Local\Programs\Python\Python39\lib\site-packages\discord\ext\commands\core.py", line 94, in wrapped
    raise CommandInvokeError(exc) from exc
discord.ext.commands.errors.CommandInvokeError: Command raised an exception: AttributeError: 'NoneType' object has no attribute 'get_text'



12시 18분 / [오류] Traceback (most recent call last):
  File "C:\Users\82105\AppData\Local\Programs\Python\Python39\lib\site-packages\discord\ext\commands\core.py", line 85, in wrapped
    ret = await coro(*args, **kwargs)
  File "c:\Users\82105\Desktop\Project\Discord\DiscordBot_Gwen\cogs\SearchCommand.py", line 218, in 패치
    champ = soup.find("h3", attrs="champion-name").get_text().strip()
AttributeError: 'NoneType' object has no attribute 'get_text'

The above exception was the direct cause of the following exception:

Traceback (most recent call last):
  File "c:\Users\82105\Desktop\Project\Discord\DiscordBot_Gwen\utils\logger.py", line 22, in err
    raise error
  File "C:\Users\82105\AppData\Local\Programs\Python\Python39\lib\site-packages\discord\ext\commands\bot.py", line 939, in invoke
    await ctx.command.invoke(ctx)
  File "C:\Users\82105\AppData\Local\Programs\Python\Python39\lib\site-packages\discord\ext\commands\core.py", line 863, in invoke
    await injected(*ctx.args, **ctx.kwargs)
  File "C:\Users\82105\AppData\Local\Programs\Python\Python39\lib\site-packages\discord\ext\commands\core.py", line 94, in wrapped
    raise CommandInvokeError(exc) from exc
discord.ext.commands.errors.CommandInvokeError: Command raised an exception: AttributeError: 'NoneType' object has no attribute 'get_text'



12시 28분 / [오류] Traceback (most recent call last):
  File "C:\Users\82105\AppData\Local\Programs\Python\Python39\lib\site-packages\discord\ext\commands\core.py", line 85, in wrapped
    ret = await coro(*args, **kwargs)
  File "c:\Users\82105\Desktop\Project\Discord\DiscordBot_Gwen\cogs\SearchCommand.py", line 222, in 패치
    await ctx.send(embed=embed)
  File "C:\Users\82105\AppData\Local\Programs\Python\Python39\lib\site-packages\discord\abc.py", line 1065, in send
    data = await state.http.send_message(channel.id, content, tts=tts, embed=embed,
  File "C:\Users\82105\AppData\Local\Programs\Python\Python39\lib\site-packages\discord\http.py", line 254, in request
    raise HTTPException(r, data)
discord.errors.HTTPException: 400 Bad Request (error code: 50035): Invalid Form Body
In embed.thumbnail.url: Scheme "http:https" is not supported. Scheme must be one of ('http', 'https').

The above exception was the direct cause of the following exception:

Traceback (most recent call last):
  File "c:\Users\82105\Desktop\Project\Discord\DiscordBot_Gwen\utils\logger.py", line 22, in err
    raise error
  File "C:\Users\82105\AppData\Local\Programs\Python\Python39\lib\site-packages\discord\ext\commands\bot.py", line 939, in invoke
    await ctx.command.invoke(ctx)
  File "C:\Users\82105\AppData\Local\Programs\Python\Python39\lib\site-packages\discord\ext\commands\core.py", line 863, in invoke
    await injected(*ctx.args, **ctx.kwargs)
  File "C:\Users\82105\AppData\Local\Programs\Python\Python39\lib\site-packages\discord\ext\commands\core.py", line 94, in wrapped
    raise CommandInvokeError(exc) from exc
discord.ext.commands.errors.CommandInvokeError: Command raised an exception: HTTPException: 400 Bad Request (error code: 50035): Invalid Form Body
In embed.thumbnail.url: Scheme "http:https" is not supported. Scheme must be one of ('http', 'https').



12시 33분 / [오류] Traceback (most recent call last):
  File "C:\Users\82105\AppData\Local\Programs\Python\Python39\lib\site-packages\discord\ext\commands\core.py", line 85, in wrapped
    ret = await coro(*args, **kwargs)
  File "c:\Users\82105\Desktop\Project\Discord\DiscordBot_Gwen\cogs\SearchCommand.py", line 219, in 패치
    embed.add_field(name="http:" + patchLink, value="League of Legend",url = "http:" + patchLink ,inline = False)
TypeError: add_field() got an unexpected keyword argument 'url'

The above exception was the direct cause of the following exception:

Traceback (most recent call last):
  File "c:\Users\82105\Desktop\Project\Discord\DiscordBot_Gwen\utils\logger.py", line 22, in err
    raise error
  File "C:\Users\82105\AppData\Local\Programs\Python\Python39\lib\site-packages\discord\ext\commands\bot.py", line 939, in invoke
    await ctx.command.invoke(ctx)
  File "C:\Users\82105\AppData\Local\Programs\Python\Python39\lib\site-packages\discord\ext\commands\core.py", line 863, in invoke
    await injected(*ctx.args, **ctx.kwargs)
  File "C:\Users\82105\AppData\Local\Programs\Python\Python39\lib\site-packages\discord\ext\commands\core.py", line 94, in wrapped
    raise CommandInvokeError(exc) from exc
discord.ext.commands.errors.CommandInvokeError: Command raised an exception: TypeError: add_field() got an unexpected keyword argument 'url'



12시 53분 / [오류] Traceback (most recent call last):
  File "C:\Users\82105\AppData\Local\Programs\Python\Python39\lib\site-packages\discord\ext\commands\core.py", line 85, in wrapped
    ret = await coro(*args, **kwargs)
  File "c:\Users\82105\Desktop\Project\Discord\DiscordBot_Gwen\cogs\SearchCommand.py", line 228, in 챔피언리스트
    embed.add_field(name=i,inline = False)
TypeError: add_field() missing 1 required keyword-only argument: 'value'

The above exception was the direct cause of the following exception:

Traceback (most recent call last):
  File "c:\Users\82105\Desktop\Project\Discord\DiscordBot_Gwen\utils\logger.py", line 22, in err
    raise error
  File "C:\Users\82105\AppData\Local\Programs\Python\Python39\lib\site-packages\discord\ext\commands\bot.py", line 939, in invoke
    await ctx.command.invoke(ctx)
  File "C:\Users\82105\AppData\Local\Programs\Python\Python39\lib\site-packages\discord\ext\commands\core.py", line 863, in invoke
    await injected(*ctx.args, **ctx.kwargs)
  File "C:\Users\82105\AppData\Local\Programs\Python\Python39\lib\site-packages\discord\ext\commands\core.py", line 94, in wrapped
    raise CommandInvokeError(exc) from exc
discord.ext.commands.errors.CommandInvokeError: Command raised an exception: TypeError: add_field() missing 1 required keyword-only argument: 'value'



12시 54분 / [오류] Traceback (most recent call last):
  File "C:\Users\82105\AppData\Local\Programs\Python\Python39\lib\site-packages\discord\ext\commands\core.py", line 85, in wrapped
    ret = await coro(*args, **kwargs)
  File "c:\Users\82105\Desktop\Project\Discord\DiscordBot_Gwen\cogs\SearchCommand.py", line 228, in 챔피언리스트
    embed.add_field(name=key,inline = False)
TypeError: add_field() missing 1 required keyword-only argument: 'value'

The above exception was the direct cause of the following exception:

Traceback (most recent call last):
  File "c:\Users\82105\Desktop\Project\Discord\DiscordBot_Gwen\utils\logger.py", line 22, in err
    raise error
  File "C:\Users\82105\AppData\Local\Programs\Python\Python39\lib\site-packages\discord\ext\commands\bot.py", line 939, in invoke
    await ctx.command.invoke(ctx)
  File "C:\Users\82105\AppData\Local\Programs\Python\Python39\lib\site-packages\discord\ext\commands\core.py", line 863, in invoke
    await injected(*ctx.args, **ctx.kwargs)
  File "C:\Users\82105\AppData\Local\Programs\Python\Python39\lib\site-packages\discord\ext\commands\core.py", line 94, in wrapped
    raise CommandInvokeError(exc) from exc
discord.ext.commands.errors.CommandInvokeError: Command raised an exception: TypeError: add_field() missing 1 required keyword-only argument: 'value'



12시 55분 / [오류] Traceback (most recent call last):
  File "C:\Users\82105\AppData\Local\Programs\Python\Python39\lib\site-packages\discord\ext\commands\core.py", line 85, in wrapped
    ret = await coro(*args, **kwargs)
  File "c:\Users\82105\Desktop\Project\Discord\DiscordBot_Gwen\cogs\SearchCommand.py", line 229, in 챔피언리스트
    embed.add_field(name=key,inline = True)
TypeError: add_field() missing 1 required keyword-only argument: 'value'

The above exception was the direct cause of the following exception:

Traceback (most recent call last):
  File "c:\Users\82105\Desktop\Project\Discord\DiscordBot_Gwen\utils\logger.py", line 22, in err
    raise error
  File "C:\Users\82105\AppData\Local\Programs\Python\Python39\lib\site-packages\discord\ext\commands\bot.py", line 939, in invoke
    await ctx.command.invoke(ctx)
  File "C:\Users\82105\AppData\Local\Programs\Python\Python39\lib\site-packages\discord\ext\commands\core.py", line 863, in invoke
    await injected(*ctx.args, **ctx.kwargs)
  File "C:\Users\82105\AppData\Local\Programs\Python\Python39\lib\site-packages\discord\ext\commands\core.py", line 94, in wrapped
    raise CommandInvokeError(exc) from exc
discord.ext.commands.errors.CommandInvokeError: Command raised an exception: TypeError: add_field() missing 1 required keyword-only argument: 'value'



17시 42분 / [오류] Traceback (most recent call last):
  File "C:\Users\82105\AppData\Local\Programs\Python\Python39\lib\site-packages\discord\ext\commands\core.py", line 85, in wrapped
    ret = await coro(*args, **kwargs)
  File "c:\Users\82105\Desktop\Project\Discord\DiscordBot_Gwen\cogs\SearchCommand.py", line 138, in 챔피언
    counter_list.append(most.find('img'.get('src')))
AttributeError: 'str' object has no attribute 'get'

The above exception was the direct cause of the following exception:

Traceback (most recent call last):
  File "c:\Users\82105\Desktop\Project\Discord\DiscordBot_Gwen\utils\logger.py", line 22, in err
    raise error
  File "C:\Users\82105\AppData\Local\Programs\Python\Python39\lib\site-packages\discord\ext\commands\bot.py", line 939, in invoke
    await ctx.command.invoke(ctx)
  File "C:\Users\82105\AppData\Local\Programs\Python\Python39\lib\site-packages\discord\ext\commands\core.py", line 863, in invoke
    await injected(*ctx.args, **ctx.kwargs)
  File "C:\Users\82105\AppData\Local\Programs\Python\Python39\lib\site-packages\discord\ext\commands\core.py", line 94, in wrapped
    raise CommandInvokeError(exc) from exc
discord.ext.commands.errors.CommandInvokeError: Command raised an exception: AttributeError: 'str' object has no attribute 'get'



17시 49분 / [오류] Traceback (most recent call last):
  File "C:\Users\82105\AppData\Local\Programs\Python\Python39\lib\site-packages\discord\ext\commands\core.py", line 85, in wrapped
    ret = await coro(*args, **kwargs)
  File "c:\Users\82105\Desktop\Project\Discord\DiscordBot_Gwen\cogs\SearchCommand.py", line 123, in 챔피언
    chamPro = soup.find("div", attrs={"class":"champion-stats-header-info__image"}).find("img").get("src")
AttributeError: 'NoneType' object has no attribute 'find'

The above exception was the direct cause of the following exception:

Traceback (most recent call last):
  File "c:\Users\82105\Desktop\Project\Discord\DiscordBot_Gwen\utils\logger.py", line 22, in err
    raise error
  File "C:\Users\82105\AppData\Local\Programs\Python\Python39\lib\site-packages\discord\ext\commands\bot.py", line 939, in invoke
    await ctx.command.invoke(ctx)
  File "C:\Users\82105\AppData\Local\Programs\Python\Python39\lib\site-packages\discord\ext\commands\core.py", line 863, in invoke
    await injected(*ctx.args, **ctx.kwargs)
  File "C:\Users\82105\AppData\Local\Programs\Python\Python39\lib\site-packages\discord\ext\commands\core.py", line 94, in wrapped
    raise CommandInvokeError(exc) from exc
discord.ext.commands.errors.CommandInvokeError: Command raised an exception: AttributeError: 'NoneType' object has no attribute 'find'



18시 14분 / [오류] Traceback (most recent call last):
  File "C:\Users\82105\AppData\Local\Programs\Python\Python39\lib\site-packages\discord\ext\commands\core.py", line 85, in wrapped
    ret = await coro(*args, **kwargs)
  File "c:\Users\82105\Desktop\Project\Discord\DiscordBot_Gwen\cogs\SearchCommand.py", line 250, in PS
    res = requests.get(url,headers=headers).text
  File "C:\Users\82105\AppData\Local\Programs\Python\Python39\lib\site-packages\requests\api.py", line 75, in get
    return request('get', url, params=params, **kwargs)
  File "C:\Users\82105\AppData\Local\Programs\Python\Python39\lib\site-packages\requests\api.py", line 61, in request
    return session.request(method=method, url=url, **kwargs)
  File "C:\Users\82105\AppData\Local\Programs\Python\Python39\lib\site-packages\requests\sessions.py", line 542, in request
    resp = self.send(prep, **send_kwargs)
  File "C:\Users\82105\AppData\Local\Programs\Python\Python39\lib\site-packages\requests\sessions.py", line 655, in send
    r = adapter.send(request, **kwargs)
  File "C:\Users\82105\AppData\Local\Programs\Python\Python39\lib\site-packages\requests\adapters.py", line 439, in send
    resp = conn.urlopen(
  File "C:\Users\82105\AppData\Local\Programs\Python\Python39\lib\site-packages\urllib3\connectionpool.py", line 699, in urlopen
    httplib_response = self._make_request(
  File "C:\Users\82105\AppData\Local\Programs\Python\Python39\lib\site-packages\urllib3\connectionpool.py", line 394, in _make_request
    conn.request(method, url, **httplib_request_kw)
  File "C:\Users\82105\AppData\Local\Programs\Python\Python39\lib\site-packages\urllib3\connection.py", line 234, in request
    super(HTTPConnection, self).request(method, url, body=body, headers=headers)
  File "C:\Users\82105\AppData\Local\Programs\Python\Python39\lib\http\client.py", line 1279, in request
    self._send_request(method, url, body, headers, encode_chunked)
  File "C:\Users\82105\AppData\Local\Programs\Python\Python39\lib\http\client.py", line 1320, in _send_request
    self.putheader(hdr, value)
  File "C:\Users\82105\AppData\Local\Programs\Python\Python39\lib\site-packages\urllib3\connection.py", line 219, in putheader
    _HTTPConnection.putheader(self, header, *values)
  File "C:\Users\82105\AppData\Local\Programs\Python\Python39\lib\http\client.py", line 1252, in putheader
    values[i] = one_value.encode('latin-1')
UnicodeEncodeError: 'latin-1' codec can't encode characters in position 0-3: ordinal not in range(256)

The above exception was the direct cause of the following exception:

Traceback (most recent call last):
  File "c:\Users\82105\Desktop\Project\Discord\DiscordBot_Gwen\utils\logger.py", line 22, in err
    raise error
  File "C:\Users\82105\AppData\Local\Programs\Python\Python39\lib\site-packages\discord\ext\commands\bot.py", line 939, in invoke
    await ctx.command.invoke(ctx)
  File "C:\Users\82105\AppData\Local\Programs\Python\Python39\lib\site-packages\discord\ext\commands\core.py", line 863, in invoke
    await injected(*ctx.args, **ctx.kwargs)
  File "C:\Users\82105\AppData\Local\Programs\Python\Python39\lib\site-packages\discord\ext\commands\core.py", line 94, in wrapped
    raise CommandInvokeError(exc) from exc
discord.ext.commands.errors.CommandInvokeError: Command raised an exception: UnicodeEncodeError: 'latin-1' codec can't encode characters in position 0-3: ordinal not in range(256)



18시 17분 / [오류] Traceback (most recent call last):
  File "C:\Users\82105\AppData\Local\Programs\Python\Python39\lib\site-packages\discord\ext\commands\core.py", line 85, in wrapped
    ret = await coro(*args, **kwargs)
  File "c:\Users\82105\Desktop\Project\Discord\DiscordBot_Gwen\cogs\SearchCommand.py", line 253, in PS
    patch = soup.find("div", attrs={"class":"simplebar-content", "sytle":"padding: 0px;"}).get_text()
AttributeError: 'NoneType' object has no attribute 'get_text'

The above exception was the direct cause of the following exception:

Traceback (most recent call last):
  File "c:\Users\82105\Desktop\Project\Discord\DiscordBot_Gwen\utils\logger.py", line 22, in err
    raise error
  File "C:\Users\82105\AppData\Local\Programs\Python\Python39\lib\site-packages\discord\ext\commands\bot.py", line 939, in invoke
    await ctx.command.invoke(ctx)
  File "C:\Users\82105\AppData\Local\Programs\Python\Python39\lib\site-packages\discord\ext\commands\core.py", line 863, in invoke
    await injected(*ctx.args, **ctx.kwargs)
  File "C:\Users\82105\AppData\Local\Programs\Python\Python39\lib\site-packages\discord\ext\commands\core.py", line 94, in wrapped
    raise CommandInvokeError(exc) from exc
discord.ext.commands.errors.CommandInvokeError: Command raised an exception: AttributeError: 'NoneType' object has no attribute 'get_text'



18시 18분 / [오류] Traceback (most recent call last):
  File "C:\Users\82105\AppData\Local\Programs\Python\Python39\lib\site-packages\discord\ext\commands\core.py", line 85, in wrapped
    ret = await coro(*args, **kwargs)
  File "c:\Users\82105\Desktop\Project\Discord\DiscordBot_Gwen\cogs\SearchCommand.py", line 253, in PS
    patch = soup.find("div", attrs={"class":"simplebar-content"}).get_text()
AttributeError: 'NoneType' object has no attribute 'get_text'

The above exception was the direct cause of the following exception:

Traceback (most recent call last):
  File "c:\Users\82105\Desktop\Project\Discord\DiscordBot_Gwen\utils\logger.py", line 22, in err
    raise error
  File "C:\Users\82105\AppData\Local\Programs\Python\Python39\lib\site-packages\discord\ext\commands\bot.py", line 939, in invoke
    await ctx.command.invoke(ctx)
  File "C:\Users\82105\AppData\Local\Programs\Python\Python39\lib\site-packages\discord\ext\commands\core.py", line 863, in invoke
    await injected(*ctx.args, **ctx.kwargs)
  File "C:\Users\82105\AppData\Local\Programs\Python\Python39\lib\site-packages\discord\ext\commands\core.py", line 94, in wrapped
    raise CommandInvokeError(exc) from exc
discord.ext.commands.errors.CommandInvokeError: Command raised an exception: AttributeError: 'NoneType' object has no attribute 'get_text'



18시 20분 / [오류] Traceback (most recent call last):
  File "C:\Users\82105\AppData\Local\Programs\Python\Python39\lib\site-packages\discord\ext\commands\core.py", line 85, in wrapped
    ret = await coro(*args, **kwargs)
  File "c:\Users\82105\Desktop\Project\Discord\DiscordBot_Gwen\cogs\SearchCommand.py", line 253, in PS
    patch = soup.find("div", attrs={"class":"simplebar-content"}).get_text()
AttributeError: 'NoneType' object has no attribute 'get_text'

The above exception was the direct cause of the following exception:

Traceback (most recent call last):
  File "c:\Users\82105\Desktop\Project\Discord\DiscordBot_Gwen\utils\logger.py", line 22, in err
    raise error
  File "C:\Users\82105\AppData\Local\Programs\Python\Python39\lib\site-packages\discord\ext\commands\bot.py", line 939, in invoke
    await ctx.command.invoke(ctx)
  File "C:\Users\82105\AppData\Local\Programs\Python\Python39\lib\site-packages\discord\ext\commands\core.py", line 863, in invoke
    await injected(*ctx.args, **ctx.kwargs)
  File "C:\Users\82105\AppData\Local\Programs\Python\Python39\lib\site-packages\discord\ext\commands\core.py", line 94, in wrapped
    raise CommandInvokeError(exc) from exc
discord.ext.commands.errors.CommandInvokeError: Command raised an exception: AttributeError: 'NoneType' object has no attribute 'get_text'



18시 21분 / [오류] Traceback (most recent call last):
  File "C:\Users\82105\AppData\Local\Programs\Python\Python39\lib\site-packages\discord\ext\commands\core.py", line 85, in wrapped
    ret = await coro(*args, **kwargs)
  File "c:\Users\82105\Desktop\Project\Discord\DiscordBot_Gwen\cogs\SearchCommand.py", line 253, in PS
    patch = soup.find("div", attrs={"class":"simplebar-content"}).get_text()
AttributeError: 'NoneType' object has no attribute 'get_text'

The above exception was the direct cause of the following exception:

Traceback (most recent call last):
  File "c:\Users\82105\Desktop\Project\Discord\DiscordBot_Gwen\utils\logger.py", line 22, in err
    raise error
  File "C:\Users\82105\AppData\Local\Programs\Python\Python39\lib\site-packages\discord\ext\commands\bot.py", line 939, in invoke
    await ctx.command.invoke(ctx)
  File "C:\Users\82105\AppData\Local\Programs\Python\Python39\lib\site-packages\discord\ext\commands\core.py", line 863, in invoke
    await injected(*ctx.args, **ctx.kwargs)
  File "C:\Users\82105\AppData\Local\Programs\Python\Python39\lib\site-packages\discord\ext\commands\core.py", line 94, in wrapped
    raise CommandInvokeError(exc) from exc
discord.ext.commands.errors.CommandInvokeError: Command raised an exception: AttributeError: 'NoneType' object has no attribute 'get_text'



18시 23분 / [오류] Traceback (most recent call last):
  File "C:\Users\82105\AppData\Local\Programs\Python\Python39\lib\site-packages\discord\ext\commands\core.py", line 85, in wrapped
    ret = await coro(*args, **kwargs)
  File "c:\Users\82105\Desktop\Project\Discord\DiscordBot_Gwen\cogs\SearchCommand.py", line 251, in PS
    res = urllib.request.Request(url=url, headers=head).text
AttributeError: 'Request' object has no attribute 'text'

The above exception was the direct cause of the following exception:

Traceback (most recent call last):
  File "c:\Users\82105\Desktop\Project\Discord\DiscordBot_Gwen\utils\logger.py", line 22, in err
    raise error
  File "C:\Users\82105\AppData\Local\Programs\Python\Python39\lib\site-packages\discord\ext\commands\bot.py", line 939, in invoke
    await ctx.command.invoke(ctx)
  File "C:\Users\82105\AppData\Local\Programs\Python\Python39\lib\site-packages\discord\ext\commands\core.py", line 863, in invoke
    await injected(*ctx.args, **ctx.kwargs)
  File "C:\Users\82105\AppData\Local\Programs\Python\Python39\lib\site-packages\discord\ext\commands\core.py", line 94, in wrapped
    raise CommandInvokeError(exc) from exc
discord.ext.commands.errors.CommandInvokeError: Command raised an exception: AttributeError: 'Request' object has no attribute 'text'



18시 25분 / [오류] Traceback (most recent call last):
  File "C:\Users\82105\AppData\Local\Programs\Python\Python39\lib\site-packages\discord\ext\commands\core.py", line 85, in wrapped
    ret = await coro(*args, **kwargs)
  File "c:\Users\82105\Desktop\Project\Discord\DiscordBot_Gwen\cogs\SearchCommand.py", line 251, in PS
    res = urllib.request.Request(url=url, headers=head).text
AttributeError: 'Request' object has no attribute 'text'

The above exception was the direct cause of the following exception:

Traceback (most recent call last):
  File "c:\Users\82105\Desktop\Project\Discord\DiscordBot_Gwen\utils\logger.py", line 22, in err
    raise error
  File "C:\Users\82105\AppData\Local\Programs\Python\Python39\lib\site-packages\discord\ext\commands\bot.py", line 939, in invoke
    await ctx.command.invoke(ctx)
  File "C:\Users\82105\AppData\Local\Programs\Python\Python39\lib\site-packages\discord\ext\commands\core.py", line 863, in invoke
    await injected(*ctx.args, **ctx.kwargs)
  File "C:\Users\82105\AppData\Local\Programs\Python\Python39\lib\site-packages\discord\ext\commands\core.py", line 94, in wrapped
    raise CommandInvokeError(exc) from exc
discord.ext.commands.errors.CommandInvokeError: Command raised an exception: AttributeError: 'Request' object has no attribute 'text'



18시 26분 / [오류] Traceback (most recent call last):
  File "C:\Users\82105\AppData\Local\Programs\Python\Python39\lib\site-packages\discord\ext\commands\core.py", line 85, in wrapped
    ret = await coro(*args, **kwargs)
  File "c:\Users\82105\Desktop\Project\Discord\DiscordBot_Gwen\cogs\SearchCommand.py", line 253, in PS
    soup = BeautifulSoup(res, "html.parser")
  File "C:\Users\82105\AppData\Local\Programs\Python\Python39\lib\site-packages\bs4\__init__.py", line 312, in __init__
    elif len(markup) <= 256 and (
TypeError: object of type 'Request' has no len()

The above exception was the direct cause of the following exception:

Traceback (most recent call last):
  File "c:\Users\82105\Desktop\Project\Discord\DiscordBot_Gwen\utils\logger.py", line 22, in err
    raise error
  File "C:\Users\82105\AppData\Local\Programs\Python\Python39\lib\site-packages\discord\ext\commands\bot.py", line 939, in invoke
    await ctx.command.invoke(ctx)
  File "C:\Users\82105\AppData\Local\Programs\Python\Python39\lib\site-packages\discord\ext\commands\core.py", line 863, in invoke
    await injected(*ctx.args, **ctx.kwargs)
  File "C:\Users\82105\AppData\Local\Programs\Python\Python39\lib\site-packages\discord\ext\commands\core.py", line 94, in wrapped
    raise CommandInvokeError(exc) from exc
discord.ext.commands.errors.CommandInvokeError: Command raised an exception: TypeError: object of type 'Request' has no len()



18시 26분 / [오류] Traceback (most recent call last):
  File "C:\Users\82105\AppData\Local\Programs\Python\Python39\lib\site-packages\discord\ext\commands\core.py", line 85, in wrapped
    ret = await coro(*args, **kwargs)
  File "c:\Users\82105\Desktop\Project\Discord\DiscordBot_Gwen\cogs\SearchCommand.py", line 253, in PS
    soup = BeautifulSoup(res, "html.parser")
  File "C:\Users\82105\AppData\Local\Programs\Python\Python39\lib\site-packages\bs4\__init__.py", line 312, in __init__
    elif len(markup) <= 256 and (
TypeError: object of type 'Request' has no len()

The above exception was the direct cause of the following exception:

Traceback (most recent call last):
  File "c:\Users\82105\Desktop\Project\Discord\DiscordBot_Gwen\utils\logger.py", line 22, in err
    raise error
  File "C:\Users\82105\AppData\Local\Programs\Python\Python39\lib\site-packages\discord\ext\commands\bot.py", line 939, in invoke
    await ctx.command.invoke(ctx)
  File "C:\Users\82105\AppData\Local\Programs\Python\Python39\lib\site-packages\discord\ext\commands\core.py", line 863, in invoke
    await injected(*ctx.args, **ctx.kwargs)
  File "C:\Users\82105\AppData\Local\Programs\Python\Python39\lib\site-packages\discord\ext\commands\core.py", line 94, in wrapped
    raise CommandInvokeError(exc) from exc
discord.ext.commands.errors.CommandInvokeError: Command raised an exception: TypeError: object of type 'Request' has no len()



18시 27분 / [오류] Traceback (most recent call last):
  File "C:\Users\82105\AppData\Local\Programs\Python\Python39\lib\site-packages\discord\ext\commands\core.py", line 85, in wrapped
    ret = await coro(*args, **kwargs)
  File "c:\Users\82105\Desktop\Project\Discord\DiscordBot_Gwen\cogs\SearchCommand.py", line 257, in PS
    patch = soup.find("div", attrs={"class":"simplebar-content"}).get_text()
AttributeError: 'NoneType' object has no attribute 'get_text'

The above exception was the direct cause of the following exception:

Traceback (most recent call last):
  File "c:\Users\82105\Desktop\Project\Discord\DiscordBot_Gwen\utils\logger.py", line 22, in err
    raise error
  File "C:\Users\82105\AppData\Local\Programs\Python\Python39\lib\site-packages\discord\ext\commands\bot.py", line 939, in invoke
    await ctx.command.invoke(ctx)
  File "C:\Users\82105\AppData\Local\Programs\Python\Python39\lib\site-packages\discord\ext\commands\core.py", line 863, in invoke
    await injected(*ctx.args, **ctx.kwargs)
  File "C:\Users\82105\AppData\Local\Programs\Python\Python39\lib\site-packages\discord\ext\commands\core.py", line 94, in wrapped
    raise CommandInvokeError(exc) from exc
discord.ext.commands.errors.CommandInvokeError: Command raised an exception: AttributeError: 'NoneType' object has no attribute 'get_text'



18시 34분 / [오류] Traceback (most recent call last):
  File "C:\Users\82105\AppData\Local\Programs\Python\Python39\lib\site-packages\discord\ext\commands\core.py", line 85, in wrapped
    ret = await coro(*args, **kwargs)
  File "c:\Users\82105\Desktop\Project\Discord\DiscordBot_Gwen\cogs\SearchCommand.py", line 260, in PS
    patch = soup.find("div", attrs={"class":"simplebar-content"}).get_text()
AttributeError: 'NoneType' object has no attribute 'get_text'

The above exception was the direct cause of the following exception:

Traceback (most recent call last):
  File "c:\Users\82105\Desktop\Project\Discord\DiscordBot_Gwen\utils\logger.py", line 22, in err
    raise error
  File "C:\Users\82105\AppData\Local\Programs\Python\Python39\lib\site-packages\discord\ext\commands\bot.py", line 939, in invoke
    await ctx.command.invoke(ctx)
  File "C:\Users\82105\AppData\Local\Programs\Python\Python39\lib\site-packages\discord\ext\commands\core.py", line 863, in invoke
    await injected(*ctx.args, **ctx.kwargs)
  File "C:\Users\82105\AppData\Local\Programs\Python\Python39\lib\site-packages\discord\ext\commands\core.py", line 94, in wrapped
    raise CommandInvokeError(exc) from exc
discord.ext.commands.errors.CommandInvokeError: Command raised an exception: AttributeError: 'NoneType' object has no attribute 'get_text'



18시 34분 / [오류] Traceback (most recent call last):
  File "C:\Users\82105\AppData\Local\Programs\Python\Python39\lib\site-packages\discord\ext\commands\core.py", line 85, in wrapped
    ret = await coro(*args, **kwargs)
  File "c:\Users\82105\Desktop\Project\Discord\DiscordBot_Gwen\cogs\SearchCommand.py", line 261, in PS
    await ctx.send(soup.get_text())
  File "C:\Users\82105\AppData\Local\Programs\Python\Python39\lib\site-packages\discord\abc.py", line 1065, in send
    data = await state.http.send_message(channel.id, content, tts=tts, embed=embed,
  File "C:\Users\82105\AppData\Local\Programs\Python\Python39\lib\site-packages\discord\http.py", line 254, in request
    raise HTTPException(r, data)
discord.errors.HTTPException: 400 Bad Request (error code: 50035): Invalid Form Body
In content: Must be 4000 or fewer in length.

The above exception was the direct cause of the following exception:

Traceback (most recent call last):
  File "c:\Users\82105\Desktop\Project\Discord\DiscordBot_Gwen\utils\logger.py", line 22, in err
    raise error
  File "C:\Users\82105\AppData\Local\Programs\Python\Python39\lib\site-packages\discord\ext\commands\bot.py", line 939, in invoke
    await ctx.command.invoke(ctx)
  File "C:\Users\82105\AppData\Local\Programs\Python\Python39\lib\site-packages\discord\ext\commands\core.py", line 863, in invoke
    await injected(*ctx.args, **ctx.kwargs)
  File "C:\Users\82105\AppData\Local\Programs\Python\Python39\lib\site-packages\discord\ext\commands\core.py", line 94, in wrapped
    raise CommandInvokeError(exc) from exc
discord.ext.commands.errors.CommandInvokeError: Command raised an exception: HTTPException: 400 Bad Request (error code: 50035): Invalid Form Body
In content: Must be 4000 or fewer in length.



18시 35분 / [오류] Traceback (most recent call last):
  File "C:\Users\82105\AppData\Local\Programs\Python\Python39\lib\site-packages\discord\ext\commands\core.py", line 85, in wrapped
    ret = await coro(*args, **kwargs)
  File "c:\Users\82105\Desktop\Project\Discord\DiscordBot_Gwen\cogs\SearchCommand.py", line 261, in PS
    #await ctx.send(soup.get_text())
  File "C:\Users\82105\AppData\Local\Programs\Python\Python39\lib\site-packages\discord\abc.py", line 1065, in send
    data = await state.http.send_message(channel.id, content, tts=tts, embed=embed,
  File "C:\Users\82105\AppData\Local\Programs\Python\Python39\lib\site-packages\discord\http.py", line 254, in request
    raise HTTPException(r, data)
discord.errors.HTTPException: 400 Bad Request (error code: 50035): Invalid Form Body
In content: Must be 4000 or fewer in length.

The above exception was the direct cause of the following exception:

Traceback (most recent call last):
  File "c:\Users\82105\Desktop\Project\Discord\DiscordBot_Gwen\utils\logger.py", line 22, in err
    raise error
  File "C:\Users\82105\AppData\Local\Programs\Python\Python39\lib\site-packages\discord\ext\commands\bot.py", line 939, in invoke
    await ctx.command.invoke(ctx)
  File "C:\Users\82105\AppData\Local\Programs\Python\Python39\lib\site-packages\discord\ext\commands\core.py", line 863, in invoke
    await injected(*ctx.args, **ctx.kwargs)
  File "C:\Users\82105\AppData\Local\Programs\Python\Python39\lib\site-packages\discord\ext\commands\core.py", line 94, in wrapped
    raise CommandInvokeError(exc) from exc
discord.ext.commands.errors.CommandInvokeError: Command raised an exception: HTTPException: 400 Bad Request (error code: 50035): Invalid Form Body
In content: Must be 4000 or fewer in length.



18시 37분 / [오류] Traceback (most recent call last):
  File "C:\Users\82105\AppData\Local\Programs\Python\Python39\lib\site-packages\discord\ext\commands\core.py", line 85, in wrapped
    ret = await coro(*args, **kwargs)
  File "c:\Users\82105\Desktop\Project\Discord\DiscordBot_Gwen\cogs\SearchCommand.py", line 257, in PS
    logger.info()
TypeError: info() missing 1 required positional argument: 'msg'

The above exception was the direct cause of the following exception:

Traceback (most recent call last):
  File "c:\Users\82105\Desktop\Project\Discord\DiscordBot_Gwen\utils\logger.py", line 22, in err
    raise error
  File "C:\Users\82105\AppData\Local\Programs\Python\Python39\lib\site-packages\discord\ext\commands\bot.py", line 939, in invoke
    await ctx.command.invoke(ctx)
  File "C:\Users\82105\AppData\Local\Programs\Python\Python39\lib\site-packages\discord\ext\commands\core.py", line 863, in invoke
    await injected(*ctx.args, **ctx.kwargs)
  File "C:\Users\82105\AppData\Local\Programs\Python\Python39\lib\site-packages\discord\ext\commands\core.py", line 94, in wrapped
    raise CommandInvokeError(exc) from exc
discord.ext.commands.errors.CommandInvokeError: Command raised an exception: TypeError: info() missing 1 required positional argument: 'msg'



18시 37분 / [오류] Traceback (most recent call last):
  File "C:\Users\82105\AppData\Local\Programs\Python\Python39\lib\site-packages\discord\ext\commands\core.py", line 85, in wrapped
    ret = await coro(*args, **kwargs)
  File "c:\Users\82105\Desktop\Project\Discord\DiscordBot_Gwen\cogs\SearchCommand.py", line 258, in PS
    patch = soup.find("div", attrs={"class":"simplebar-content-wrapper"}).get_text()
AttributeError: 'NoneType' object has no attribute 'get_text'

The above exception was the direct cause of the following exception:

Traceback (most recent call last):
  File "c:\Users\82105\Desktop\Project\Discord\DiscordBot_Gwen\utils\logger.py", line 22, in err
    raise error
  File "C:\Users\82105\AppData\Local\Programs\Python\Python39\lib\site-packages\discord\ext\commands\bot.py", line 939, in invoke
    await ctx.command.invoke(ctx)
  File "C:\Users\82105\AppData\Local\Programs\Python\Python39\lib\site-packages\discord\ext\commands\core.py", line 863, in invoke
    await injected(*ctx.args, **ctx.kwargs)
  File "C:\Users\82105\AppData\Local\Programs\Python\Python39\lib\site-packages\discord\ext\commands\core.py", line 94, in wrapped
    raise CommandInvokeError(exc) from exc
discord.ext.commands.errors.CommandInvokeError: Command raised an exception: AttributeError: 'NoneType' object has no attribute 'get_text'



18시 38분 / [오류] Traceback (most recent call last):
  File "C:\Users\82105\AppData\Local\Programs\Python\Python39\lib\site-packages\discord\ext\commands\core.py", line 85, in wrapped
    ret = await coro(*args, **kwargs)
  File "c:\Users\82105\Desktop\Project\Discord\DiscordBot_Gwen\cogs\SearchCommand.py", line 258, in PS
    patch = soup.find("div", attrs={"class":"swiper-slide champ-slide"}).get_text()
AttributeError: 'NoneType' object has no attribute 'get_text'

The above exception was the direct cause of the following exception:

Traceback (most recent call last):
  File "c:\Users\82105\Desktop\Project\Discord\DiscordBot_Gwen\utils\logger.py", line 22, in err
    raise error
  File "C:\Users\82105\AppData\Local\Programs\Python\Python39\lib\site-packages\discord\ext\commands\bot.py", line 939, in invoke
    await ctx.command.invoke(ctx)
  File "C:\Users\82105\AppData\Local\Programs\Python\Python39\lib\site-packages\discord\ext\commands\core.py", line 863, in invoke
    await injected(*ctx.args, **ctx.kwargs)
  File "C:\Users\82105\AppData\Local\Programs\Python\Python39\lib\site-packages\discord\ext\commands\core.py", line 94, in wrapped
    raise CommandInvokeError(exc) from exc
discord.ext.commands.errors.CommandInvokeError: Command raised an exception: AttributeError: 'NoneType' object has no attribute 'get_text'



18시 40분 / [오류] Traceback (most recent call last):
  File "C:\Users\82105\AppData\Local\Programs\Python\Python39\lib\site-packages\discord\ext\commands\core.py", line 85, in wrapped
    ret = await coro(*args, **kwargs)
  File "c:\Users\82105\Desktop\Project\Discord\DiscordBot_Gwen\cogs\SearchCommand.py", line 259, in PS
    await ctx.send(patch)
  File "C:\Users\82105\AppData\Local\Programs\Python\Python39\lib\site-packages\discord\abc.py", line 1065, in send
    data = await state.http.send_message(channel.id, content, tts=tts, embed=embed,
  File "C:\Users\82105\AppData\Local\Programs\Python\Python39\lib\site-packages\discord\http.py", line 254, in request
    raise HTTPException(r, data)
discord.errors.HTTPException: 400 Bad Request (error code: 50006): Cannot send an empty message

The above exception was the direct cause of the following exception:

Traceback (most recent call last):
  File "c:\Users\82105\Desktop\Project\Discord\DiscordBot_Gwen\utils\logger.py", line 22, in err
    raise error
  File "C:\Users\82105\AppData\Local\Programs\Python\Python39\lib\site-packages\discord\ext\commands\bot.py", line 939, in invoke
    await ctx.command.invoke(ctx)
  File "C:\Users\82105\AppData\Local\Programs\Python\Python39\lib\site-packages\discord\ext\commands\core.py", line 863, in invoke
    await injected(*ctx.args, **ctx.kwargs)
  File "C:\Users\82105\AppData\Local\Programs\Python\Python39\lib\site-packages\discord\ext\commands\core.py", line 94, in wrapped
    raise CommandInvokeError(exc) from exc
discord.ext.commands.errors.CommandInvokeError: Command raised an exception: HTTPException: 400 Bad Request (error code: 50006): Cannot send an empty message



18시 42분 / [오류] Traceback (most recent call last):
  File "C:\Users\82105\AppData\Local\Programs\Python\Python39\lib\site-packages\discord\ext\commands\core.py", line 85, in wrapped
    ret = await coro(*args, **kwargs)
  File "c:\Users\82105\Desktop\Project\Discord\DiscordBot_Gwen\cogs\SearchCommand.py", line 258, in PS
    patch = soup.find("div", attrs={"class":"simplebar-placeholder"}).get_text()
AttributeError: 'NoneType' object has no attribute 'get_text'

The above exception was the direct cause of the following exception:

Traceback (most recent call last):
  File "c:\Users\82105\Desktop\Project\Discord\DiscordBot_Gwen\utils\logger.py", line 22, in err
    raise error
  File "C:\Users\82105\AppData\Local\Programs\Python\Python39\lib\site-packages\discord\ext\commands\bot.py", line 939, in invoke
    await ctx.command.invoke(ctx)
  File "C:\Users\82105\AppData\Local\Programs\Python\Python39\lib\site-packages\discord\ext\commands\core.py", line 863, in invoke
    await injected(*ctx.args, **ctx.kwargs)
  File "C:\Users\82105\AppData\Local\Programs\Python\Python39\lib\site-packages\discord\ext\commands\core.py", line 94, in wrapped
    raise CommandInvokeError(exc) from exc
discord.ext.commands.errors.CommandInvokeError: Command raised an exception: AttributeError: 'NoneType' object has no attribute 'get_text'



18시 44분 / [오류] Traceback (most recent call last):
  File "C:\Users\82105\AppData\Local\Programs\Python\Python39\lib\site-packages\discord\ext\commands\core.py", line 85, in wrapped
    ret = await coro(*args, **kwargs)
  File "c:\Users\82105\Desktop\Project\Discord\DiscordBot_Gwen\cogs\SearchCommand.py", line 258, in PS
    patch = soup.find("div", attrs={"class":"champinfo-difference"}).get_text()
AttributeError: 'NoneType' object has no attribute 'get_text'

The above exception was the direct cause of the following exception:

Traceback (most recent call last):
  File "c:\Users\82105\Desktop\Project\Discord\DiscordBot_Gwen\utils\logger.py", line 22, in err
    raise error
  File "C:\Users\82105\AppData\Local\Programs\Python\Python39\lib\site-packages\discord\ext\commands\bot.py", line 939, in invoke
    await ctx.command.invoke(ctx)
  File "C:\Users\82105\AppData\Local\Programs\Python\Python39\lib\site-packages\discord\ext\commands\core.py", line 863, in invoke
    await injected(*ctx.args, **ctx.kwargs)
  File "C:\Users\82105\AppData\Local\Programs\Python\Python39\lib\site-packages\discord\ext\commands\core.py", line 94, in wrapped
    raise CommandInvokeError(exc) from exc
discord.ext.commands.errors.CommandInvokeError: Command raised an exception: AttributeError: 'NoneType' object has no attribute 'get_text'



18시 44분 / [오류] Traceback (most recent call last):
  File "C:\Users\82105\AppData\Local\Programs\Python\Python39\lib\site-packages\discord\ext\commands\core.py", line 85, in wrapped
    ret = await coro(*args, **kwargs)
  File "c:\Users\82105\Desktop\Project\Discord\DiscordBot_Gwen\cogs\SearchCommand.py", line 258, in PS
    patch = soup.find("h4", attrs={"class":"champinfo-label"}).get_text()
AttributeError: 'NoneType' object has no attribute 'get_text'

The above exception was the direct cause of the following exception:

Traceback (most recent call last):
  File "c:\Users\82105\Desktop\Project\Discord\DiscordBot_Gwen\utils\logger.py", line 22, in err
    raise error
  File "C:\Users\82105\AppData\Local\Programs\Python\Python39\lib\site-packages\discord\ext\commands\bot.py", line 939, in invoke
    await ctx.command.invoke(ctx)
  File "C:\Users\82105\AppData\Local\Programs\Python\Python39\lib\site-packages\discord\ext\commands\core.py", line 863, in invoke
    await injected(*ctx.args, **ctx.kwargs)
  File "C:\Users\82105\AppData\Local\Programs\Python\Python39\lib\site-packages\discord\ext\commands\core.py", line 94, in wrapped
    raise CommandInvokeError(exc) from exc
discord.ext.commands.errors.CommandInvokeError: Command raised an exception: AttributeError: 'NoneType' object has no attribute 'get_text'



18시 48분 / [오류] Traceback (most recent call last):
  File "C:\Users\82105\AppData\Local\Programs\Python\Python39\lib\site-packages\discord\ext\commands\core.py", line 85, in wrapped
    ret = await coro(*args, **kwargs)
  File "c:\Users\82105\Desktop\Project\Discord\DiscordBot_Gwen\cogs\SearchCommand.py", line 258, in PS
    patch = soup.find("h4", attrs={"class":"champ-link text-right"}).get_text()
AttributeError: 'NoneType' object has no attribute 'get_text'

The above exception was the direct cause of the following exception:

Traceback (most recent call last):
  File "c:\Users\82105\Desktop\Project\Discord\DiscordBot_Gwen\utils\logger.py", line 22, in err
    raise error
  File "C:\Users\82105\AppData\Local\Programs\Python\Python39\lib\site-packages\discord\ext\commands\bot.py", line 939, in invoke
    await ctx.command.invoke(ctx)
  File "C:\Users\82105\AppData\Local\Programs\Python\Python39\lib\site-packages\discord\ext\commands\core.py", line 863, in invoke
    await injected(*ctx.args, **ctx.kwargs)
  File "C:\Users\82105\AppData\Local\Programs\Python\Python39\lib\site-packages\discord\ext\commands\core.py", line 94, in wrapped
    raise CommandInvokeError(exc) from exc
discord.ext.commands.errors.CommandInvokeError: Command raised an exception: AttributeError: 'NoneType' object has no attribute 'get_text'



18시 48분 / [오류] Traceback (most recent call last):
  File "C:\Users\82105\AppData\Local\Programs\Python\Python39\lib\site-packages\discord\ext\commands\core.py", line 85, in wrapped
    ret = await coro(*args, **kwargs)
  File "c:\Users\82105\Desktop\Project\Discord\DiscordBot_Gwen\cogs\SearchCommand.py", line 259, in PS
    await ctx.send(patch)
  File "C:\Users\82105\AppData\Local\Programs\Python\Python39\lib\site-packages\discord\abc.py", line 1065, in send
    data = await state.http.send_message(channel.id, content, tts=tts, embed=embed,
  File "C:\Users\82105\AppData\Local\Programs\Python\Python39\lib\site-packages\discord\http.py", line 254, in request
    raise HTTPException(r, data)
discord.errors.HTTPException: 400 Bad Request (error code: 50006): Cannot send an empty message

The above exception was the direct cause of the following exception:

Traceback (most recent call last):
  File "c:\Users\82105\Desktop\Project\Discord\DiscordBot_Gwen\utils\logger.py", line 22, in err
    raise error
  File "C:\Users\82105\AppData\Local\Programs\Python\Python39\lib\site-packages\discord\ext\commands\bot.py", line 939, in invoke
    await ctx.command.invoke(ctx)
  File "C:\Users\82105\AppData\Local\Programs\Python\Python39\lib\site-packages\discord\ext\commands\core.py", line 863, in invoke
    await injected(*ctx.args, **ctx.kwargs)
  File "C:\Users\82105\AppData\Local\Programs\Python\Python39\lib\site-packages\discord\ext\commands\core.py", line 94, in wrapped
    raise CommandInvokeError(exc) from exc
discord.ext.commands.errors.CommandInvokeError: Command raised an exception: HTTPException: 400 Bad Request (error code: 50006): Cannot send an empty message



18시 49분 / [오류] Traceback (most recent call last):
  File "C:\Users\82105\AppData\Local\Programs\Python\Python39\lib\site-packages\discord\ext\commands\core.py", line 85, in wrapped
    ret = await coro(*args, **kwargs)
  File "c:\Users\82105\Desktop\Project\Discord\DiscordBot_Gwen\cogs\SearchCommand.py", line 259, in PS
    await ctx.send(patch)
  File "C:\Users\82105\AppData\Local\Programs\Python\Python39\lib\site-packages\discord\abc.py", line 1065, in send
    data = await state.http.send_message(channel.id, content, tts=tts, embed=embed,
  File "C:\Users\82105\AppData\Local\Programs\Python\Python39\lib\site-packages\discord\http.py", line 254, in request
    raise HTTPException(r, data)
discord.errors.HTTPException: 400 Bad Request (error code: 50006): Cannot send an empty message

The above exception was the direct cause of the following exception:

Traceback (most recent call last):
  File "c:\Users\82105\Desktop\Project\Discord\DiscordBot_Gwen\utils\logger.py", line 22, in err
    raise error
  File "C:\Users\82105\AppData\Local\Programs\Python\Python39\lib\site-packages\discord\ext\commands\bot.py", line 939, in invoke
    await ctx.command.invoke(ctx)
  File "C:\Users\82105\AppData\Local\Programs\Python\Python39\lib\site-packages\discord\ext\commands\core.py", line 863, in invoke
    await injected(*ctx.args, **ctx.kwargs)
  File "C:\Users\82105\AppData\Local\Programs\Python\Python39\lib\site-packages\discord\ext\commands\core.py", line 94, in wrapped
    raise CommandInvokeError(exc) from exc
discord.ext.commands.errors.CommandInvokeError: Command raised an exception: HTTPException: 400 Bad Request (error code: 50006): Cannot send an empty message



18시 50분 / [오류] Traceback (most recent call last):
  File "C:\Users\82105\AppData\Local\Programs\Python\Python39\lib\site-packages\discord\ext\commands\core.py", line 85, in wrapped
    ret = await coro(*args, **kwargs)
  File "c:\Users\82105\Desktop\Project\Discord\DiscordBot_Gwen\cogs\SearchCommand.py", line 259, in PS
    await ctx.send(patch)
  File "C:\Users\82105\AppData\Local\Programs\Python\Python39\lib\site-packages\discord\abc.py", line 1065, in send
    data = await state.http.send_message(channel.id, content, tts=tts, embed=embed,
  File "C:\Users\82105\AppData\Local\Programs\Python\Python39\lib\site-packages\discord\http.py", line 254, in request
    raise HTTPException(r, data)
discord.errors.HTTPException: 400 Bad Request (error code: 50006): Cannot send an empty message

The above exception was the direct cause of the following exception:

Traceback (most recent call last):
  File "c:\Users\82105\Desktop\Project\Discord\DiscordBot_Gwen\utils\logger.py", line 22, in err
    raise error
  File "C:\Users\82105\AppData\Local\Programs\Python\Python39\lib\site-packages\discord\ext\commands\bot.py", line 939, in invoke
    await ctx.command.invoke(ctx)
  File "C:\Users\82105\AppData\Local\Programs\Python\Python39\lib\site-packages\discord\ext\commands\core.py", line 863, in invoke
    await injected(*ctx.args, **ctx.kwargs)
  File "C:\Users\82105\AppData\Local\Programs\Python\Python39\lib\site-packages\discord\ext\commands\core.py", line 94, in wrapped
    raise CommandInvokeError(exc) from exc
discord.ext.commands.errors.CommandInvokeError: Command raised an exception: HTTPException: 400 Bad Request (error code: 50006): Cannot send an empty message



18시 51분 / [오류] Traceback (most recent call last):
  File "C:\Users\82105\AppData\Local\Programs\Python\Python39\lib\site-packages\discord\ext\commands\core.py", line 85, in wrapped
    ret = await coro(*args, **kwargs)
  File "c:\Users\82105\Desktop\Project\Discord\DiscordBot_Gwen\cogs\SearchCommand.py", line 259, in PS
    await ctx.send(patch)
  File "C:\Users\82105\AppData\Local\Programs\Python\Python39\lib\site-packages\discord\abc.py", line 1065, in send
    data = await state.http.send_message(channel.id, content, tts=tts, embed=embed,
  File "C:\Users\82105\AppData\Local\Programs\Python\Python39\lib\site-packages\discord\http.py", line 254, in request
    raise HTTPException(r, data)
discord.errors.HTTPException: 400 Bad Request (error code: 50006): Cannot send an empty message

The above exception was the direct cause of the following exception:

Traceback (most recent call last):
  File "c:\Users\82105\Desktop\Project\Discord\DiscordBot_Gwen\utils\logger.py", line 22, in err
    raise error
  File "C:\Users\82105\AppData\Local\Programs\Python\Python39\lib\site-packages\discord\ext\commands\bot.py", line 939, in invoke
    await ctx.command.invoke(ctx)
  File "C:\Users\82105\AppData\Local\Programs\Python\Python39\lib\site-packages\discord\ext\commands\core.py", line 863, in invoke
    await injected(*ctx.args, **ctx.kwargs)
  File "C:\Users\82105\AppData\Local\Programs\Python\Python39\lib\site-packages\discord\ext\commands\core.py", line 94, in wrapped
    raise CommandInvokeError(exc) from exc
discord.ext.commands.errors.CommandInvokeError: Command raised an exception: HTTPException: 400 Bad Request (error code: 50006): Cannot send an empty message



18시 52분 / [오류] Traceback (most recent call last):
  File "C:\Users\82105\AppData\Local\Programs\Python\Python39\lib\site-packages\discord\ext\commands\core.py", line 85, in wrapped
    ret = await coro(*args, **kwargs)
  File "c:\Users\82105\Desktop\Project\Discord\DiscordBot_Gwen\cogs\SearchCommand.py", line 259, in PS
    await ctx.send(patch)
  File "C:\Users\82105\AppData\Local\Programs\Python\Python39\lib\site-packages\discord\abc.py", line 1065, in send
    data = await state.http.send_message(channel.id, content, tts=tts, embed=embed,
  File "C:\Users\82105\AppData\Local\Programs\Python\Python39\lib\site-packages\discord\http.py", line 254, in request
    raise HTTPException(r, data)
discord.errors.HTTPException: 400 Bad Request (error code: 50035): Invalid Form Body
In content: Must be 4000 or fewer in length.

The above exception was the direct cause of the following exception:

Traceback (most recent call last):
  File "c:\Users\82105\Desktop\Project\Discord\DiscordBot_Gwen\utils\logger.py", line 22, in err
    raise error
  File "C:\Users\82105\AppData\Local\Programs\Python\Python39\lib\site-packages\discord\ext\commands\bot.py", line 939, in invoke
    await ctx.command.invoke(ctx)
  File "C:\Users\82105\AppData\Local\Programs\Python\Python39\lib\site-packages\discord\ext\commands\core.py", line 863, in invoke
    await injected(*ctx.args, **ctx.kwargs)
  File "C:\Users\82105\AppData\Local\Programs\Python\Python39\lib\site-packages\discord\ext\commands\core.py", line 94, in wrapped
    raise CommandInvokeError(exc) from exc
discord.ext.commands.errors.CommandInvokeError: Command raised an exception: HTTPException: 400 Bad Request (error code: 50035): Invalid Form Body
In content: Must be 4000 or fewer in length.



18시 55분 / [오류] Traceback (most recent call last):
  File "C:\Users\82105\AppData\Local\Programs\Python\Python39\lib\site-packages\discord\ext\commands\core.py", line 85, in wrapped
    ret = await coro(*args, **kwargs)
  File "c:\Users\82105\Desktop\Project\Discord\DiscordBot_Gwen\cogs\SearchCommand.py", line 259, in PS
    await ctx.send(patch)
  File "C:\Users\82105\AppData\Local\Programs\Python\Python39\lib\site-packages\discord\abc.py", line 1065, in send
    data = await state.http.send_message(channel.id, content, tts=tts, embed=embed,
  File "C:\Users\82105\AppData\Local\Programs\Python\Python39\lib\site-packages\discord\http.py", line 254, in request
    raise HTTPException(r, data)
discord.errors.HTTPException: 400 Bad Request (error code: 50006): Cannot send an empty message

The above exception was the direct cause of the following exception:

Traceback (most recent call last):
  File "c:\Users\82105\Desktop\Project\Discord\DiscordBot_Gwen\utils\logger.py", line 22, in err
    raise error
  File "C:\Users\82105\AppData\Local\Programs\Python\Python39\lib\site-packages\discord\ext\commands\bot.py", line 939, in invoke
    await ctx.command.invoke(ctx)
  File "C:\Users\82105\AppData\Local\Programs\Python\Python39\lib\site-packages\discord\ext\commands\core.py", line 863, in invoke
    await injected(*ctx.args, **ctx.kwargs)
  File "C:\Users\82105\AppData\Local\Programs\Python\Python39\lib\site-packages\discord\ext\commands\core.py", line 94, in wrapped
    raise CommandInvokeError(exc) from exc
discord.ext.commands.errors.CommandInvokeError: Command raised an exception: HTTPException: 400 Bad Request (error code: 50006): Cannot send an empty message



19시 32분 / [오류] Traceback (most recent call last):
  File "C:\Users\82105\AppData\Local\Programs\Python\Python39\lib\site-packages\discord\ext\commands\core.py", line 85, in wrapped
    ret = await coro(*args, **kwargs)
  File "c:\Users\82105\Desktop\Project\Discord\DiscordBot_Gwen\cogs\SearchCommand.py", line 260, in PS
    await ctx.send(soup.get_text())
  File "C:\Users\82105\AppData\Local\Programs\Python\Python39\lib\site-packages\discord\abc.py", line 1065, in send
    data = await state.http.send_message(channel.id, content, tts=tts, embed=embed,
  File "C:\Users\82105\AppData\Local\Programs\Python\Python39\lib\site-packages\discord\http.py", line 254, in request
    raise HTTPException(r, data)
discord.errors.HTTPException: 400 Bad Request (error code: 50035): Invalid Form Body
In content: Must be 4000 or fewer in length.

The above exception was the direct cause of the following exception:

Traceback (most recent call last):
  File "c:\Users\82105\Desktop\Project\Discord\DiscordBot_Gwen\utils\logger.py", line 22, in err
    raise error
  File "C:\Users\82105\AppData\Local\Programs\Python\Python39\lib\site-packages\discord\ext\commands\bot.py", line 939, in invoke
    await ctx.command.invoke(ctx)
  File "C:\Users\82105\AppData\Local\Programs\Python\Python39\lib\site-packages\discord\ext\commands\core.py", line 863, in invoke
    await injected(*ctx.args, **ctx.kwargs)
  File "C:\Users\82105\AppData\Local\Programs\Python\Python39\lib\site-packages\discord\ext\commands\core.py", line 94, in wrapped
    raise CommandInvokeError(exc) from exc
discord.ext.commands.errors.CommandInvokeError: Command raised an exception: HTTPException: 400 Bad Request (error code: 50035): Invalid Form Body
In content: Must be 4000 or fewer in length.



19시 34분 / [오류] Traceback (most recent call last):
  File "C:\Users\82105\AppData\Local\Programs\Python\Python39\lib\site-packages\discord\ext\commands\core.py", line 85, in wrapped
    ret = await coro(*args, **kwargs)
  File "c:\Users\82105\Desktop\Project\Discord\DiscordBot_Gwen\cogs\SearchCommand.py", line 260, in PS
    for most in range(0,3000):
  File "C:\Users\82105\AppData\Local\Programs\Python\Python39\lib\site-packages\discord\abc.py", line 1065, in send
    data = await state.http.send_message(channel.id, content, tts=tts, embed=embed,
  File "C:\Users\82105\AppData\Local\Programs\Python\Python39\lib\site-packages\discord\http.py", line 254, in request
    raise HTTPException(r, data)
discord.errors.HTTPException: 400 Bad Request (error code: 50035): Invalid Form Body
In content: Must be 4000 or fewer in length.

The above exception was the direct cause of the following exception:

Traceback (most recent call last):
  File "c:\Users\82105\Desktop\Project\Discord\DiscordBot_Gwen\utils\logger.py", line 22, in err
    raise error
  File "C:\Users\82105\AppData\Local\Programs\Python\Python39\lib\site-packages\discord\ext\commands\bot.py", line 939, in invoke
    await ctx.command.invoke(ctx)
  File "C:\Users\82105\AppData\Local\Programs\Python\Python39\lib\site-packages\discord\ext\commands\core.py", line 863, in invoke
    await injected(*ctx.args, **ctx.kwargs)
  File "C:\Users\82105\AppData\Local\Programs\Python\Python39\lib\site-packages\discord\ext\commands\core.py", line 94, in wrapped
    raise CommandInvokeError(exc) from exc
discord.ext.commands.errors.CommandInvokeError: Command raised an exception: HTTPException: 400 Bad Request (error code: 50035): Invalid Form Body
In content: Must be 4000 or fewer in length.



