13시 42분 / [오류] Traceback (most recent call last):
  File "C:\Users\82105\AppData\Local\Programs\Python\Python39\lib\site-packages\discord\ext\commands\core.py", line 85, in wrapped
    ret = await coro(*args, **kwargs)
  File "c:\Users\82105\Desktop\Project\Discord\DiscordBot_Gwen\cogs\SearchCommand.py", line 211, in 챔피언
    Background.paste(getImg(SeleLune_list[0], 200,200), (250,200))
IndexError: list index out of range

The above exception was the direct cause of the following exception:

Traceback (most recent call last):
  File "c:\Users\82105\Desktop\Project\Discord\DiscordBot_Gwen\utils\logger.py", line 22, in err
    raise error
  File "C:\Users\82105\AppData\Local\Programs\Python\Python39\lib\site-packages\discord\ext\commands\bot.py", line 939, in invoke
    await ctx.command.invoke(ctx)
  File "C:\Users\82105\AppData\Local\Programs\Python\Python39\lib\site-packages\discord\ext\commands\core.py", line 863, in invoke
    await injected(*ctx.args, **ctx.kwargs)
  File "C:\Users\82105\AppData\Local\Programs\Python\Python39\lib\site-packages\discord\ext\commands\core.py", line 94, in wrapped
    raise CommandInvokeError(exc) from exc
discord.ext.commands.errors.CommandInvokeError: Command raised an exception: IndexError: list index out of range



13시 42분 / [오류] Traceback (most recent call last):
  File "C:\Users\82105\AppData\Local\Programs\Python\Python39\lib\site-packages\discord\ext\commands\core.py", line 85, in wrapped
    ret = await coro(*args, **kwargs)
  File "c:\Users\82105\Desktop\Project\Discord\DiscordBot_Gwen\cogs\SearchCommand.py", line 211, in 챔피언
    Background.paste(getImg(SeleLune_list[0], 200,200), (250,200))
IndexError: list index out of range

The above exception was the direct cause of the following exception:

Traceback (most recent call last):
  File "c:\Users\82105\Desktop\Project\Discord\DiscordBot_Gwen\utils\logger.py", line 22, in err
    raise error
  File "C:\Users\82105\AppData\Local\Programs\Python\Python39\lib\site-packages\discord\ext\commands\bot.py", line 939, in invoke
    await ctx.command.invoke(ctx)
  File "C:\Users\82105\AppData\Local\Programs\Python\Python39\lib\site-packages\discord\ext\commands\core.py", line 863, in invoke
    await injected(*ctx.args, **ctx.kwargs)
  File "C:\Users\82105\AppData\Local\Programs\Python\Python39\lib\site-packages\discord\ext\commands\core.py", line 94, in wrapped
    raise CommandInvokeError(exc) from exc
discord.ext.commands.errors.CommandInvokeError: Command raised an exception: IndexError: list index out of range



13시 44분 / [오류] Traceback (most recent call last):
  File "C:\Users\82105\AppData\Local\Programs\Python\Python39\lib\site-packages\discord\ext\commands\core.py", line 85, in wrapped
    ret = await coro(*args, **kwargs)
  File "c:\Users\82105\Desktop\Project\Discord\DiscordBot_Gwen\cogs\SearchCommand.py", line 211, in 챔피언
    Background.paste(getImg(SeleLune_list[0], 200,200), (250,200))
IndexError: list index out of range

The above exception was the direct cause of the following exception:

Traceback (most recent call last):
  File "c:\Users\82105\Desktop\Project\Discord\DiscordBot_Gwen\utils\logger.py", line 22, in err
    raise error
  File "C:\Users\82105\AppData\Local\Programs\Python\Python39\lib\site-packages\discord\ext\commands\bot.py", line 939, in invoke
    await ctx.command.invoke(ctx)
  File "C:\Users\82105\AppData\Local\Programs\Python\Python39\lib\site-packages\discord\ext\commands\core.py", line 863, in invoke
    await injected(*ctx.args, **ctx.kwargs)
  File "C:\Users\82105\AppData\Local\Programs\Python\Python39\lib\site-packages\discord\ext\commands\core.py", line 94, in wrapped
    raise CommandInvokeError(exc) from exc
discord.ext.commands.errors.CommandInvokeError: Command raised an exception: IndexError: list index out of range



13시 48분 / [오류] Traceback (most recent call last):
  File "C:\Users\82105\AppData\Local\Programs\Python\Python39\lib\site-packages\discord\ext\commands\core.py", line 85, in wrapped
    ret = await coro(*args, **kwargs)
  File "c:\Users\82105\Desktop\Project\Discord\DiscordBot_Gwen\cogs\SearchCommand.py", line 211, in 챔피언
    Background.paste(getImg(SeleLune_list[0], 200,200), (250,200))
IndexError: list index out of range

The above exception was the direct cause of the following exception:

Traceback (most recent call last):
  File "c:\Users\82105\Desktop\Project\Discord\DiscordBot_Gwen\utils\logger.py", line 22, in err
    raise error
  File "C:\Users\82105\AppData\Local\Programs\Python\Python39\lib\site-packages\discord\ext\commands\bot.py", line 939, in invoke
    await ctx.command.invoke(ctx)
  File "C:\Users\82105\AppData\Local\Programs\Python\Python39\lib\site-packages\discord\ext\commands\core.py", line 863, in invoke
    await injected(*ctx.args, **ctx.kwargs)
  File "C:\Users\82105\AppData\Local\Programs\Python\Python39\lib\site-packages\discord\ext\commands\core.py", line 94, in wrapped
    raise CommandInvokeError(exc) from exc
discord.ext.commands.errors.CommandInvokeError: Command raised an exception: IndexError: list index out of range



13시 54분 / [오류] Traceback (most recent call last):
  File "C:\Users\82105\AppData\Local\Programs\Python\Python39\lib\site-packages\discord\ext\commands\core.py", line 85, in wrapped
    ret = await coro(*args, **kwargs)
  File "c:\Users\82105\Desktop\Project\Discord\DiscordBot_Gwen\cogs\SearchCommand.py", line 200, in 챔피언
    SeleLune = soup.find("div", attrs={"class":"perk-page__item  perk-page__item--active"}).find("img").get("src")
AttributeError: 'NoneType' object has no attribute 'find'

The above exception was the direct cause of the following exception:

Traceback (most recent call last):
  File "c:\Users\82105\Desktop\Project\Discord\DiscordBot_Gwen\utils\logger.py", line 22, in err
    raise error
  File "C:\Users\82105\AppData\Local\Programs\Python\Python39\lib\site-packages\discord\ext\commands\bot.py", line 939, in invoke
    await ctx.command.invoke(ctx)
  File "C:\Users\82105\AppData\Local\Programs\Python\Python39\lib\site-packages\discord\ext\commands\core.py", line 863, in invoke
    await injected(*ctx.args, **ctx.kwargs)
  File "C:\Users\82105\AppData\Local\Programs\Python\Python39\lib\site-packages\discord\ext\commands\core.py", line 94, in wrapped
    raise CommandInvokeError(exc) from exc
discord.ext.commands.errors.CommandInvokeError: Command raised an exception: AttributeError: 'NoneType' object has no attribute 'find'



17시 40분 / [오류] Traceback (most recent call last):
  File "C:\Users\82105\AppData\Local\Programs\Python\Python39\lib\site-packages\discord\ext\commands\core.py", line 85, in wrapped
    ret = await coro(*args, **kwargs)
  File "c:\Users\82105\Desktop\Project\Discord\DiscordBot_Gwen\cogs\SearchCommand.py", line 475, in 정글
    Background.paste(getImg(spell_list[0], 100,100), (90, 1185))
IndexError: list index out of range

The above exception was the direct cause of the following exception:

Traceback (most recent call last):
  File "c:\Users\82105\Desktop\Project\Discord\DiscordBot_Gwen\utils\logger.py", line 22, in err
    raise error
  File "C:\Users\82105\AppData\Local\Programs\Python\Python39\lib\site-packages\discord\ext\commands\bot.py", line 939, in invoke
    await ctx.command.invoke(ctx)
  File "C:\Users\82105\AppData\Local\Programs\Python\Python39\lib\site-packages\discord\ext\commands\core.py", line 863, in invoke
    await injected(*ctx.args, **ctx.kwargs)
  File "C:\Users\82105\AppData\Local\Programs\Python\Python39\lib\site-packages\discord\ext\commands\core.py", line 94, in wrapped
    raise CommandInvokeError(exc) from exc
discord.ext.commands.errors.CommandInvokeError: Command raised an exception: IndexError: list index out of range



17시 41분 / [오류] Traceback (most recent call last):
  File "C:\Users\82105\AppData\Local\Programs\Python\Python39\lib\site-packages\discord\ext\commands\core.py", line 85, in wrapped
    ret = await coro(*args, **kwargs)
  File "c:\Users\82105\Desktop\Project\Discord\DiscordBot_Gwen\cogs\SearchCommand.py", line 481, in 정글
    Background.paste(getImg(counter_list[0], 100,100), (500,1270))
IndexError: list index out of range

The above exception was the direct cause of the following exception:

Traceback (most recent call last):
  File "c:\Users\82105\Desktop\Project\Discord\DiscordBot_Gwen\utils\logger.py", line 22, in err
    raise error
  File "C:\Users\82105\AppData\Local\Programs\Python\Python39\lib\site-packages\discord\ext\commands\bot.py", line 939, in invoke
    await ctx.command.invoke(ctx)
  File "C:\Users\82105\AppData\Local\Programs\Python\Python39\lib\site-packages\discord\ext\commands\core.py", line 863, in invoke
    await injected(*ctx.args, **ctx.kwargs)
  File "C:\Users\82105\AppData\Local\Programs\Python\Python39\lib\site-packages\discord\ext\commands\core.py", line 94, in wrapped
    raise CommandInvokeError(exc) from exc
discord.ext.commands.errors.CommandInvokeError: Command raised an exception: IndexError: list index out of range



17시 41분 / [오류] Traceback (most recent call last):
  File "C:\Users\82105\AppData\Local\Programs\Python\Python39\lib\site-packages\discord\ext\commands\core.py", line 85, in wrapped
    ret = await coro(*args, **kwargs)
  File "c:\Users\82105\Desktop\Project\Discord\DiscordBot_Gwen\cogs\SearchCommand.py", line 483, in 정글
    Background.paste(getImg(counter_list[2], 100,100), (750,1270))
IndexError: list index out of range

The above exception was the direct cause of the following exception:

Traceback (most recent call last):
  File "c:\Users\82105\Desktop\Project\Discord\DiscordBot_Gwen\utils\logger.py", line 22, in err
    raise error
  File "C:\Users\82105\AppData\Local\Programs\Python\Python39\lib\site-packages\discord\ext\commands\bot.py", line 939, in invoke
    await ctx.command.invoke(ctx)
  File "C:\Users\82105\AppData\Local\Programs\Python\Python39\lib\site-packages\discord\ext\commands\core.py", line 863, in invoke
    await injected(*ctx.args, **ctx.kwargs)
  File "C:\Users\82105\AppData\Local\Programs\Python\Python39\lib\site-packages\discord\ext\commands\core.py", line 94, in wrapped
    raise CommandInvokeError(exc) from exc
discord.ext.commands.errors.CommandInvokeError: Command raised an exception: IndexError: list index out of range



17시 41분 / [오류] Traceback (most recent call last):
  File "C:\Users\82105\AppData\Local\Programs\Python\Python39\lib\site-packages\discord\ext\commands\core.py", line 85, in wrapped
    ret = await coro(*args, **kwargs)
  File "c:\Users\82105\Desktop\Project\Discord\DiscordBot_Gwen\cogs\SearchCommand.py", line 793, in 원딜
    Background.paste(getImg(counter_list[0], 100,100), (500,1270))
IndexError: list index out of range

The above exception was the direct cause of the following exception:

Traceback (most recent call last):
  File "c:\Users\82105\Desktop\Project\Discord\DiscordBot_Gwen\utils\logger.py", line 22, in err
    raise error
  File "C:\Users\82105\AppData\Local\Programs\Python\Python39\lib\site-packages\discord\ext\commands\bot.py", line 939, in invoke
    await ctx.command.invoke(ctx)
  File "C:\Users\82105\AppData\Local\Programs\Python\Python39\lib\site-packages\discord\ext\commands\core.py", line 863, in invoke
    await injected(*ctx.args, **ctx.kwargs)
  File "C:\Users\82105\AppData\Local\Programs\Python\Python39\lib\site-packages\discord\ext\commands\core.py", line 94, in wrapped
    raise CommandInvokeError(exc) from exc
discord.ext.commands.errors.CommandInvokeError: Command raised an exception: IndexError: list index out of range



17시 43분 / [오류] Traceback (most recent call last):
  File "C:\Users\82105\AppData\Local\Programs\Python\Python39\lib\site-packages\discord\ext\commands\core.py", line 85, in wrapped
    ret = await coro(*args, **kwargs)
  File "c:\Users\82105\Desktop\Project\Discord\DiscordBot_Gwen\cogs\SearchCommand.py", line 481, in 정글
    Background.paste(getImg(counter_list[0], 100,100), (500,1270))
IndexError: list index out of range

The above exception was the direct cause of the following exception:

Traceback (most recent call last):
  File "c:\Users\82105\Desktop\Project\Discord\DiscordBot_Gwen\utils\logger.py", line 22, in err
    raise error
  File "C:\Users\82105\AppData\Local\Programs\Python\Python39\lib\site-packages\discord\ext\commands\bot.py", line 939, in invoke
    await ctx.command.invoke(ctx)
  File "C:\Users\82105\AppData\Local\Programs\Python\Python39\lib\site-packages\discord\ext\commands\core.py", line 863, in invoke
    await injected(*ctx.args, **ctx.kwargs)
  File "C:\Users\82105\AppData\Local\Programs\Python\Python39\lib\site-packages\discord\ext\commands\core.py", line 94, in wrapped
    raise CommandInvokeError(exc) from exc
discord.ext.commands.errors.CommandInvokeError: Command raised an exception: IndexError: list index out of range



17시 58분 / [오류] Traceback (most recent call last):
  File "C:\Users\82105\AppData\Local\Programs\Python\Python39\lib\site-packages\discord\ext\commands\core.py", line 85, in wrapped
    ret = await coro(*args, **kwargs)
  File "c:\Users\82105\Desktop\Project\Discord\DiscordBot_Gwen\cogs\SearchCommand.py", line 502, in 정글
    small = soup.find("div", attrs={"class":"fragment-page"}).find_all("img", attrs={"class":"active tip"},limit=3)
AttributeError: 'NoneType' object has no attribute 'find_all'

The above exception was the direct cause of the following exception:

Traceback (most recent call last):
  File "c:\Users\82105\Desktop\Project\Discord\DiscordBot_Gwen\utils\logger.py", line 22, in err
    raise error
  File "C:\Users\82105\AppData\Local\Programs\Python\Python39\lib\site-packages\discord\ext\commands\bot.py", line 939, in invoke
    await ctx.command.invoke(ctx)
  File "C:\Users\82105\AppData\Local\Programs\Python\Python39\lib\site-packages\discord\ext\commands\core.py", line 863, in invoke
    await injected(*ctx.args, **ctx.kwargs)
  File "C:\Users\82105\AppData\Local\Programs\Python\Python39\lib\site-packages\discord\ext\commands\core.py", line 94, in wrapped
    raise CommandInvokeError(exc) from exc
discord.ext.commands.errors.CommandInvokeError: Command raised an exception: AttributeError: 'NoneType' object has no attribute 'find_all'



18시 01분 / [오류] Traceback (most recent call last):
  File "C:\Users\82105\AppData\Local\Programs\Python\Python39\lib\site-packages\discord\ext\commands\core.py", line 85, in wrapped
    ret = await coro(*args, **kwargs)
  File "c:\Users\82105\Desktop\Project\Discord\DiscordBot_Gwen\cogs\SearchCommand.py", line 511, in 정글
    small = soup.find("div", attrs={"class":"fragment-page"}).find_all("img", attrs={"class":"active tip"},limit=3)
AttributeError: 'NoneType' object has no attribute 'find_all'

The above exception was the direct cause of the following exception:

Traceback (most recent call last):
  File "c:\Users\82105\Desktop\Project\Discord\DiscordBot_Gwen\utils\logger.py", line 22, in err
    raise error
  File "C:\Users\82105\AppData\Local\Programs\Python\Python39\lib\site-packages\discord\ext\commands\bot.py", line 939, in invoke
    await ctx.command.invoke(ctx)
  File "C:\Users\82105\AppData\Local\Programs\Python\Python39\lib\site-packages\discord\ext\commands\core.py", line 863, in invoke
    await injected(*ctx.args, **ctx.kwargs)
  File "C:\Users\82105\AppData\Local\Programs\Python\Python39\lib\site-packages\discord\ext\commands\core.py", line 94, in wrapped
    raise CommandInvokeError(exc) from exc
discord.ext.commands.errors.CommandInvokeError: Command raised an exception: AttributeError: 'NoneType' object has no attribute 'find_all'



