19시 32분 / [오류] Traceback (most recent call last):
  File "C:\Users\82105\AppData\Local\Programs\Python\Python39\lib\site-packages\discord\ext\commands\core.py", line 85, in wrapped
    ret = await coro(*args, **kwargs)
  File "c:\Users\82105\Desktop\Project\Discord\DiscordBot_Gwen\cogs\Favorability.py", line 19, in 학습
    word = ctx.split(" ")
AttributeError: 'Context' object has no attribute 'split'

The above exception was the direct cause of the following exception:

Traceback (most recent call last):
  File "c:\Users\82105\Desktop\Project\Discord\DiscordBot_Gwen\utils\logger.py", line 22, in err
    raise error
  File "C:\Users\82105\AppData\Local\Programs\Python\Python39\lib\site-packages\discord\ext\commands\bot.py", line 939, in invoke
    await ctx.command.invoke(ctx)
  File "C:\Users\82105\AppData\Local\Programs\Python\Python39\lib\site-packages\discord\ext\commands\core.py", line 863, in invoke
    await injected(*ctx.args, **ctx.kwargs)
  File "C:\Users\82105\AppData\Local\Programs\Python\Python39\lib\site-packages\discord\ext\commands\core.py", line 94, in wrapped
    raise CommandInvokeError(exc) from exc
discord.ext.commands.errors.CommandInvokeError: Command raised an exception: AttributeError: 'Context' object has no attribute 'split'



19시 38분 / [오류] Traceback (most recent call last):
  File "C:\Users\82105\AppData\Local\Programs\Python\Python39\lib\site-packages\discord\ext\commands\core.py", line 85, in wrapped
    ret = await coro(*args, **kwargs)
  File "c:\Users\82105\Desktop\Project\Discord\DiscordBot_Gwen\cogs\Favorability.py", line 19, in 학습
    word = ctx.split(" ")
AttributeError: 'Context' object has no attribute 'split'

The above exception was the direct cause of the following exception:

Traceback (most recent call last):
  File "c:\Users\82105\Desktop\Project\Discord\DiscordBot_Gwen\utils\logger.py", line 22, in err
    raise error
  File "C:\Users\82105\AppData\Local\Programs\Python\Python39\lib\site-packages\discord\ext\commands\bot.py", line 939, in invoke
    await ctx.command.invoke(ctx)
  File "C:\Users\82105\AppData\Local\Programs\Python\Python39\lib\site-packages\discord\ext\commands\core.py", line 863, in invoke
    await injected(*ctx.args, **ctx.kwargs)
  File "C:\Users\82105\AppData\Local\Programs\Python\Python39\lib\site-packages\discord\ext\commands\core.py", line 94, in wrapped
    raise CommandInvokeError(exc) from exc
discord.ext.commands.errors.CommandInvokeError: Command raised an exception: AttributeError: 'Context' object has no attribute 'split'



19시 38분 / [오류] Traceback (most recent call last):
  File "C:\Users\82105\AppData\Local\Programs\Python\Python39\lib\site-packages\discord\ext\commands\core.py", line 85, in wrapped
    ret = await coro(*args, **kwargs)
  File "c:\Users\82105\Desktop\Project\Discord\DiscordBot_Gwen\cogs\Favorability.py", line 19, in 학습
    word = ctx.split(" ")
AttributeError: 'Context' object has no attribute 'split'

The above exception was the direct cause of the following exception:

Traceback (most recent call last):
  File "c:\Users\82105\Desktop\Project\Discord\DiscordBot_Gwen\utils\logger.py", line 22, in err
    raise error
  File "C:\Users\82105\AppData\Local\Programs\Python\Python39\lib\site-packages\discord\ext\commands\bot.py", line 939, in invoke
    await ctx.command.invoke(ctx)
  File "C:\Users\82105\AppData\Local\Programs\Python\Python39\lib\site-packages\discord\ext\commands\core.py", line 863, in invoke
    await injected(*ctx.args, **ctx.kwargs)
  File "C:\Users\82105\AppData\Local\Programs\Python\Python39\lib\site-packages\discord\ext\commands\core.py", line 94, in wrapped
    raise CommandInvokeError(exc) from exc
discord.ext.commands.errors.CommandInvokeError: Command raised an exception: AttributeError: 'Context' object has no attribute 'split'



19시 39분 / [오류] Traceback (most recent call last):
  File "C:\Users\82105\AppData\Local\Programs\Python\Python39\lib\site-packages\discord\ext\commands\core.py", line 85, in wrapped
    ret = await coro(*args, **kwargs)
  File "c:\Users\82105\Desktop\Project\Discord\DiscordBot_Gwen\cogs\Favorability.py", line 19, in 학습
    word = ctx.split(" ")
AttributeError: 'Context' object has no attribute 'split'

The above exception was the direct cause of the following exception:

Traceback (most recent call last):
  File "c:\Users\82105\Desktop\Project\Discord\DiscordBot_Gwen\utils\logger.py", line 22, in err
    raise error
  File "C:\Users\82105\AppData\Local\Programs\Python\Python39\lib\site-packages\discord\ext\commands\bot.py", line 939, in invoke
    await ctx.command.invoke(ctx)
  File "C:\Users\82105\AppData\Local\Programs\Python\Python39\lib\site-packages\discord\ext\commands\core.py", line 863, in invoke
    await injected(*ctx.args, **ctx.kwargs)
  File "C:\Users\82105\AppData\Local\Programs\Python\Python39\lib\site-packages\discord\ext\commands\core.py", line 94, in wrapped
    raise CommandInvokeError(exc) from exc
discord.ext.commands.errors.CommandInvokeError: Command raised an exception: AttributeError: 'Context' object has no attribute 'split'



