20시 51분 / [오류] Traceback (most recent call last):
  File "C:\Users\82105\AppData\Local\Programs\Python\Python39\lib\site-packages\discord\ext\commands\core.py", line 85, in wrapped
    ret = await coro(*args, **kwargs)
  File "c:\Users\82105\Downloads\SetaBot-2.3\cogs\example.py", line 53, in 말해
    await ctx.message.delete()  # 유저가 쓴 메시지는 지웁니다.
  File "C:\Users\82105\AppData\Local\Programs\Python\Python39\lib\site-packages\discord\message.py", line 1023, in delete
    await self._state.http.delete_message(self.channel.id, self.id)
  File "C:\Users\82105\AppData\Local\Programs\Python\Python39\lib\site-packages\discord\http.py", line 248, in request
    raise Forbidden(r, data)
discord.errors.Forbidden: 403 Forbidden (error code: 50013): Missing Permissions

The above exception was the direct cause of the following exception:

Traceback (most recent call last):
  File "c:\Users\82105\Downloads\SetaBot-2.3\utils\logger.py", line 22, in err
    raise error
  File "C:\Users\82105\AppData\Local\Programs\Python\Python39\lib\site-packages\discord\ext\commands\bot.py", line 939, in invoke
    await ctx.command.invoke(ctx)
  File "C:\Users\82105\AppData\Local\Programs\Python\Python39\lib\site-packages\discord\ext\commands\core.py", line 863, in invoke
    await injected(*ctx.args, **ctx.kwargs)
  File "C:\Users\82105\AppData\Local\Programs\Python\Python39\lib\site-packages\discord\ext\commands\core.py", line 94, in wrapped
    raise CommandInvokeError(exc) from exc
discord.ext.commands.errors.CommandInvokeError: Command raised an exception: Forbidden: 403 Forbidden (error code: 50013): Missing Permissions



20시 52분 / [오류] Traceback (most recent call last):
  File "C:\Users\82105\AppData\Local\Programs\Python\Python39\lib\site-packages\discord\ext\commands\core.py", line 85, in wrapped
    ret = await coro(*args, **kwargs)
  File "c:\Users\82105\Downloads\SetaBot-2.3\cogs\example.py", line 71, in 탕수육
    result = await util_box.ox(self.bot, window, ctx)
  File "c:\Users\82105\Downloads\SetaBot-2.3\utils\util_box.py", line 28, in ox
    await message.clear_reactions()
  File "C:\Users\82105\AppData\Local\Programs\Python\Python39\lib\site-packages\discord\message.py", line 1309, in clear_reactions
    await self._state.http.clear_reactions(self.channel.id, self.id)
  File "C:\Users\82105\AppData\Local\Programs\Python\Python39\lib\site-packages\discord\http.py", line 248, in request
    raise Forbidden(r, data)
discord.errors.Forbidden: 403 Forbidden (error code: 50013): Missing Permissions

The above exception was the direct cause of the following exception:

Traceback (most recent call last):
  File "c:\Users\82105\Downloads\SetaBot-2.3\utils\logger.py", line 22, in err
    raise error
  File "C:\Users\82105\AppData\Local\Programs\Python\Python39\lib\site-packages\discord\ext\commands\bot.py", line 939, in invoke
    await ctx.command.invoke(ctx)
  File "C:\Users\82105\AppData\Local\Programs\Python\Python39\lib\site-packages\discord\ext\commands\core.py", line 863, in invoke
    await injected(*ctx.args, **ctx.kwargs)
  File "C:\Users\82105\AppData\Local\Programs\Python\Python39\lib\site-packages\discord\ext\commands\core.py", line 94, in wrapped
    raise CommandInvokeError(exc) from exc
discord.ext.commands.errors.CommandInvokeError: Command raised an exception: Forbidden: 403 Forbidden (error code: 50013): Missing Permissions



20시 52분 / [오류] Traceback (most recent call last):
  File "C:\Users\82105\AppData\Local\Programs\Python\Python39\lib\site-packages\discord\ext\commands\core.py", line 85, in wrapped
    ret = await coro(*args, **kwargs)
  File "c:\Users\82105\Downloads\SetaBot-2.3\cogs\example.py", line 71, in 탕수육
    result = await util_box.ox(self.bot, window, ctx)
  File "c:\Users\82105\Downloads\SetaBot-2.3\utils\util_box.py", line 25, in ox
    await message.clear_reactions()
  File "C:\Users\82105\AppData\Local\Programs\Python\Python39\lib\site-packages\discord\message.py", line 1309, in clear_reactions
    await self._state.http.clear_reactions(self.channel.id, self.id)
  File "C:\Users\82105\AppData\Local\Programs\Python\Python39\lib\site-packages\discord\http.py", line 248, in request
    raise Forbidden(r, data)
discord.errors.Forbidden: 403 Forbidden (error code: 50013): Missing Permissions

The above exception was the direct cause of the following exception:

Traceback (most recent call last):
  File "c:\Users\82105\Downloads\SetaBot-2.3\utils\logger.py", line 22, in err
    raise error
  File "C:\Users\82105\AppData\Local\Programs\Python\Python39\lib\site-packages\discord\ext\commands\bot.py", line 939, in invoke
    await ctx.command.invoke(ctx)
  File "C:\Users\82105\AppData\Local\Programs\Python\Python39\lib\site-packages\discord\ext\commands\core.py", line 863, in invoke
    await injected(*ctx.args, **ctx.kwargs)
  File "C:\Users\82105\AppData\Local\Programs\Python\Python39\lib\site-packages\discord\ext\commands\core.py", line 94, in wrapped
    raise CommandInvokeError(exc) from exc
discord.ext.commands.errors.CommandInvokeError: Command raised an exception: Forbidden: 403 Forbidden (error code: 50013): Missing Permissions



20시 55분 / [오류] Traceback (most recent call last):
  File "C:\Users\82105\AppData\Local\Programs\Python\Python39\lib\site-packages\discord\ext\commands\core.py", line 85, in wrapped
    ret = await coro(*args, **kwargs)
  File "c:\Users\82105\Downloads\SetaBot-2.3\cogs\example.py", line 71, in 탕수육
    result = await util_box.ox(self.bot, window, ctx)
  File "c:\Users\82105\Downloads\SetaBot-2.3\utils\util_box.py", line 28, in ox
    await message.clear_reactions()
  File "C:\Users\82105\AppData\Local\Programs\Python\Python39\lib\site-packages\discord\message.py", line 1309, in clear_reactions
    await self._state.http.clear_reactions(self.channel.id, self.id)
  File "C:\Users\82105\AppData\Local\Programs\Python\Python39\lib\site-packages\discord\http.py", line 248, in request
    raise Forbidden(r, data)
discord.errors.Forbidden: 403 Forbidden (error code: 50013): Missing Permissions

The above exception was the direct cause of the following exception:

Traceback (most recent call last):
  File "c:\Users\82105\Downloads\SetaBot-2.3\utils\logger.py", line 22, in err
    raise error
  File "C:\Users\82105\AppData\Local\Programs\Python\Python39\lib\site-packages\discord\ext\commands\bot.py", line 939, in invoke
    await ctx.command.invoke(ctx)
  File "C:\Users\82105\AppData\Local\Programs\Python\Python39\lib\site-packages\discord\ext\commands\core.py", line 863, in invoke
    await injected(*ctx.args, **ctx.kwargs)
  File "C:\Users\82105\AppData\Local\Programs\Python\Python39\lib\site-packages\discord\ext\commands\core.py", line 94, in wrapped
    raise CommandInvokeError(exc) from exc
discord.ext.commands.errors.CommandInvokeError: Command raised an exception: Forbidden: 403 Forbidden (error code: 50013): Missing Permissions



22시 50분 / [오류] Traceback (most recent call last):
  File "C:\Users\82105\AppData\Local\Programs\Python\Python39\lib\site-packages\discord\ext\commands\core.py", line 85, in wrapped
    ret = await coro(*args, **kwargs)
  File "c:\Users\82105\Downloads\SetaBot-2.3\cogs\CommandBot.py", line 39, in 가위바위보
    await ctx.message.clear_reactions()
  File "C:\Users\82105\AppData\Local\Programs\Python\Python39\lib\site-packages\discord\message.py", line 1309, in clear_reactions
    await self._state.http.clear_reactions(self.channel.id, self.id)
  File "C:\Users\82105\AppData\Local\Programs\Python\Python39\lib\site-packages\discord\http.py", line 248, in request
    raise Forbidden(r, data)
discord.errors.Forbidden: 403 Forbidden (error code: 50013): Missing Permissions

The above exception was the direct cause of the following exception:

Traceback (most recent call last):
  File "c:\Users\82105\Downloads\SetaBot-2.3\utils\logger.py", line 22, in err
    raise error
  File "C:\Users\82105\AppData\Local\Programs\Python\Python39\lib\site-packages\discord\ext\commands\bot.py", line 939, in invoke
    await ctx.command.invoke(ctx)
  File "C:\Users\82105\AppData\Local\Programs\Python\Python39\lib\site-packages\discord\ext\commands\core.py", line 863, in invoke
    await injected(*ctx.args, **ctx.kwargs)
  File "C:\Users\82105\AppData\Local\Programs\Python\Python39\lib\site-packages\discord\ext\commands\core.py", line 94, in wrapped
    raise CommandInvokeError(exc) from exc
discord.ext.commands.errors.CommandInvokeError: Command raised an exception: Forbidden: 403 Forbidden (error code: 50013): Missing Permissions



22시 52분 / [오류] Traceback (most recent call last):
  File "C:\Users\82105\AppData\Local\Programs\Python\Python39\lib\site-packages\discord\ext\commands\core.py", line 85, in wrapped
    ret = await coro(*args, **kwargs)
  File "c:\Users\82105\Downloads\SetaBot-2.3\cogs\CommandBot.py", line 36, in 가위바위보
    await ctx.message.clear_reactions()
  File "C:\Users\82105\AppData\Local\Programs\Python\Python39\lib\site-packages\discord\message.py", line 1309, in clear_reactions
    await self._state.http.clear_reactions(self.channel.id, self.id)
  File "C:\Users\82105\AppData\Local\Programs\Python\Python39\lib\site-packages\discord\http.py", line 248, in request
    raise Forbidden(r, data)
discord.errors.Forbidden: 403 Forbidden (error code: 50013): Missing Permissions

The above exception was the direct cause of the following exception:

Traceback (most recent call last):
  File "c:\Users\82105\Downloads\SetaBot-2.3\utils\logger.py", line 22, in err
    raise error
  File "C:\Users\82105\AppData\Local\Programs\Python\Python39\lib\site-packages\discord\ext\commands\bot.py", line 939, in invoke
    await ctx.command.invoke(ctx)
  File "C:\Users\82105\AppData\Local\Programs\Python\Python39\lib\site-packages\discord\ext\commands\core.py", line 863, in invoke
    await injected(*ctx.args, **ctx.kwargs)
  File "C:\Users\82105\AppData\Local\Programs\Python\Python39\lib\site-packages\discord\ext\commands\core.py", line 94, in wrapped
    raise CommandInvokeError(exc) from exc
discord.ext.commands.errors.CommandInvokeError: Command raised an exception: Forbidden: 403 Forbidden (error code: 50013): Missing Permissions



22시 57분 / [오류] Traceback (most recent call last):
  File "C:\Users\82105\AppData\Local\Programs\Python\Python39\lib\site-packages\discord\ext\commands\core.py", line 85, in wrapped
    ret = await coro(*args, **kwargs)
  File "c:\Users\82105\Downloads\SetaBot-2.3\cogs\CommandBot.py", line 42, in 가위바위보
    await ctx.message.clear_reactions()
  File "C:\Users\82105\AppData\Local\Programs\Python\Python39\lib\site-packages\discord\message.py", line 1309, in clear_reactions
    await self._state.http.clear_reactions(self.channel.id, self.id)
  File "C:\Users\82105\AppData\Local\Programs\Python\Python39\lib\site-packages\discord\http.py", line 248, in request
    raise Forbidden(r, data)
discord.errors.Forbidden: 403 Forbidden (error code: 50013): Missing Permissions

The above exception was the direct cause of the following exception:

Traceback (most recent call last):
  File "c:\Users\82105\Downloads\SetaBot-2.3\utils\logger.py", line 22, in err
    raise error
  File "C:\Users\82105\AppData\Local\Programs\Python\Python39\lib\site-packages\discord\ext\commands\bot.py", line 939, in invoke
    await ctx.command.invoke(ctx)
  File "C:\Users\82105\AppData\Local\Programs\Python\Python39\lib\site-packages\discord\ext\commands\core.py", line 863, in invoke
    await injected(*ctx.args, **ctx.kwargs)
  File "C:\Users\82105\AppData\Local\Programs\Python\Python39\lib\site-packages\discord\ext\commands\core.py", line 94, in wrapped
    raise CommandInvokeError(exc) from exc
discord.ext.commands.errors.CommandInvokeError: Command raised an exception: Forbidden: 403 Forbidden (error code: 50013): Missing Permissions



23시 24분 / [오류] Traceback (most recent call last):
  File "C:\Users\82105\AppData\Local\Programs\Python\Python39\lib\site-packages\discord\ext\commands\core.py", line 85, in wrapped
    ret = await coro(*args, **kwargs)
  File "c:\Users\82105\Downloads\SetaBot-2.3\cogs\CommandBot.py", line 114, in 전적
    embed = discord.Embed(title=message_content + " 님의 플레이어 정보", description="", color=0x62c1cc)
NameError: name 'message_content' is not defined

The above exception was the direct cause of the following exception:

Traceback (most recent call last):
  File "c:\Users\82105\Downloads\SetaBot-2.3\utils\logger.py", line 22, in err
    raise error
  File "C:\Users\82105\AppData\Local\Programs\Python\Python39\lib\site-packages\discord\ext\commands\bot.py", line 939, in invoke
    await ctx.command.invoke(ctx)
  File "C:\Users\82105\AppData\Local\Programs\Python\Python39\lib\site-packages\discord\ext\commands\core.py", line 863, in invoke
    await injected(*ctx.args, **ctx.kwargs)
  File "C:\Users\82105\AppData\Local\Programs\Python\Python39\lib\site-packages\discord\ext\commands\core.py", line 94, in wrapped
    raise CommandInvokeError(exc) from exc
discord.ext.commands.errors.CommandInvokeError: Command raised an exception: NameError: name 'message_content' is not defined



23시 29분 / [오류] Traceback (most recent call last):
  File "C:\Users\82105\AppData\Local\Programs\Python\Python39\lib\site-packages\discord\ext\commands\core.py", line 85, in wrapped
    ret = await coro(*args, **kwargs)
  File "c:\Users\82105\Downloads\SetaBot-2.3\cogs\CommandBot.py", line 94, in 전적
    img = soup.find("div", attrs={"class":"SummonerRatingMedium"}).find("img").get('src')
AttributeError: 'NoneType' object has no attribute 'find'

The above exception was the direct cause of the following exception:

Traceback (most recent call last):
  File "c:\Users\82105\Downloads\SetaBot-2.3\utils\logger.py", line 22, in err
    raise error
  File "C:\Users\82105\AppData\Local\Programs\Python\Python39\lib\site-packages\discord\ext\commands\bot.py", line 939, in invoke
    await ctx.command.invoke(ctx)
  File "C:\Users\82105\AppData\Local\Programs\Python\Python39\lib\site-packages\discord\ext\commands\core.py", line 863, in invoke
    await injected(*ctx.args, **ctx.kwargs)
  File "C:\Users\82105\AppData\Local\Programs\Python\Python39\lib\site-packages\discord\ext\commands\core.py", line 94, in wrapped
    raise CommandInvokeError(exc) from exc
discord.ext.commands.errors.CommandInvokeError: Command raised an exception: AttributeError: 'NoneType' object has no attribute 'find'



