12시 56분 / [오류] Traceback (most recent call last):
  File "C:\Users\82105\AppData\Local\Programs\Python\Python39\lib\site-packages\discord\ext\commands\core.py", line 85, in wrapped
    ret = await coro(*args, **kwargs)
  File "c:\Users\82105\Desktop\Project\Discord\DiscordBot_Gwen\cogs\SearchCommand.py", line 278, in 탑
    chamPro = soup.find("div", attrs={"class":"champion-stats-header-info__image"}).find("img").get("src")
AttributeError: 'NoneType' object has no attribute 'find'

The above exception was the direct cause of the following exception:

Traceback (most recent call last):
  File "c:\Users\82105\Desktop\Project\Discord\DiscordBot_Gwen\utils\logger.py", line 22, in err
    raise error
  File "C:\Users\82105\AppData\Local\Programs\Python\Python39\lib\site-packages\discord\ext\commands\bot.py", line 939, in invoke
    await ctx.command.invoke(ctx)
  File "C:\Users\82105\AppData\Local\Programs\Python\Python39\lib\site-packages\discord\ext\commands\core.py", line 863, in invoke
    await injected(*ctx.args, **ctx.kwargs)
  File "C:\Users\82105\AppData\Local\Programs\Python\Python39\lib\site-packages\discord\ext\commands\core.py", line 94, in wrapped
    raise CommandInvokeError(exc) from exc
discord.ext.commands.errors.CommandInvokeError: Command raised an exception: AttributeError: 'NoneType' object has no attribute 'find'



13시 20분 / [오류] Traceback (most recent call last):
  File "C:\Users\82105\AppData\Local\Programs\Python\Python39\lib\site-packages\discord\ext\commands\core.py", line 85, in wrapped
    ret = await coro(*args, **kwargs)
  File "c:\Users\82105\Desktop\Project\Discord\DiscordBot_Gwen\cogs\SearchCommand.py", line 124, in 챔피언
    chamPro = soup.find("div", attrs={"class":"champion-stats-header-info__image"}).find("img").get("src")
AttributeError: 'NoneType' object has no attribute 'find'

The above exception was the direct cause of the following exception:

Traceback (most recent call last):
  File "c:\Users\82105\Desktop\Project\Discord\DiscordBot_Gwen\utils\logger.py", line 13, in err
    raise error
  File "C:\Users\82105\AppData\Local\Programs\Python\Python39\lib\site-packages\discord\ext\commands\bot.py", line 939, in invoke
    await ctx.command.invoke(ctx)
  File "C:\Users\82105\AppData\Local\Programs\Python\Python39\lib\site-packages\discord\ext\commands\core.py", line 863, in invoke
    await injected(*ctx.args, **ctx.kwargs)
  File "C:\Users\82105\AppData\Local\Programs\Python\Python39\lib\site-packages\discord\ext\commands\core.py", line 94, in wrapped
    raise CommandInvokeError(exc) from exc
discord.ext.commands.errors.CommandInvokeError: Command raised an exception: AttributeError: 'NoneType' object has no attribute 'find'



