08시 42분 / [정보] ======================
08시 42분 / [정보] < 구동 완료 >
08시 42분 / [정보] ======================
08시 44분 / [정보] c:\Users\82105\Downloads\SetaBot-2.3\cogs\CommandBot.py 로드 완료
08시 44분 / [정보] c:\Users\82105\Downloads\SetaBot-2.3\cogs\event.py 로드 완료
08시 44분 / [정보] ======================
08시 44분 / [정보] < 구동 완료 >
08시 44분 / [정보] ======================
08시 44분 / 병신들 <실험 | 하리하루 | 758963978331619331> 그웬아 가위바위보
08시 50분 / 병신들 <실험 | 하리하루 | 758963978331619331> !restart
08시 50분 / [정보] c:\Users\82105\Downloads\SetaBot-2.3\cogs\CommandBot.py 로드 완료
08시 50분 / [정보] 'CommandBot' 다시 불러옴
08시 50분 / [정보] c:\Users\82105\Downloads\SetaBot-2.3\cogs\event.py 로드 완료
08시 50분 / [정보] 'event' 다시 불러옴
08시 50분 / [오류] Traceback (most recent call last):
  File "C:\Users\82105\AppData\Local\Programs\Python\Python39\lib\site-packages\discord\ext\commands\core.py", line 85, in wrapped
    ret = await coro(*args, **kwargs)
  File "c:\Users\82105\Downloads\SetaBot-2.3\main.py", line 60, in restart
    self.bot.reload_extension(f"cogs.{i}")
  File "C:\Users\82105\AppData\Local\Programs\Python\Python39\lib\site-packages\discord\ext\commands\bot.py", line 759, in reload_extension
    raise errors.ExtensionNotLoaded(name)
discord.ext.commands.errors.ExtensionNotLoaded: Extension 'cogs.__init__' has not been loaded.

The above exception was the direct cause of the following exception:

Traceback (most recent call last):
  File "c:\Users\82105\Downloads\SetaBot-2.3\utils\logger.py", line 22, in err
    raise error
  File "C:\Users\82105\AppData\Local\Programs\Python\Python39\lib\site-packages\discord\ext\commands\bot.py", line 939, in invoke
    await ctx.command.invoke(ctx)
  File "C:\Users\82105\AppData\Local\Programs\Python\Python39\lib\site-packages\discord\ext\commands\core.py", line 863, in invoke
    await injected(*ctx.args, **ctx.kwargs)
  File "C:\Users\82105\AppData\Local\Programs\Python\Python39\lib\site-packages\discord\ext\commands\core.py", line 94, in wrapped
    raise CommandInvokeError(exc) from exc
discord.ext.commands.errors.CommandInvokeError: Command raised an exception: ExtensionNotLoaded: Extension 'cogs.__init__' has not been loaded.



09시 00분 / [정보] c:\Users\82105\Downloads\SetaBot-2.3\cogs\AdminCommand.py 로드 완료
09시 00분 / [정보] c:\Users\82105\Downloads\SetaBot-2.3\cogs\CommandBot.py 로드 완료
09시 00분 / [정보] c:\Users\82105\Downloads\SetaBot-2.3\cogs\event.py 로드 완료
09시 00분 / [정보] ======================
09시 00분 / [정보] < 구동 완료 >
09시 00분 / [정보] ======================
09시 01분 / 병신들 <실험 | 하리하루 | 758963978331619331> !가위바위보
09시 01분 / 병신들 <실험 | 하리하루 | 758963978331619331> !restart
09시 01분 / [정보] c:\Users\82105\Downloads\SetaBot-2.3\cogs\AdminCommand.py 로드 완료
09시 01분 / [정보] 'AdminCommand' 다시 불러옴
09시 01분 / [정보] c:\Users\82105\Downloads\SetaBot-2.3\cogs\CommandBot.py 로드 완료
09시 01분 / [정보] 'CommandBot' 다시 불러옴
09시 01분 / [정보] c:\Users\82105\Downloads\SetaBot-2.3\cogs\event.py 로드 완료
09시 01분 / [정보] 'event' 다시 불러옴
09시 01분 / [오류] Traceback (most recent call last):
  File "C:\Users\82105\AppData\Local\Programs\Python\Python39\lib\site-packages\discord\ext\commands\core.py", line 85, in wrapped
    ret = await coro(*args, **kwargs)
  File "c:\Users\82105\Downloads\SetaBot-2.3\cogs\AdminCommand.py", line 26, in restart
    self.bot.reload_extension(f"cogs.{i}")
  File "C:\Users\82105\AppData\Local\Programs\Python\Python39\lib\site-packages\discord\ext\commands\bot.py", line 759, in reload_extension
    raise errors.ExtensionNotLoaded(name)
discord.ext.commands.errors.ExtensionNotLoaded: Extension 'cogs.__init__' has not been loaded.

The above exception was the direct cause of the following exception:

Traceback (most recent call last):
  File "c:\Users\82105\Downloads\SetaBot-2.3\utils\logger.py", line 22, in err
    raise error
  File "C:\Users\82105\AppData\Local\Programs\Python\Python39\lib\site-packages\discord\ext\commands\bot.py", line 939, in invoke
    await ctx.command.invoke(ctx)
  File "C:\Users\82105\AppData\Local\Programs\Python\Python39\lib\site-packages\discord\ext\commands\core.py", line 863, in invoke
    await injected(*ctx.args, **ctx.kwargs)
  File "C:\Users\82105\AppData\Local\Programs\Python\Python39\lib\site-packages\discord\ext\commands\core.py", line 94, in wrapped
    raise CommandInvokeError(exc) from exc
discord.ext.commands.errors.CommandInvokeError: Command raised an exception: ExtensionNotLoaded: Extension 'cogs.__init__' has not been loaded.



09시 06분 / [정보] c:\Users\82105\Downloads\SetaBot-2.3\cogs\AdminCommand.py 로드 완료
09시 06분 / [정보] c:\Users\82105\Downloads\SetaBot-2.3\cogs\CommandBot.py 로드 완료
09시 06분 / [정보] c:\Users\82105\Downloads\SetaBot-2.3\cogs\event.py 로드 완료
09시 06분 / [정보] ======================
09시 06분 / [정보] < 구동 완료 >
09시 06분 / [정보] ======================
09시 09분 / [정보] c:\Users\82105\Downloads\SetaBot-2.3\cogs\AdminCommand.py 로드 완료
09시 09분 / [정보] c:\Users\82105\Downloads\SetaBot-2.3\cogs\CommandBot.py 로드 완료
09시 09분 / [정보] c:\Users\82105\Downloads\SetaBot-2.3\cogs\event.py 로드 완료
09시 09분 / [정보] ======================
09시 09분 / [정보] < 구동 완료 >
09시 09분 / [정보] ======================
09시 10분 / 병신들 <실험 | 하리하루 | 758963978331619331> !eval
09시 10분 / [오류] Traceback (most recent call last):
  File "C:\Users\82105\AppData\Local\Programs\Python\Python39\lib\site-packages\discord\ext\commands\core.py", line 85, in wrapped
    ret = await coro(*args, **kwargs)
  File "c:\Users\82105\Downloads\SetaBot-2.3\cogs\AdminCommand.py", line 73, in eval
    me = User(ctx.author)
  File "c:\Users\82105\Downloads\SetaBot-2.3\classes\user.py", line 41, in __init__
    self.load()
  File "c:\Users\82105\Downloads\SetaBot-2.3\classes\user.py", line 57, in load
    data = self._load_data()
  File "c:\Users\82105\Downloads\SetaBot-2.3\classes\user.py", line 71, in _load_data
    return db.select_sql(
  File "c:\Users\82105\Downloads\SetaBot-2.3\utils\sqlite_class.py", line 65, in select_sql
    return self.sql("SELECT " + rec + " FROM " + table + ' ' + rule, True)
  File "c:\Users\82105\Downloads\SetaBot-2.3\utils\sqlite_class.py", line 98, in sql
    self.cur.execute(qur)
sqlite3.OperationalError: no such table: users

The above exception was the direct cause of the following exception:

Traceback (most recent call last):
  File "c:\Users\82105\Downloads\SetaBot-2.3\utils\logger.py", line 22, in err
    raise error
  File "C:\Users\82105\AppData\Local\Programs\Python\Python39\lib\site-packages\discord\ext\commands\bot.py", line 939, in invoke
    await ctx.command.invoke(ctx)
  File "C:\Users\82105\AppData\Local\Programs\Python\Python39\lib\site-packages\discord\ext\commands\core.py", line 863, in invoke
    await injected(*ctx.args, **ctx.kwargs)
  File "C:\Users\82105\AppData\Local\Programs\Python\Python39\lib\site-packages\discord\ext\commands\core.py", line 94, in wrapped
    raise CommandInvokeError(exc) from exc
discord.ext.commands.errors.CommandInvokeError: Command raised an exception: OperationalError: no such table: users



09시 10분 / 병신들 <실험 | 하리하루 | 758963978331619331> !exec
09시 10분 / [오류] Traceback (most recent call last):
  File "C:\Users\82105\AppData\Local\Programs\Python\Python39\lib\site-packages\discord\ext\commands\core.py", line 85, in wrapped
    ret = await coro(*args, **kwargs)
  File "c:\Users\82105\Downloads\SetaBot-2.3\cogs\AdminCommand.py", line 39, in exec
    me = User(ctx.author)
  File "c:\Users\82105\Downloads\SetaBot-2.3\classes\user.py", line 41, in __init__
    self.load()
  File "c:\Users\82105\Downloads\SetaBot-2.3\classes\user.py", line 57, in load
    data = self._load_data()
  File "c:\Users\82105\Downloads\SetaBot-2.3\classes\user.py", line 71, in _load_data
    return db.select_sql(
  File "c:\Users\82105\Downloads\SetaBot-2.3\utils\sqlite_class.py", line 65, in select_sql
    return self.sql("SELECT " + rec + " FROM " + table + ' ' + rule, True)
  File "c:\Users\82105\Downloads\SetaBot-2.3\utils\sqlite_class.py", line 98, in sql
    self.cur.execute(qur)
sqlite3.OperationalError: no such table: users

The above exception was the direct cause of the following exception:

Traceback (most recent call last):
  File "c:\Users\82105\Downloads\SetaBot-2.3\utils\logger.py", line 22, in err
    raise error
  File "C:\Users\82105\AppData\Local\Programs\Python\Python39\lib\site-packages\discord\ext\commands\bot.py", line 939, in invoke
    await ctx.command.invoke(ctx)
  File "C:\Users\82105\AppData\Local\Programs\Python\Python39\lib\site-packages\discord\ext\commands\core.py", line 863, in invoke
    await injected(*ctx.args, **ctx.kwargs)
  File "C:\Users\82105\AppData\Local\Programs\Python\Python39\lib\site-packages\discord\ext\commands\core.py", line 94, in wrapped
    raise CommandInvokeError(exc) from exc
discord.ext.commands.errors.CommandInvokeError: Command raised an exception: OperationalError: no such table: users



09시 10분 / 병신들 <실험 | 하리하루 | 758963978331619331> !restart
09시 10분 / [정보] c:\Users\82105\Downloads\SetaBot-2.3\cogs\AdminCommand.py 로드 완료
09시 10분 / [정보] 'AdminCommand' 다시 불러옴
09시 10분 / [정보] c:\Users\82105\Downloads\SetaBot-2.3\cogs\CommandBot.py 로드 완료
09시 10분 / [정보] 'CommandBot' 다시 불러옴
09시 10분 / [정보] c:\Users\82105\Downloads\SetaBot-2.3\cogs\event.py 로드 완료
09시 10분 / [정보] 'event' 다시 불러옴
09시 10분 / [오류] Traceback (most recent call last):
  File "C:\Users\82105\AppData\Local\Programs\Python\Python39\lib\site-packages\discord\ext\commands\core.py", line 85, in wrapped
    ret = await coro(*args, **kwargs)
  File "c:\Users\82105\Downloads\SetaBot-2.3\cogs\AdminCommand.py", line 26, in restart
    self.bot.reload_extension(f"cogs.{i}")
  File "C:\Users\82105\AppData\Local\Programs\Python\Python39\lib\site-packages\discord\ext\commands\bot.py", line 759, in reload_extension
    raise errors.ExtensionNotLoaded(name)
discord.ext.commands.errors.ExtensionNotLoaded: Extension 'cogs.__init__' has not been loaded.

The above exception was the direct cause of the following exception:

Traceback (most recent call last):
  File "c:\Users\82105\Downloads\SetaBot-2.3\utils\logger.py", line 22, in err
    raise error
  File "C:\Users\82105\AppData\Local\Programs\Python\Python39\lib\site-packages\discord\ext\commands\bot.py", line 939, in invoke
    await ctx.command.invoke(ctx)
  File "C:\Users\82105\AppData\Local\Programs\Python\Python39\lib\site-packages\discord\ext\commands\core.py", line 863, in invoke
    await injected(*ctx.args, **ctx.kwargs)
  File "C:\Users\82105\AppData\Local\Programs\Python\Python39\lib\site-packages\discord\ext\commands\core.py", line 94, in wrapped
    raise CommandInvokeError(exc) from exc
discord.ext.commands.errors.CommandInvokeError: Command raised an exception: ExtensionNotLoaded: Extension 'cogs.__init__' has not been loaded.



09시 13분 / [정보] c:\Users\82105\Downloads\SetaBot-2.3\cogs\AdminCommand.py 로드 완료
09시 13분 / [정보] c:\Users\82105\Downloads\SetaBot-2.3\cogs\CommandBot.py 로드 완료
09시 13분 / [정보] c:\Users\82105\Downloads\SetaBot-2.3\cogs\event.py 로드 완료
09시 13분 / [정보] ======================
09시 13분 / [정보] < 구동 완료 >
09시 13분 / [정보] ======================
09시 15분 / [정보] c:\Users\82105\Desktop\Project\Discord\DiscordBot_Gwen\cogs\AdminCommand.py 로드 완료
09시 15분 / [정보] c:\Users\82105\Desktop\Project\Discord\DiscordBot_Gwen\cogs\CommandBot.py 로드 완료
09시 15분 / [정보] c:\Users\82105\Desktop\Project\Discord\DiscordBot_Gwen\cogs\event.py 로드 완료
09시 15분 / [정보] ======================
09시 15분 / [정보] < 구동 완료 >
09시 15분 / [정보] ======================
09시 15분 / 병신들 <실험 | 하리하루 | 758963978331619331> !restart
09시 15분 / [정보] c:\Users\82105\Desktop\Project\Discord\DiscordBot_Gwen\cogs\AdminCommand.py 로드 완료
09시 15분 / [정보] 'AdminCommand' 다시 불러옴
09시 15분 / [정보] c:\Users\82105\Desktop\Project\Discord\DiscordBot_Gwen\cogs\CommandBot.py 로드 완료
09시 15분 / [정보] 'CommandBot' 다시 불러옴
09시 15분 / [정보] c:\Users\82105\Desktop\Project\Discord\DiscordBot_Gwen\cogs\event.py 로드 완료
09시 15분 / [정보] 'event' 다시 불러옴
09시 15분 / [오류] Traceback (most recent call last):
  File "C:\Users\82105\AppData\Local\Programs\Python\Python39\lib\site-packages\discord\ext\commands\core.py", line 85, in wrapped
    ret = await coro(*args, **kwargs)
  File "c:\Users\82105\Desktop\Project\Discord\DiscordBot_Gwen\cogs\AdminCommand.py", line 26, in restart
    self.bot.reload_extension(f"cogs.{i}")
  File "C:\Users\82105\AppData\Local\Programs\Python\Python39\lib\site-packages\discord\ext\commands\bot.py", line 759, in reload_extension
    raise errors.ExtensionNotLoaded(name)
discord.ext.commands.errors.ExtensionNotLoaded: Extension 'cogs.__init__' has not been loaded.

The above exception was the direct cause of the following exception:

Traceback (most recent call last):
  File "c:\Users\82105\Desktop\Project\Discord\DiscordBot_Gwen\utils\logger.py", line 22, in err
    raise error
  File "C:\Users\82105\AppData\Local\Programs\Python\Python39\lib\site-packages\discord\ext\commands\bot.py", line 939, in invoke
    await ctx.command.invoke(ctx)
  File "C:\Users\82105\AppData\Local\Programs\Python\Python39\lib\site-packages\discord\ext\commands\core.py", line 863, in invoke
    await injected(*ctx.args, **ctx.kwargs)
  File "C:\Users\82105\AppData\Local\Programs\Python\Python39\lib\site-packages\discord\ext\commands\core.py", line 94, in wrapped
    raise CommandInvokeError(exc) from exc
discord.ext.commands.errors.CommandInvokeError: Command raised an exception: ExtensionNotLoaded: Extension 'cogs.__init__' has not been loaded.



09시 16분 / 병신들 <실험 | 하리하루 | 758963978331619331> !가위바위보
09시 19분 / [정보] c:\Users\82105\Desktop\Project\Discord\DiscordBot_Gwen\cogs\AdminCommand.py 로드 완료
09시 19분 / [정보] c:\Users\82105\Desktop\Project\Discord\DiscordBot_Gwen\cogs\CommandBot.py 로드 완료
09시 19분 / [정보] c:\Users\82105\Desktop\Project\Discord\DiscordBot_Gwen\cogs\event.py 로드 완료
09시 19분 / [정보] ======================
09시 19분 / [정보] < 구동 완료 >
09시 19분 / [정보] ======================
09시 19분 / 병신들 <실험 | 하리하루 | 758963978331619331> !restart
09시 19분 / [정보] c:\Users\82105\Desktop\Project\Discord\DiscordBot_Gwen\cogs\AdminCommand.py 로드 완료
09시 19분 / [정보] 'AdminCommand' 다시 불러옴
09시 19분 / [정보] c:\Users\82105\Desktop\Project\Discord\DiscordBot_Gwen\cogs\CommandBot.py 로드 완료
09시 19분 / [정보] 'CommandBot' 다시 불러옴
09시 19분 / [정보] c:\Users\82105\Desktop\Project\Discord\DiscordBot_Gwen\cogs\event.py 로드 완료
09시 19분 / [정보] 'event' 다시 불러옴
09시 19분 / 병신들 <실험 | 하리하루 | 758963978331619331> !가위바위보
09시 23분 / 병신들 <실험 | 하리하루 | 758963978331619331> !eval
09시 23분 / [오류] Traceback (most recent call last):
  File "C:\Users\82105\AppData\Local\Programs\Python\Python39\lib\site-packages\discord\ext\commands\core.py", line 85, in wrapped
    ret = await coro(*args, **kwargs)
  File "c:\Users\82105\Desktop\Project\Discord\DiscordBot_Gwen\cogs\AdminCommand.py", line 73, in eval
    me = User(ctx.author)
  File "c:\Users\82105\Desktop\Project\Discord\DiscordBot_Gwen\classes\user.py", line 41, in __init__
    self.load()
  File "c:\Users\82105\Desktop\Project\Discord\DiscordBot_Gwen\classes\user.py", line 57, in load
    data = self._load_data()
  File "c:\Users\82105\Desktop\Project\Discord\DiscordBot_Gwen\classes\user.py", line 71, in _load_data
    return db.select_sql(
  File "c:\Users\82105\Desktop\Project\Discord\DiscordBot_Gwen\utils\sqlite_class.py", line 65, in select_sql
    return self.sql("SELECT " + rec + " FROM " + table + ' ' + rule, True)
  File "c:\Users\82105\Desktop\Project\Discord\DiscordBot_Gwen\utils\sqlite_class.py", line 98, in sql
    self.cur.execute(qur)
sqlite3.OperationalError: no such table: users

The above exception was the direct cause of the following exception:

Traceback (most recent call last):
  File "c:\Users\82105\Desktop\Project\Discord\DiscordBot_Gwen\utils\logger.py", line 22, in err
    raise error
  File "C:\Users\82105\AppData\Local\Programs\Python\Python39\lib\site-packages\discord\ext\commands\bot.py", line 939, in invoke
    await ctx.command.invoke(ctx)
  File "C:\Users\82105\AppData\Local\Programs\Python\Python39\lib\site-packages\discord\ext\commands\core.py", line 863, in invoke
    await injected(*ctx.args, **ctx.kwargs)
  File "C:\Users\82105\AppData\Local\Programs\Python\Python39\lib\site-packages\discord\ext\commands\core.py", line 94, in wrapped
    raise CommandInvokeError(exc) from exc
discord.ext.commands.errors.CommandInvokeError: Command raised an exception: OperationalError: no such table: users



09시 25분 / 병신들 <실험 | 하리하루 | 758963978331619331> !전적 시리하루
09시 26분 / 병신들 <실험 | 하리하루 | 758963978331619331> !restart
09시 26분 / [정보] c:\Users\82105\Desktop\Project\Discord\DiscordBot_Gwen\cogs\AdminCommand.py 로드 완료
09시 26분 / [정보] 'AdminCommand' 다시 불러옴
09시 26분 / [정보] c:\Users\82105\Desktop\Project\Discord\DiscordBot_Gwen\cogs\event.py 로드 완료
09시 26분 / [정보] 'event' 다시 불러옴
09시 26분 / [오류] Traceback (most recent call last):
  File "C:\Users\82105\AppData\Local\Programs\Python\Python39\lib\site-packages\discord\ext\commands\core.py", line 85, in wrapped
    ret = await coro(*args, **kwargs)
  File "c:\Users\82105\Desktop\Project\Discord\DiscordBot_Gwen\cogs\AdminCommand.py", line 26, in restart
    self.bot.reload_extension(f"cogs.{i}")
  File "C:\Users\82105\AppData\Local\Programs\Python\Python39\lib\site-packages\discord\ext\commands\bot.py", line 759, in reload_extension
    raise errors.ExtensionNotLoaded(name)
discord.ext.commands.errors.ExtensionNotLoaded: Extension 'cogs.NormalCommandBot' has not been loaded.

The above exception was the direct cause of the following exception:

Traceback (most recent call last):
  File "c:\Users\82105\Desktop\Project\Discord\DiscordBot_Gwen\utils\logger.py", line 22, in err
    raise error
  File "C:\Users\82105\AppData\Local\Programs\Python\Python39\lib\site-packages\discord\ext\commands\bot.py", line 939, in invoke
    await ctx.command.invoke(ctx)
  File "C:\Users\82105\AppData\Local\Programs\Python\Python39\lib\site-packages\discord\ext\commands\core.py", line 863, in invoke
    await injected(*ctx.args, **ctx.kwargs)
  File "C:\Users\82105\AppData\Local\Programs\Python\Python39\lib\site-packages\discord\ext\commands\core.py", line 94, in wrapped
    raise CommandInvokeError(exc) from exc
discord.ext.commands.errors.CommandInvokeError: Command raised an exception: ExtensionNotLoaded: Extension 'cogs.NormalCommandBot' has not been loaded.



09시 26분 / [정보] c:\Users\82105\Desktop\Project\Discord\DiscordBot_Gwen\cogs\AdminCommand.py 로드 완료
09시 26분 / [정보] c:\Users\82105\Desktop\Project\Discord\DiscordBot_Gwen\cogs\event.py 로드 완료
09시 26분 / [정보] c:\Users\82105\Desktop\Project\Discord\DiscordBot_Gwen\cogs\NormalCommandBot.py 로드 완료
09시 26분 / [정보] ======================
09시 26분 / [정보] < 구동 완료 >
09시 26분 / [정보] ======================
09시 26분 / 병신들 <실험 | 하리하루 | 758963978331619331> !restart
09시 26분 / [정보] c:\Users\82105\Desktop\Project\Discord\DiscordBot_Gwen\cogs\AdminCommand.py 로드 완료
09시 26분 / [정보] 'AdminCommand' 다시 불러옴
09시 26분 / [정보] c:\Users\82105\Desktop\Project\Discord\DiscordBot_Gwen\cogs\event.py 로드 완료
09시 26분 / [정보] 'event' 다시 불러옴
09시 26분 / [정보] c:\Users\82105\Desktop\Project\Discord\DiscordBot_Gwen\cogs\NormalCommandBot.py 로드 완료
09시 26분 / [정보] 'NormalCommandBot' 다시 불러옴
09시 34분 / 병신들 <실험 | 하리하루 | 758963978331619331> !restart
09시 34분 / [정보] c:\Users\82105\Desktop\Project\Discord\DiscordBot_Gwen\cogs\AdminCommand.py 로드 완료
09시 34분 / [정보] 'AdminCommand' 다시 불러옴
09시 34분 / [정보] c:\Users\82105\Desktop\Project\Discord\DiscordBot_Gwen\cogs\event.py 로드 완료
09시 34분 / [정보] 'event' 다시 불러옴
09시 34분 / [정보] c:\Users\82105\Desktop\Project\Discord\DiscordBot_Gwen\cogs\NormalCommandBot.py 로드 완료
09시 34분 / [정보] 'NormalCommandBot' 다시 불러옴
09시 34분 / [오류] Traceback (most recent call last):
  File "C:\Users\82105\AppData\Local\Programs\Python\Python39\lib\site-packages\discord\ext\commands\core.py", line 85, in wrapped
    ret = await coro(*args, **kwargs)
  File "c:\Users\82105\Desktop\Project\Discord\DiscordBot_Gwen\cogs\AdminCommand.py", line 26, in restart
    self.bot.reload_extension(f"cogs.{i}")
  File "C:\Users\82105\AppData\Local\Programs\Python\Python39\lib\site-packages\discord\ext\commands\bot.py", line 759, in reload_extension
    raise errors.ExtensionNotLoaded(name)
discord.ext.commands.errors.ExtensionNotLoaded: Extension 'cogs.SearchCommand' has not been loaded.

The above exception was the direct cause of the following exception:

Traceback (most recent call last):
  File "c:\Users\82105\Desktop\Project\Discord\DiscordBot_Gwen\utils\logger.py", line 22, in err
    raise error
  File "C:\Users\82105\AppData\Local\Programs\Python\Python39\lib\site-packages\discord\ext\commands\bot.py", line 939, in invoke
    await ctx.command.invoke(ctx)
  File "C:\Users\82105\AppData\Local\Programs\Python\Python39\lib\site-packages\discord\ext\commands\core.py", line 863, in invoke
    await injected(*ctx.args, **ctx.kwargs)
  File "C:\Users\82105\AppData\Local\Programs\Python\Python39\lib\site-packages\discord\ext\commands\core.py", line 94, in wrapped
    raise CommandInvokeError(exc) from exc
discord.ext.commands.errors.CommandInvokeError: Command raised an exception: ExtensionNotLoaded: Extension 'cogs.SearchCommand' has not been loaded.



09시 34분 / [정보] c:\Users\82105\Desktop\Project\Discord\DiscordBot_Gwen\cogs\AdminCommand.py 로드 완료
09시 34분 / [정보] c:\Users\82105\Desktop\Project\Discord\DiscordBot_Gwen\cogs\event.py 로드 완료
09시 34분 / [정보] c:\Users\82105\Desktop\Project\Discord\DiscordBot_Gwen\cogs\NormalCommandBot.py 로드 완료
09시 38분 / [정보] c:\Users\82105\Desktop\Project\Discord\DiscordBot_Gwen\cogs\AdminCommand.py 로드 완료
09시 38분 / [정보] c:\Users\82105\Desktop\Project\Discord\DiscordBot_Gwen\cogs\event.py 로드 완료
09시 38분 / [정보] c:\Users\82105\Desktop\Project\Discord\DiscordBot_Gwen\cogs\NormalCommandBot.py 로드 완료
09시 43분 / [정보] c:\Users\82105\Desktop\Project\Discord\DiscordBot_Gwen\cogs\AdminCommand.py 로드 완료
09시 43분 / [정보] c:\Users\82105\Desktop\Project\Discord\DiscordBot_Gwen\cogs\event.py 로드 완료
09시 43분 / [정보] c:\Users\82105\Desktop\Project\Discord\DiscordBot_Gwen\cogs\NormalCommandBot.py 로드 완료
09시 43분 / [정보] c:\Users\82105\Desktop\Project\Discord\DiscordBot_Gwen\cogs\SearchCommand.py 로드 완료
09시 43분 / [정보] ======================
09시 43분 / [정보] < 구동 완료 >
09시 43분 / [정보] ======================
10시 06분 / 병신들 <실험 | 하리하루 | 758963978331619331> !restart
10시 06분 / [정보] c:\Users\82105\Desktop\Project\Discord\DiscordBot_Gwen\cogs\AdminCommand.py 로드 완료
10시 06분 / [정보] 'AdminCommand' 다시 불러옴
10시 06분 / [정보] c:\Users\82105\Desktop\Project\Discord\DiscordBot_Gwen\cogs\event.py 로드 완료
10시 06분 / [정보] 'event' 다시 불러옴
10시 06분 / [정보] c:\Users\82105\Desktop\Project\Discord\DiscordBot_Gwen\cogs\NormalCommandBot.py 로드 완료
10시 06분 / [정보] 'NormalCommandBot' 다시 불러옴
10시 06분 / [정보] c:\Users\82105\Desktop\Project\Discord\DiscordBot_Gwen\cogs\SearchCommand.py 로드 완료
10시 06분 / [정보] 'SearchCommand' 다시 불러옴
10시 06분 / 병신들 <실험 | 하리하루 | 758963978331619331> !전적 Archetto
10시 06분 / 병신들 <실험 | 하리하루 | 758963978331619331> !restart
10시 06분 / [정보] c:\Users\82105\Desktop\Project\Discord\DiscordBot_Gwen\cogs\AdminCommand.py 로드 완료
10시 06분 / [정보] 'AdminCommand' 다시 불러옴
10시 06분 / [정보] c:\Users\82105\Desktop\Project\Discord\DiscordBot_Gwen\cogs\event.py 로드 완료
10시 06분 / [정보] 'event' 다시 불러옴
10시 06분 / [정보] c:\Users\82105\Desktop\Project\Discord\DiscordBot_Gwen\cogs\NormalCommandBot.py 로드 완료
10시 06분 / [정보] 'NormalCommandBot' 다시 불러옴
10시 06분 / [정보] c:\Users\82105\Desktop\Project\Discord\DiscordBot_Gwen\cogs\SearchCommand.py 로드 완료
10시 06분 / [정보] 'SearchCommand' 다시 불러옴
10시 06분 / 병신들 <실험 | 하리하루 | 758963978331619331> !전적 Archetto
10시 07분 / 병신들 <실험 | 하리하루 | 758963978331619331> !restart
10시 07분 / [정보] c:\Users\82105\Desktop\Project\Discord\DiscordBot_Gwen\cogs\AdminCommand.py 로드 완료
10시 07분 / [정보] 'AdminCommand' 다시 불러옴
10시 07분 / [정보] c:\Users\82105\Desktop\Project\Discord\DiscordBot_Gwen\cogs\event.py 로드 완료
10시 07분 / [정보] 'event' 다시 불러옴
10시 07분 / [정보] c:\Users\82105\Desktop\Project\Discord\DiscordBot_Gwen\cogs\NormalCommandBot.py 로드 완료
10시 07분 / [정보] 'NormalCommandBot' 다시 불러옴
10시 07분 / [정보] c:\Users\82105\Desktop\Project\Discord\DiscordBot_Gwen\cogs\SearchCommand.py 로드 완료
10시 07분 / [정보] 'SearchCommand' 다시 불러옴
10시 07분 / 병신들 <실험 | 하리하루 | 758963978331619331> !전적 Archetto
10시 07분 / 병신들 <실험 | 하리하루 | 758963978331619331> 애미
10시 07분 / 병신들 <실험 | 하리하루 | 758963978331619331> 존나크네
10시 24분 / 병신들 <실험 | 하리하루 | 758963978331619331> !restart
10시 24분 / [정보] c:\Users\82105\Desktop\Project\Discord\DiscordBot_Gwen\cogs\AdminCommand.py 로드 완료
10시 24분 / [정보] 'AdminCommand' 다시 불러옴
10시 24분 / [정보] c:\Users\82105\Desktop\Project\Discord\DiscordBot_Gwen\cogs\event.py 로드 완료
10시 24분 / [정보] 'event' 다시 불러옴
10시 24분 / [정보] c:\Users\82105\Desktop\Project\Discord\DiscordBot_Gwen\cogs\NormalCommandBot.py 로드 완료
10시 24분 / [정보] 'NormalCommandBot' 다시 불러옴
10시 24분 / [정보] c:\Users\82105\Desktop\Project\Discord\DiscordBot_Gwen\cogs\SearchCommand.py 로드 완료
10시 24분 / [정보] 'SearchCommand' 다시 불러옴
10시 24분 / 병신들 <실험 | 하리하루 | 758963978331619331> !전적 시리하루
10시 24분 / 병신들 <실험 | 하리하루 | 758963978331619331> !restart
10시 24분 / [정보] c:\Users\82105\Desktop\Project\Discord\DiscordBot_Gwen\cogs\AdminCommand.py 로드 완료
10시 24분 / [정보] 'AdminCommand' 다시 불러옴
10시 24분 / [정보] c:\Users\82105\Desktop\Project\Discord\DiscordBot_Gwen\cogs\event.py 로드 완료
10시 24분 / [정보] 'event' 다시 불러옴
10시 24분 / [정보] c:\Users\82105\Desktop\Project\Discord\DiscordBot_Gwen\cogs\NormalCommandBot.py 로드 완료
10시 24분 / [정보] 'NormalCommandBot' 다시 불러옴
10시 24분 / [정보] c:\Users\82105\Desktop\Project\Discord\DiscordBot_Gwen\cogs\SearchCommand.py 로드 완료
10시 24분 / [정보] 'SearchCommand' 다시 불러옴
10시 25분 / 병신들 <실험 | 하리하루 | 758963978331619331> !전적 Archetto
10시 25분 / [오류] Traceback (most recent call last):
  File "C:\Users\82105\AppData\Local\Programs\Python\Python39\lib\site-packages\discord\ext\commands\core.py", line 85, in wrapped
    ret = await coro(*args, **kwargs)
  File "c:\Users\82105\Desktop\Project\Discord\DiscordBot_Gwen\cogs\SearchCommand.py", line 28, in 전적
    price = soup.find("soup", attrs={"class":"ranking"}).get_text()
AttributeError: 'NoneType' object has no attribute 'get_text'

The above exception was the direct cause of the following exception:

Traceback (most recent call last):
  File "c:\Users\82105\Desktop\Project\Discord\DiscordBot_Gwen\utils\logger.py", line 22, in err
    raise error
  File "C:\Users\82105\AppData\Local\Programs\Python\Python39\lib\site-packages\discord\ext\commands\bot.py", line 939, in invoke
    await ctx.command.invoke(ctx)
  File "C:\Users\82105\AppData\Local\Programs\Python\Python39\lib\site-packages\discord\ext\commands\core.py", line 863, in invoke
    await injected(*ctx.args, **ctx.kwargs)
  File "C:\Users\82105\AppData\Local\Programs\Python\Python39\lib\site-packages\discord\ext\commands\core.py", line 94, in wrapped
    raise CommandInvokeError(exc) from exc
discord.ext.commands.errors.CommandInvokeError: Command raised an exception: AttributeError: 'NoneType' object has no attribute 'get_text'



10시 25분 / 병신들 <실험 | 하리하루 | 758963978331619331> !전적 Archetto
10시 25분 / [오류] Traceback (most recent call last):
  File "C:\Users\82105\AppData\Local\Programs\Python\Python39\lib\site-packages\discord\ext\commands\core.py", line 85, in wrapped
    ret = await coro(*args, **kwargs)
  File "c:\Users\82105\Desktop\Project\Discord\DiscordBot_Gwen\cogs\SearchCommand.py", line 28, in 전적
    price = soup.find("soup", attrs={"class":"ranking"}).get_text().strip()
AttributeError: 'NoneType' object has no attribute 'get_text'

The above exception was the direct cause of the following exception:

Traceback (most recent call last):
  File "c:\Users\82105\Desktop\Project\Discord\DiscordBot_Gwen\utils\logger.py", line 22, in err
    raise error
  File "C:\Users\82105\AppData\Local\Programs\Python\Python39\lib\site-packages\discord\ext\commands\bot.py", line 939, in invoke
    await ctx.command.invoke(ctx)
  File "C:\Users\82105\AppData\Local\Programs\Python\Python39\lib\site-packages\discord\ext\commands\core.py", line 863, in invoke
    await injected(*ctx.args, **ctx.kwargs)
  File "C:\Users\82105\AppData\Local\Programs\Python\Python39\lib\site-packages\discord\ext\commands\core.py", line 94, in wrapped
    raise CommandInvokeError(exc) from exc
discord.ext.commands.errors.CommandInvokeError: Command raised an exception: AttributeError: 'NoneType' object has no attribute 'get_text'



10시 27분 / 병신들 <실험 | 하리하루 | 758963978331619331> !restart
10시 27분 / [정보] c:\Users\82105\Desktop\Project\Discord\DiscordBot_Gwen\cogs\AdminCommand.py 로드 완료
10시 27분 / [정보] 'AdminCommand' 다시 불러옴
10시 27분 / [정보] c:\Users\82105\Desktop\Project\Discord\DiscordBot_Gwen\cogs\event.py 로드 완료
10시 27분 / [정보] 'event' 다시 불러옴
10시 27분 / [정보] c:\Users\82105\Desktop\Project\Discord\DiscordBot_Gwen\cogs\NormalCommandBot.py 로드 완료
10시 27분 / [정보] 'NormalCommandBot' 다시 불러옴
10시 27분 / [정보] c:\Users\82105\Desktop\Project\Discord\DiscordBot_Gwen\cogs\SearchCommand.py 로드 완료
10시 27분 / [정보] 'SearchCommand' 다시 불러옴
10시 28분 / 병신들 <실험 | 하리하루 | 758963978331619331> !전적 Archetto
10시 28분 / 병신들 <실험 | 하리하루 | 758963978331619331> !restart
10시 28분 / [정보] c:\Users\82105\Desktop\Project\Discord\DiscordBot_Gwen\cogs\AdminCommand.py 로드 완료
10시 28분 / [정보] 'AdminCommand' 다시 불러옴
10시 28분 / [정보] c:\Users\82105\Desktop\Project\Discord\DiscordBot_Gwen\cogs\event.py 로드 완료
10시 28분 / [정보] 'event' 다시 불러옴
10시 28분 / [정보] c:\Users\82105\Desktop\Project\Discord\DiscordBot_Gwen\cogs\NormalCommandBot.py 로드 완료
10시 28분 / [정보] 'NormalCommandBot' 다시 불러옴
10시 28분 / [정보] c:\Users\82105\Desktop\Project\Discord\DiscordBot_Gwen\cogs\SearchCommand.py 로드 완료
10시 28분 / [정보] 'SearchCommand' 다시 불러옴
10시 28분 / 병신들 <실험 | 하리하루 | 758963978331619331> !전적 Archetto
11시 06분 / [정보] c:\Users\82105\Desktop\Project\Discord\DiscordBot_Gwen\cogs\AdminCommand.py 로드 완료
11시 06분 / [정보] c:\Users\82105\Desktop\Project\Discord\DiscordBot_Gwen\cogs\event.py 로드 완료
11시 06분 / [정보] c:\Users\82105\Desktop\Project\Discord\DiscordBot_Gwen\cogs\NormalCommandBot.py 로드 완료
11시 06분 / [정보] c:\Users\82105\Desktop\Project\Discord\DiscordBot_Gwen\cogs\SearchCommand.py 로드 완료
11시 06분 / [정보] ======================
11시 06분 / [정보] < 구동 완료 >
11시 06분 / [정보] ======================
11시 06분 / 병신들 <실험 | 하리하루 | 758963978331619331> !전적 11
11시 06분 / [오류] Traceback (most recent call last):
  File "C:\Users\82105\AppData\Local\Programs\Python\Python39\lib\site-packages\discord\ext\commands\core.py", line 85, in wrapped
    ret = await coro(*args, **kwargs)
  File "c:\Users\82105\Desktop\Project\Discord\DiscordBot_Gwen\cogs\SearchCommand.py", line 28, in 전적
    price = soup.find("span", attrs={"class":"ranking"}).get_text().strip()
AttributeError: 'NoneType' object has no attribute 'get_text'

The above exception was the direct cause of the following exception:

Traceback (most recent call last):
  File "c:\Users\82105\Desktop\Project\Discord\DiscordBot_Gwen\utils\logger.py", line 22, in err
    raise error
  File "C:\Users\82105\AppData\Local\Programs\Python\Python39\lib\site-packages\discord\ext\commands\bot.py", line 939, in invoke
    await ctx.command.invoke(ctx)
  File "C:\Users\82105\AppData\Local\Programs\Python\Python39\lib\site-packages\discord\ext\commands\core.py", line 863, in invoke
    await injected(*ctx.args, **ctx.kwargs)
  File "C:\Users\82105\AppData\Local\Programs\Python\Python39\lib\site-packages\discord\ext\commands\core.py", line 94, in wrapped
    raise CommandInvokeError(exc) from exc
discord.ext.commands.errors.CommandInvokeError: Command raised an exception: AttributeError: 'NoneType' object has no attribute 'get_text'



11시 10분 / 병신들 <실험 | 하리하루 | 758963978331619331> !restart
11시 10분 / [정보] c:\Users\82105\Desktop\Project\Discord\DiscordBot_Gwen\cogs\AdminCommand.py 로드 완료
11시 10분 / [정보] 'AdminCommand' 다시 불러옴
11시 10분 / [정보] c:\Users\82105\Desktop\Project\Discord\DiscordBot_Gwen\cogs\event.py 로드 완료
11시 10분 / [정보] 'event' 다시 불러옴
11시 10분 / [정보] c:\Users\82105\Desktop\Project\Discord\DiscordBot_Gwen\cogs\NormalCommandBot.py 로드 완료
11시 10분 / [정보] 'NormalCommandBot' 다시 불러옴
11시 10분 / [정보] c:\Users\82105\Desktop\Project\Discord\DiscordBot_Gwen\cogs\SearchCommand.py 로드 완료
11시 10분 / [정보] 'SearchCommand' 다시 불러옴
11시 10분 / 병신들 <실험 | 하리하루 | 758963978331619331> !전적 11
11시 10분 / 병신들 <실험 | 하리하루 | 758963978331619331> !전적 시리하루
11시 23분 / 병신들 <실험 | 하리하루 | 758963978331619331> !restart
11시 23분 / [정보] c:\Users\82105\Desktop\Project\Discord\DiscordBot_Gwen\cogs\AdminCommand.py 로드 완료
11시 23분 / [정보] 'AdminCommand' 다시 불러옴
11시 23분 / [정보] c:\Users\82105\Desktop\Project\Discord\DiscordBot_Gwen\cogs\event.py 로드 완료
11시 23분 / [정보] 'event' 다시 불러옴
11시 23분 / [정보] c:\Users\82105\Desktop\Project\Discord\DiscordBot_Gwen\cogs\NormalCommandBot.py 로드 완료
11시 23분 / [정보] 'NormalCommandBot' 다시 불러옴
11시 23분 / [정보] c:\Users\82105\Desktop\Project\Discord\DiscordBot_Gwen\cogs\SearchCommand.py 로드 완료
11시 23분 / [정보] 'SearchCommand' 다시 불러옴
11시 23분 / 병신들 <실험 | 하리하루 | 758963978331619331> !챔피언 가렌
11시 23분 / 병신들 <실험 | 하리하루 | 758963978331619331> !챔피언 11
11시 23분 / [오류] Traceback (most recent call last):
  File "C:\Users\82105\AppData\Local\Programs\Python\Python39\lib\site-packages\discord\ext\commands\core.py", line 85, in wrapped
    ret = await coro(*args, **kwargs)
  File "c:\Users\82105\Desktop\Project\Discord\DiscordBot_Gwen\cogs\SearchCommand.py", line 75, in 챔피언
    champ = Champion.champion[arg1]
KeyError: '11'

The above exception was the direct cause of the following exception:

Traceback (most recent call last):
  File "c:\Users\82105\Desktop\Project\Discord\DiscordBot_Gwen\utils\logger.py", line 22, in err
    raise error
  File "C:\Users\82105\AppData\Local\Programs\Python\Python39\lib\site-packages\discord\ext\commands\bot.py", line 939, in invoke
    await ctx.command.invoke(ctx)
  File "C:\Users\82105\AppData\Local\Programs\Python\Python39\lib\site-packages\discord\ext\commands\core.py", line 863, in invoke
    await injected(*ctx.args, **ctx.kwargs)
  File "C:\Users\82105\AppData\Local\Programs\Python\Python39\lib\site-packages\discord\ext\commands\core.py", line 94, in wrapped
    raise CommandInvokeError(exc) from exc
discord.ext.commands.errors.CommandInvokeError: Command raised an exception: KeyError: '11'



11시 29분 / 병신들 <실험 | 하리하루 | 758963978331619331> !restart
11시 29분 / [정보] c:\Users\82105\Desktop\Project\Discord\DiscordBot_Gwen\cogs\AdminCommand.py 로드 완료
11시 29분 / [정보] 'AdminCommand' 다시 불러옴
11시 29분 / [정보] c:\Users\82105\Desktop\Project\Discord\DiscordBot_Gwen\cogs\event.py 로드 완료
11시 29분 / [정보] 'event' 다시 불러옴
11시 29분 / [정보] c:\Users\82105\Desktop\Project\Discord\DiscordBot_Gwen\cogs\NormalCommandBot.py 로드 완료
11시 29분 / [정보] 'NormalCommandBot' 다시 불러옴
11시 29분 / [정보] c:\Users\82105\Desktop\Project\Discord\DiscordBot_Gwen\cogs\SearchCommand.py 로드 완료
11시 29분 / [정보] 'SearchCommand' 다시 불러옴
11시 29분 / 병신들 <실험 | 하리하루 | 758963978331619331> !챔피언 가렌
11시 29분 / 병신들 <실험 | 하리하루 | 758963978331619331> !챔피언 11
11시 30분 / 병신들 <실험 | 하리하루 | 758963978331619331> !챔피언 니달리
11시 31분 / 병신들 <실험 | 김강냉 | 582041127323041813> trpt
11시 31분 / 병신들 <실험 | 김강냉 | 582041127323041813> 섹스
11시 31분 / 병신들 <실험 | 김강냉 | 582041127323041813> 섹스
11시 31분 / 병신들 <실험 | 김강냉 | 582041127323041813> !챔피언 박주아엄마
11시 32분 / 병신들 <실험 | 하리하루 | 758963978331619331> ^ㅣ발
11시 32분 / 병신들 <실험 | 하리하루 | 758963978331619331> 150 개 넘는거
11시 32분 / 병신들 <실험 | 하리하루 | 758963978331619331> 언제 다 적노
11시 32분 / 병신들 <실험 | 하리하루 | 758963978331619331> 시발
11시 32분 / 병신들 <실험 | 하리하루 | 758963978331619331> !챔피언 가렌
11시 32분 / 병신들 <실험 | 김강냉 | 582041127323041813> ㅋㅋㅋㅋㅋㅋㅋㅋㅋ
11시 32분 / 병신들 <실험 | 김강냉 | 582041127323041813> 학교
11시 32분 / 병신들 <실험 | 김강냉 | 582041127323041813> 안가냐
11시 32분 / 병신들 <실험 | 하리하루 | 758963978331619331> 학교임
11시 32분 / 병신들 <실험 | 하리하루 | 758963978331619331> !전적
11시 33분 / 병신들 <실험 | 하리하루 | 758963978331619331> !전적 archetto
11시 39분 / 병신들 <실험 | MURYAN | 397036116676575233> 그웬씹년...
11시 39분 / 병신들 <실험 | MURYAN | 397036116676575233> 왜이리 천박함
11시 39분 / 병신들 <실험 | MURYAN | 397036116676575233> 꼴리네
11시 47분 / 병신들 <실험 | 하리하루 | 758963978331619331> 천박한 명령을 했으니까
11시 47분 / 병신들 <실험 | 김강냉 | 582041127323041813> !말해 헤으응
11시 47분 / [정보] 김강냉이(가) '!말해 헤으응'라고 한 메시지를 삭제했어!
11시 47분 / 병신들 <실험 | 김강냉 | 582041127323041813> !발사  재호 실버
11시 48분 / 병신들 <실험 | 김강냉 | 582041127323041813> ?
11시 48분 / 병신들 <실험 | 김강냉 | 582041127323041813> !발사 실버 재호
11시 48분 / 병신들 <실험 | 김강냉 | 582041127323041813> !발사 브론즈 재호
12시 18분 / 병신들 <실험 | 하리하루 | 758963978331619331> !restart
12시 18분 / [정보] c:\Users\82105\Desktop\Project\Discord\DiscordBot_Gwen\cogs\AdminCommand.py 로드 완료
12시 18분 / [정보] 'AdminCommand' 다시 불러옴
12시 18분 / [정보] c:\Users\82105\Desktop\Project\Discord\DiscordBot_Gwen\cogs\event.py 로드 완료
12시 18분 / [정보] 'event' 다시 불러옴
12시 18분 / [정보] c:\Users\82105\Desktop\Project\Discord\DiscordBot_Gwen\cogs\NormalCommandBot.py 로드 완료
12시 18분 / [정보] 'NormalCommandBot' 다시 불러옴
12시 18분 / [정보] c:\Users\82105\Desktop\Project\Discord\DiscordBot_Gwen\cogs\SearchCommand.py 로드 완료
12시 18분 / [정보] 'SearchCommand' 다시 불러옴
12시 19분 / 병신들 <실험 | 하리하루 | 758963978331619331> !챔피언 가렌
12시 19분 / 병신들 <실험 | 하리하루 | 758963978331619331> 애미
12시 23분 / 병신들 <실험 | MURYAN | 397036116676575233> 개꽃쳐
12시 23분 / 병신들 <실험 | MURYAN | 397036116676575233> 이기비나누어나미니나우류노노오여롱
12시 23분 / 병신들 <실험 | MURYAN | 397036116676575233> 아 신주황
12시 23분 / 병신들 <실험 | MURYAN | 397036116676575233> 니네학교 7반 자가격리라매 ㅋㅋ
12시 27분 / 병신들 <실험 | 하리하루 | 758963978331619331> !restart
12시 27분 / [정보] c:\Users\82105\Desktop\Project\Discord\DiscordBot_Gwen\cogs\AdminCommand.py 로드 완료
12시 27분 / [정보] 'AdminCommand' 다시 불러옴
12시 27분 / [정보] c:\Users\82105\Desktop\Project\Discord\DiscordBot_Gwen\cogs\event.py 로드 완료
12시 27분 / [정보] 'event' 다시 불러옴
12시 27분 / [정보] c:\Users\82105\Desktop\Project\Discord\DiscordBot_Gwen\cogs\NormalCommandBot.py 로드 완료
12시 27분 / [정보] 'NormalCommandBot' 다시 불러옴
12시 27분 / [정보] c:\Users\82105\Desktop\Project\Discord\DiscordBot_Gwen\cogs\SearchCommand.py 로드 완료
12시 27분 / [정보] 'SearchCommand' 다시 불러옴
12시 27분 / 병신들 <실험 | 하리하루 | 758963978331619331> !restart
12시 27분 / [정보] c:\Users\82105\Desktop\Project\Discord\DiscordBot_Gwen\cogs\AdminCommand.py 로드 완료
12시 27분 / [정보] 'AdminCommand' 다시 불러옴
12시 27분 / [정보] c:\Users\82105\Desktop\Project\Discord\DiscordBot_Gwen\cogs\event.py 로드 완료
12시 27분 / [정보] 'event' 다시 불러옴
12시 27분 / [정보] c:\Users\82105\Desktop\Project\Discord\DiscordBot_Gwen\cogs\NormalCommandBot.py 로드 완료
12시 27분 / [정보] 'NormalCommandBot' 다시 불러옴
12시 27분 / [정보] c:\Users\82105\Desktop\Project\Discord\DiscordBot_Gwen\cogs\SearchCommand.py 로드 완료
12시 27분 / [정보] 'SearchCommand' 다시 불러옴
12시 28분 / 병신들 <실험 | 하리하루 | 758963978331619331> !DM
12시 28분 / 병신들 <실험 | 하리하루 | 758963978331619331> !프로필
12시 28분 / 병신들 <실험 | 하리하루 | 758963978331619331> !restart
12시 28분 / [정보] c:\Users\82105\Desktop\Project\Discord\DiscordBot_Gwen\cogs\AdminCommand.py 로드 완료
12시 28분 / [정보] 'AdminCommand' 다시 불러옴
12시 28분 / [정보] c:\Users\82105\Desktop\Project\Discord\DiscordBot_Gwen\cogs\event.py 로드 완료
12시 28분 / [정보] 'event' 다시 불러옴
12시 28분 / [정보] c:\Users\82105\Desktop\Project\Discord\DiscordBot_Gwen\cogs\NormalCommandBot.py 로드 완료
12시 28분 / [정보] 'NormalCommandBot' 다시 불러옴
12시 28분 / [정보] c:\Users\82105\Desktop\Project\Discord\DiscordBot_Gwen\cogs\SearchCommand.py 로드 완료
12시 28분 / [정보] 'SearchCommand' 다시 불러옴
12시 29분 / 병신들 <실험 | 하리하루 | 758963978331619331> !DM
12시 29분 / [오류] Traceback (most recent call last):
  File "C:\Users\82105\AppData\Local\Programs\Python\Python39\lib\site-packages\discord\ext\commands\core.py", line 85, in wrapped
    ret = await coro(*args, **kwargs)
  File "c:\Users\82105\Desktop\Project\Discord\DiscordBot_Gwen\cogs\NormalCommandBot.py", line 128, in DM
    channel = await ctx.create_dm()
AttributeError: 'Context' object has no attribute 'create_dm'

The above exception was the direct cause of the following exception:

Traceback (most recent call last):
  File "c:\Users\82105\Desktop\Project\Discord\DiscordBot_Gwen\utils\logger.py", line 22, in err
    raise error
  File "C:\Users\82105\AppData\Local\Programs\Python\Python39\lib\site-packages\discord\ext\commands\bot.py", line 939, in invoke
    await ctx.command.invoke(ctx)
  File "C:\Users\82105\AppData\Local\Programs\Python\Python39\lib\site-packages\discord\ext\commands\core.py", line 863, in invoke
    await injected(*ctx.args, **ctx.kwargs)
  File "C:\Users\82105\AppData\Local\Programs\Python\Python39\lib\site-packages\discord\ext\commands\core.py", line 94, in wrapped
    raise CommandInvokeError(exc) from exc
discord.ext.commands.errors.CommandInvokeError: Command raised an exception: AttributeError: 'Context' object has no attribute 'create_dm'



12시 33분 / 병신들 <실험 | 하리하루 | 758963978331619331> !restart
12시 33분 / [정보] c:\Users\82105\Desktop\Project\Discord\DiscordBot_Gwen\cogs\AdminCommand.py 로드 완료
12시 33분 / [정보] 'AdminCommand' 다시 불러옴
12시 33분 / [정보] c:\Users\82105\Desktop\Project\Discord\DiscordBot_Gwen\cogs\event.py 로드 완료
12시 33분 / [정보] 'event' 다시 불러옴
12시 33분 / [정보] c:\Users\82105\Desktop\Project\Discord\DiscordBot_Gwen\cogs\NormalCommandBot.py 로드 완료
12시 33분 / [정보] 'NormalCommandBot' 다시 불러옴
12시 33분 / [정보] c:\Users\82105\Desktop\Project\Discord\DiscordBot_Gwen\cogs\SearchCommand.py 로드 완료
12시 33분 / [정보] 'SearchCommand' 다시 불러옴
12시 33분 / 병신들 <실험 | 하리하루 | 758963978331619331> !DM
12시 34분 / 병신들 <실험 | 하리하루 | 758963978331619331> !restart
12시 34분 / [정보] c:\Users\82105\Desktop\Project\Discord\DiscordBot_Gwen\cogs\AdminCommand.py 로드 완료
12시 34분 / [정보] 'AdminCommand' 다시 불러옴
12시 34분 / [정보] c:\Users\82105\Desktop\Project\Discord\DiscordBot_Gwen\cogs\event.py 로드 완료
12시 34분 / [정보] 'event' 다시 불러옴
12시 34분 / [정보] c:\Users\82105\Desktop\Project\Discord\DiscordBot_Gwen\cogs\NormalCommandBot.py 로드 완료
12시 34분 / [정보] 'NormalCommandBot' 다시 불러옴
12시 34분 / [정보] c:\Users\82105\Desktop\Project\Discord\DiscordBot_Gwen\cogs\SearchCommand.py 로드 완료
12시 34분 / [정보] 'SearchCommand' 다시 불러옴
13시 04분 / 병신들 <실험 | 김강냉 | 582041127323041813> 뭐지
13시 04분 / 병신들 <실험 | 김강냉 | 582041127323041813> 트포랑
13시 04분 / 병신들 <실험 | 김강냉 | 582041127323041813> 정수 같이올리면
13시 04분 / 병신들 <실험 | 김강냉 | 582041127323041813> 주문검  하나만
13시 04분 / 병신들 <실험 | 김강냉 | 582041127323041813> 적용되지않나
13시 07분 / 병신들 <실험 | 김강냉 | 582041127323041813> 그러네
13시 07분 / 병신들 <실험 | 김강냉 | 582041127323041813> 하나만
13시 07분 / 병신들 <실험 | 김강냉 | 582041127323041813> 적용되네
13시 14분 / [정보] c:\Users\82105\Desktop\Project\Discord\DiscordBot_Gwen\cogs\AdminCommand.py 로드 완료
13시 14분 / [정보] c:\Users\82105\Desktop\Project\Discord\DiscordBot_Gwen\cogs\event.py 로드 완료
13시 14분 / [정보] c:\Users\82105\Desktop\Project\Discord\DiscordBot_Gwen\cogs\NormalCommandBot.py 로드 완료
13시 14분 / [정보] c:\Users\82105\Desktop\Project\Discord\DiscordBot_Gwen\cogs\SearchCommand.py 로드 완료
13시 14분 / [정보] ======================
13시 14분 / [정보] < 구동 완료 >
13시 14분 / [정보] ======================
13시 14분 / 병신들 <실험 | 하리하루 | 758963978331619331> !전적 시리하루
13시 14분 / 병신들 <실험 | 김강냉 | 582041127323041813> 어지럽네
