00시 40분 / 병신들 <📊명령어 | 박병현 | 690902795452416043> !p 끝이라고 말하지마
00시 40분 / 병신들 <📊명령어 | 박병현 | 690902795452416043> !p 끝이라고 말하지마 1시간
00시 47분 / 병신들 <📩채팅창 | ping | 669911401183182848> 정글용으로
00시 47분 / 병신들 <📩채팅창 | ping | 669911401183182848> 킨드연습중
00시 47분 / 병신들 <📩채팅창 | ping | 669911401183182848> ㅁㅌㅊ?
00시 50분 / 병신들 <📩채팅창 | ping | 669911401183182848> 사실이블린도함
01시 14분 / 병신들 <📊명령어 | 박병현 | 690902795452416043> !skip
01시 24분 / 병신들 <📩채팅창 | 김강냉 | 582041127323041813> ㅆㅅㅌㅊ
01시 41분 / 병신들 <📩채팅창 | ping | 669911401183182848> 아니근데ㄹㅇ
01시 41분 / 병신들 <📩채팅창 | ping | 669911401183182848> 제드스오요네르블랑←이놈들은
01시 41분 / 병신들 <📩채팅창 | ping | 669911401183182848> 절대못이기겠음
01시 42분 / 병신들 <📩채팅창 | ping | 669911401183182848> 요네는 궁나온후에
01시 43분 / 병신들 <📩채팅창 | ping | 669911401183182848> 3타Q한번만 잘못맞아도 바로 썰리고
01시 43분 / 병신들 <📩채팅창 | ping | 669911401183182848> Q피하거나 거리안줘도 그냥 E로 계속따라와서 때리는거 개패고싶음
01시 44분 / 병신들 <📩채팅창 | ping | 669911401183182848> 그나마 스오 요네 상대론 애니비아 유효해서 쓰는데
01시 48분 / [정보] ping이(가) 'Q피하거나 거리안줘도 그냥 E로 계속따라와서 때리는거 개패고싶음' 메시지를 삭제
01시 48분 / [정보] ping이(가) '요네는 궁나온후에' 메시지를 삭제
01시 48분 / [정보] ping이(가) '3타Q한번만 잘못맞아도 바로 썰리고' 메시지를 삭제
03시 08분 / 병신들 <🧬정신나간-호재 | MURYAN | 397036116676575233> <@758963978331619331>
03시 09분 / 병신들 <🧬정신나간-호재 | MURYAN | 397036116676575233> 야맞다
03시 09분 / 병신들 <🧬정신나간-호재 | MURYAN | 397036116676575233> 베인 1티어되고
03시 09분 / 병신들 <🧬정신나간-호재 | MURYAN | 397036116676575233> 그시절베인 돌아왓는데
03시 09분 / 병신들 <🧬정신나간-호재 | MURYAN | 397036116676575233> 생각해보니 룰루를 다시
03시 09분 / 병신들 <🧬정신나간-호재 | MURYAN | 397036116676575233> 구해야될때가
03시 09분 / 병신들 <🧬정신나간-호재 | MURYAN | 397036116676575233> 온거같아
03시 09분 / 병신들 <🧬정신나간-호재 | MURYAN | 397036116676575233> 룰루...
08시 36분 / [정보] ======================
08시 36분 / [정보] < 구동 완료 >
08시 36분 / [정보] ======================
08시 41분 / [정보] ======================
08시 41분 / [정보] < 구동 완료 >
08시 41분 / [정보] ======================
08시 47분 / [정보] ======================
08시 47분 / [정보] < 구동 완료 >
08시 47분 / [정보] ======================
09시 00분 / [정보] ======================
09시 00분 / [정보] < 구동 완료 >
09시 00분 / [정보] ======================
09시 20분 / [정보] ======================
09시 20분 / [정보] < 구동 완료 >
09시 20분 / [정보] ======================
09시 26분 / 병신들 <실험 | T̴͖̃r̵̍͘1̸͑͠á̸́ỉ̶̍ň̴̒a̴̍͒ | 496627750858260480> #챔피언 카이사
10시 32분 / [정보] ======================
10시 32분 / [정보] < 구동 완료 >
10시 32분 / [정보] ======================
10시 38분 / [정보] ======================
10시 38분 / [정보] < 구동 완료 >
10시 38분 / [정보] ======================
10시 39분 / [정보] ======================
10시 39분 / [정보] < 구동 완료 >
10시 39분 / [정보] ======================
10시 47분 / 병신들 <🧬정신나간-호재 | 김강냉 | 582041127323041813> tLQKF
10시 47분 / 병신들 <🧬정신나간-호재 | 김강냉 | 582041127323041813> 나는
10시 47분 / 병신들 <🧬정신나간-호재 | 김강냉 | 582041127323041813> 안찾아주노
10시 47분 / 병신들 <🧬정신나간-호재 | 김강냉 | 582041127323041813> ㅠㅠ
10시 48분 / 병신들 <🧬정신나간-호재 | MURYAN | 397036116676575233> 아니근데 주황이랑 듀오한다치고
10시 48분 / [정보] ======================
10시 48분 / [정보] < 구동 완료 >
10시 48분 / [정보] ======================
10시 48분 / 병신들 <🧬정신나간-호재 | MURYAN | 397036116676575233> 베인룰루나 징크스카르마 렐카이사면
10시 48분 / 병신들 <🧬정신나간-호재 | MURYAN | 397036116676575233> 딱봐도 베인룰루가 가장 승률 낮아보이지않냐
10시 48분 / 병신들 <🧬정신나간-호재 | 김강냉 | 582041127323041813> ㅋㅋㅋㅋㅋㅋㅋㅋㅋㅋㅋㅋㅋㅋㅋㅋㅋㅋㅋㅋㅋ
11시 22분 / [정보] ======================
11시 22분 / [정보] < 구동 완료 >
11시 22분 / [정보] ======================
11시 26분 / [정보] ======================
11시 26분 / [정보] < 구동 완료 >
11시 26분 / [정보] ======================
11시 28분 / [정보] ======================
11시 28분 / [정보] < 구동 완료 >
11시 28분 / [정보] ======================
11시 45분 / [정보] ======================
11시 45분 / [정보] < 구동 완료 >
11시 45분 / [정보] ======================
12시 23분 / [정보] ======================
12시 23분 / [정보] < 구동 완료 >
12시 23분 / [정보] ======================
12시 59분 / [정보] ======================
12시 59분 / [정보] < 구동 완료 >
12시 59분 / [정보] ======================
13시 36분 / [정보] ======================
13시 36분 / [정보] < 구동 완료 >
13시 36분 / [정보] ======================
13시 37분 / [정보] ======================
13시 37분 / [정보] < 구동 완료 >
13시 37분 / [정보] ======================
14시 18분 / [정보] 실행 완료
14시 19분 / [정보] 실행 완료
15시 17분 / [정보] c:\Users\82105\Desktop\Project\Discord\DiscordBot_Gwen\cogs\AdminCommand.py 로드 완료
15시 17분 / [정보] c:\Users\82105\Desktop\Project\Discord\DiscordBot_Gwen\cogs\event.py 로드 완료
15시 17분 / [정보] c:\Users\82105\Desktop\Project\Discord\DiscordBot_Gwen\cogs\Favorability.py 로드 완료
15시 17분 / [정보] c:\Users\82105\Desktop\Project\Discord\DiscordBot_Gwen\cogs\NormalCommandBot.py 로드 완료
15시 17분 / [정보] c:\Users\82105\Desktop\Project\Discord\DiscordBot_Gwen\cogs\SearchCommand.py 로드 완료
15시 17분 / [정보] ======================
15시 17분 / [정보] < 구동 완료 >
15시 17분 / [정보] ======================
15시 17분 / 봇서버 <ㅎㅎ | 하리하루 | 758963978331619331> #전적 archetto
15시 17분 / [오류] Traceback (most recent call last):
  File "C:\Users\82105\AppData\Local\Programs\Python\Python39\lib\site-packages\urllib3\connectionpool.py", line 699, in urlopen
    httplib_response = self._make_request(
  File "C:\Users\82105\AppData\Local\Programs\Python\Python39\lib\site-packages\urllib3\connectionpool.py", line 382, in _make_request
    self._validate_conn(conn)
  File "C:\Users\82105\AppData\Local\Programs\Python\Python39\lib\site-packages\urllib3\connectionpool.py", line 1010, in _validate_conn
    conn.connect()
  File "C:\Users\82105\AppData\Local\Programs\Python\Python39\lib\site-packages\urllib3\connection.py", line 411, in connect
    self.sock = ssl_wrap_socket(
  File "C:\Users\82105\AppData\Local\Programs\Python\Python39\lib\site-packages\urllib3\util\ssl_.py", line 449, in ssl_wrap_socket
    ssl_sock = _ssl_wrap_socket_impl(
  File "C:\Users\82105\AppData\Local\Programs\Python\Python39\lib\site-packages\urllib3\util\ssl_.py", line 493, in _ssl_wrap_socket_impl
    return ssl_context.wrap_socket(sock, server_hostname=server_hostname)
  File "C:\Users\82105\AppData\Local\Programs\Python\Python39\lib\ssl.py", line 500, in wrap_socket
    return self.sslsocket_class._create(
  File "C:\Users\82105\AppData\Local\Programs\Python\Python39\lib\ssl.py", line 1040, in _create
    self.do_handshake()
  File "C:\Users\82105\AppData\Local\Programs\Python\Python39\lib\ssl.py", line 1309, in do_handshake
    self._sslobj.do_handshake()
ssl.SSLCertVerificationError: [SSL: CERTIFICATE_VERIFY_FAILED] certificate verify failed: self signed certificate (_ssl.c:1129)

During handling of the above exception, another exception occurred:

Traceback (most recent call last):
  File "C:\Users\82105\AppData\Local\Programs\Python\Python39\lib\site-packages\requests\adapters.py", line 439, in send
    resp = conn.urlopen(
  File "C:\Users\82105\AppData\Local\Programs\Python\Python39\lib\site-packages\urllib3\connectionpool.py", line 755, in urlopen
    retries = retries.increment(
  File "C:\Users\82105\AppData\Local\Programs\Python\Python39\lib\site-packages\urllib3\util\retry.py", line 574, in increment
    raise MaxRetryError(_pool, url, error or ResponseError(cause))
urllib3.exceptions.MaxRetryError: HTTPSConnectionPool(host='kr.op.gg', port=443): Max retries exceeded with url: /summoner/userName=archetto (Caused by SSLError(SSLCertVerificationError(1, '[SSL: CERTIFICATE_VERIFY_FAILED] certificate verify failed: self signed certificate (_ssl.c:1129)')))

During handling of the above exception, another exception occurred:

Traceback (most recent call last):
  File "C:\Users\82105\AppData\Local\Programs\Python\Python39\lib\site-packages\discord\ext\commands\core.py", line 85, in wrapped
    ret = await coro(*args, **kwargs)
  File "c:\Users\82105\Desktop\Project\Discord\DiscordBot_Gwen\cogs\SearchCommand.py", line 32, in 전적
    res = requests.get(url).text
  File "C:\Users\82105\AppData\Local\Programs\Python\Python39\lib\site-packages\requests\api.py", line 75, in get
    return request('get', url, params=params, **kwargs)
  File "C:\Users\82105\AppData\Local\Programs\Python\Python39\lib\site-packages\requests\api.py", line 61, in request
    return session.request(method=method, url=url, **kwargs)
  File "C:\Users\82105\AppData\Local\Programs\Python\Python39\lib\site-packages\requests\sessions.py", line 542, in request
    resp = self.send(prep, **send_kwargs)
  File "C:\Users\82105\AppData\Local\Programs\Python\Python39\lib\site-packages\requests\sessions.py", line 655, in send
    r = adapter.send(request, **kwargs)
  File "C:\Users\82105\AppData\Local\Programs\Python\Python39\lib\site-packages\requests\adapters.py", line 514, in send
    raise SSLError(e, request=request)
requests.exceptions.SSLError: HTTPSConnectionPool(host='kr.op.gg', port=443): Max retries exceeded with url: /summoner/userName=archetto (Caused by SSLError(SSLCertVerificationError(1, '[SSL: CERTIFICATE_VERIFY_FAILED] certificate verify failed: self signed certificate (_ssl.c:1129)')))

The above exception was the direct cause of the following exception:

Traceback (most recent call last):
  File "c:\Users\82105\Desktop\Project\Discord\DiscordBot_Gwen\utils\logger.py", line 22, in err
    raise error
  File "C:\Users\82105\AppData\Local\Programs\Python\Python39\lib\site-packages\discord\ext\commands\bot.py", line 939, in invoke
    await ctx.command.invoke(ctx)
  File "C:\Users\82105\AppData\Local\Programs\Python\Python39\lib\site-packages\discord\ext\commands\core.py", line 863, in invoke
    await injected(*ctx.args, **ctx.kwargs)
  File "C:\Users\82105\AppData\Local\Programs\Python\Python39\lib\site-packages\discord\ext\commands\core.py", line 94, in wrapped
    raise CommandInvokeError(exc) from exc
discord.ext.commands.errors.CommandInvokeError: Command raised an exception: SSLError: HTTPSConnectionPool(host='kr.op.gg', port=443): Max retries exceeded with url: /summoner/userName=archetto (Caused by SSLError(SSLCertVerificationError(1, '[SSL: CERTIFICATE_VERIFY_FAILED] certificate verify failed: self signed certificate (_ssl.c:1129)')))



15시 18분 / 봇서버 <ㅎㅎ | 하리하루 | 758963978331619331> #전적 시리하루
15시 18분 / [오류] Traceback (most recent call last):
  File "C:\Users\82105\AppData\Local\Programs\Python\Python39\lib\site-packages\urllib3\connectionpool.py", line 699, in urlopen
    httplib_response = self._make_request(
  File "C:\Users\82105\AppData\Local\Programs\Python\Python39\lib\site-packages\urllib3\connectionpool.py", line 382, in _make_request
    self._validate_conn(conn)
  File "C:\Users\82105\AppData\Local\Programs\Python\Python39\lib\site-packages\urllib3\connectionpool.py", line 1010, in _validate_conn
    conn.connect()
  File "C:\Users\82105\AppData\Local\Programs\Python\Python39\lib\site-packages\urllib3\connection.py", line 411, in connect
    self.sock = ssl_wrap_socket(
  File "C:\Users\82105\AppData\Local\Programs\Python\Python39\lib\site-packages\urllib3\util\ssl_.py", line 449, in ssl_wrap_socket
    ssl_sock = _ssl_wrap_socket_impl(
  File "C:\Users\82105\AppData\Local\Programs\Python\Python39\lib\site-packages\urllib3\util\ssl_.py", line 493, in _ssl_wrap_socket_impl
    return ssl_context.wrap_socket(sock, server_hostname=server_hostname)
  File "C:\Users\82105\AppData\Local\Programs\Python\Python39\lib\ssl.py", line 500, in wrap_socket
    return self.sslsocket_class._create(
  File "C:\Users\82105\AppData\Local\Programs\Python\Python39\lib\ssl.py", line 1040, in _create
    self.do_handshake()
  File "C:\Users\82105\AppData\Local\Programs\Python\Python39\lib\ssl.py", line 1309, in do_handshake
    self._sslobj.do_handshake()
ssl.SSLCertVerificationError: [SSL: CERTIFICATE_VERIFY_FAILED] certificate verify failed: self signed certificate (_ssl.c:1129)

During handling of the above exception, another exception occurred:

Traceback (most recent call last):
  File "C:\Users\82105\AppData\Local\Programs\Python\Python39\lib\site-packages\requests\adapters.py", line 439, in send
    resp = conn.urlopen(
  File "C:\Users\82105\AppData\Local\Programs\Python\Python39\lib\site-packages\urllib3\connectionpool.py", line 755, in urlopen
    retries = retries.increment(
  File "C:\Users\82105\AppData\Local\Programs\Python\Python39\lib\site-packages\urllib3\util\retry.py", line 574, in increment
    raise MaxRetryError(_pool, url, error or ResponseError(cause))
urllib3.exceptions.MaxRetryError: HTTPSConnectionPool(host='kr.op.gg', port=443): Max retries exceeded with url: /summoner/userName=%EC%8B%9C%EB%A6%AC%ED%95%98%EB%A3%A8 (Caused by SSLError(SSLCertVerificationError(1, '[SSL: CERTIFICATE_VERIFY_FAILED] certificate verify failed: self signed certificate (_ssl.c:1129)')))

During handling of the above exception, another exception occurred:

Traceback (most recent call last):
  File "C:\Users\82105\AppData\Local\Programs\Python\Python39\lib\site-packages\discord\ext\commands\core.py", line 85, in wrapped
    ret = await coro(*args, **kwargs)
  File "c:\Users\82105\Desktop\Project\Discord\DiscordBot_Gwen\cogs\SearchCommand.py", line 32, in 전적
    res = requests.get(url).text
  File "C:\Users\82105\AppData\Local\Programs\Python\Python39\lib\site-packages\requests\api.py", line 75, in get
    return request('get', url, params=params, **kwargs)
  File "C:\Users\82105\AppData\Local\Programs\Python\Python39\lib\site-packages\requests\api.py", line 61, in request
    return session.request(method=method, url=url, **kwargs)
  File "C:\Users\82105\AppData\Local\Programs\Python\Python39\lib\site-packages\requests\sessions.py", line 542, in request
    resp = self.send(prep, **send_kwargs)
  File "C:\Users\82105\AppData\Local\Programs\Python\Python39\lib\site-packages\requests\sessions.py", line 655, in send
    r = adapter.send(request, **kwargs)
  File "C:\Users\82105\AppData\Local\Programs\Python\Python39\lib\site-packages\requests\adapters.py", line 514, in send
    raise SSLError(e, request=request)
requests.exceptions.SSLError: HTTPSConnectionPool(host='kr.op.gg', port=443): Max retries exceeded with url: /summoner/userName=%EC%8B%9C%EB%A6%AC%ED%95%98%EB%A3%A8 (Caused by SSLError(SSLCertVerificationError(1, '[SSL: CERTIFICATE_VERIFY_FAILED] certificate verify failed: self signed certificate (_ssl.c:1129)')))

The above exception was the direct cause of the following exception:

Traceback (most recent call last):
  File "c:\Users\82105\Desktop\Project\Discord\DiscordBot_Gwen\utils\logger.py", line 22, in err
    raise error
  File "C:\Users\82105\AppData\Local\Programs\Python\Python39\lib\site-packages\discord\ext\commands\bot.py", line 939, in invoke
    await ctx.command.invoke(ctx)
  File "C:\Users\82105\AppData\Local\Programs\Python\Python39\lib\site-packages\discord\ext\commands\core.py", line 863, in invoke
    await injected(*ctx.args, **ctx.kwargs)
  File "C:\Users\82105\AppData\Local\Programs\Python\Python39\lib\site-packages\discord\ext\commands\core.py", line 94, in wrapped
    raise CommandInvokeError(exc) from exc
discord.ext.commands.errors.CommandInvokeError: Command raised an exception: SSLError: HTTPSConnectionPool(host='kr.op.gg', port=443): Max retries exceeded with url: /summoner/userName=%EC%8B%9C%EB%A6%AC%ED%95%98%EB%A3%A8 (Caused by SSLError(SSLCertVerificationError(1, '[SSL: CERTIFICATE_VERIFY_FAILED] certificate verify failed: self signed certificate (_ssl.c:1129)')))



15시 18분 / 봇서버 <ㅎㅎ | 하리하루 | 758963978331619331> #챔피언 아칼리
15시 20분 / 봇서버 <ㅎㅎ | 하리하루 | 758963978331619331> #restart
15시 20분 / [정보] c:\Users\82105\Desktop\Project\Discord\DiscordBot_Gwen\cogs\AdminCommand.py 로드 완료
15시 20분 / [정보] 'AdminCommand' reload complete
15시 20분 / [정보] c:\Users\82105\Desktop\Project\Discord\DiscordBot_Gwen\cogs\event.py 로드 완료
15시 20분 / [정보] 'event' reload complete
15시 20분 / [정보] c:\Users\82105\Desktop\Project\Discord\DiscordBot_Gwen\cogs\Favorability.py 로드 완료
15시 20분 / [정보] 'Favorability' reload complete
15시 20분 / [정보] c:\Users\82105\Desktop\Project\Discord\DiscordBot_Gwen\cogs\NormalCommandBot.py 로드 완료
15시 20분 / [정보] 'NormalCommandBot' reload complete
15시 20분 / [정보] c:\Users\82105\Desktop\Project\Discord\DiscordBot_Gwen\cogs\SearchCommand.py 로드 완료
15시 20분 / [정보] 'SearchCommand' reload complete
15시 20분 / 봇서버 <ㅎㅎ | 하리하루 | 758963978331619331> #전적 시리하루
15시 20분 / 봇서버 <ㅎㅎ | 하리하루 | 758963978331619331> #전적 archetto
15시 24분 / 병신들 <📩채팅창 | 하리하루 | 758963978331619331> #히히네이스
18시 59분 / [정보] ======================
18시 59분 / [정보] < 구동 완료 >
18시 59분 / [정보] ======================
21시 57분 / 병신들 <📩채팅창 | 장선효 | 534534395118485506> At the end of the experiment, Regina said, “I don’t look at the elderly in the same way that I used to anymore.  
→ that I used to는 선행사 (the same way )를 수식하는 관계부사절이다. → used to 다음에 동일한 어구의 반복을 피하기 위해 ( )가 생략되었다.
21시 57분 / 병신들 <📩채팅창 | 장선효 | 534534395118485506> 아는분
22시 03분 / [정보] 장선효이(가) 'At the end of the experiment, Regina said, “I don’t look at the elderly in the same way that I used to anymore.  
→ that I used to는 선행사 (the same way )를 수식하는 관계부사절이다. → used to 다음에 동일한 어구의 반복을 피하기 위해 ( )가 생략되었다.' 메시지를 삭제
22시 03분 / [정보] 장선효이(가) '아는분' 메시지를 삭제
23시 30분 / 병신들 <📩채팅창 | T̴͖̃r̵̍͘1̸͑͠á̸́ỉ̶̍ň̴̒a̴̍͒ | 496627750858260480> <@!620609712785850398> 난이도 평화해도됨?
23시 30분 / 병신들 <📩채팅창 | 송찬형 | 620609712785850398> dd
23시 30분 / 병신들 <📩채팅창 | T̴͖̃r̵̍͘1̸͑͠á̸́ỉ̶̍ň̴̒a̴̍͒ | 496627750858260480> ㅇㅋ
23시 40분 / 병신들 <📩채팅창 | 박문균 | 817580757753135104> <@!758963978331619331>
23시 40분 / 병신들 <📩채팅창 | 박문균 | 817580757753135104> 자냐
